Workbook

Sheet Dashboard
A1: Class Start Date | B1: Trainer Name | C1: Number of Agent Transition to Nesting | D1: Whistleblowing | E1: PCB Compliance Coaching Model | F1: Complaint Management Theory | G1: NTT BPO PCB AML - General | H1: Senior's Fraud | I1: Corporate Policy and Procedure Employee Sign off | J1: NTT BPO CASL | K1: NTT BPO AODA | L1: NTT BPO Health and Safety - Onshore or Offshore version | M1: NTT BPO WHMIS | N1: NTT BPO Violence and Harassment in the Workplace Quiz | O1: NTT BPO Insider Fraud Awareness | P1: NTT BPO Privacy + Security | Q1: NTT BPO Human Rights Code | R1: Total Complete
U2: Trainer Name | V2: Sum of Number of Agent Transition to Nesting | W2: Sum of Total Complete | Y2: Correct
A3: ='Q1'!A2 -> 03.10.2025 | B3: ='Q1'!B2 -> Jean LuZada | C3: ='Q1'!D2 -> 18 | D3: ='Q1'!E2 -> 25 | E3: ='Q1'!F2 -> 25 | F3: ='Q1'!G2 -> 22 | G3: ='Q1'!H2 -> 25 | H3: ='Q1'!I2 -> 22 | I3: ='Q1'!J2 -> 25 | J3: ='Q1'!K2 -> 25 | ... Q3: ='Q1'!R2 -> 25 | R3: =MIN(D3:Q3) -> 1 | U3: Catherine Cachero | V3: 68 | W3: 59 | X3: =V3/W3 -> 1.1525424 | Y3: =W3/V3 -> 0.86764706
A4: ='Q1'!A2 -> 03.10.2025 | B4: ='Q1'!C2 -> Mel Cajucom | C4: ='Q1'!D2 -> 18 | D4: ='Q1'!E2 -> 25 | E4: ='Q1'!F2 -> 25 | F4: ='Q1'!G2 -> 22 | G4: ='Q1'!H2 -> 25 | H4: ='Q1'!I2 -> 22 | I4: ='Q1'!J2 -> 25 | ... Q4: ='Q1'!R2 -> 25 | R4: =MIN(D4:Q4) -> 1 | U4: Chase Argamosa | V4: 46 | W4: 32 | X4: =V4/W4 -> 1.4375 | Y4: =W4/V4 -> 0.69565217
A5: ='Q1'!A32 -> 03.24.2025 | B5: ='Q1'!B32 -> Irish Ferreras | C5: ='Q1'!D32 -> 31 | D5: ='Q1'!E32 -> 33 | E5: ='Q1'!F32 -> 33 | F5: ='Q1'!G32 -> 30 | G5: ='Q1'!H32 -> 33 | H5: ='Q1'!I32 -> 27 | I5: ='Q1'!J32 -> 11 | J5: ='Q1'!K32 -> 33 | ... Q5: ='Q1'!R32 -> 33 | R5: =MIN(D5:Q5) -> 11 | U5: Donna Caliling | V5: 13 | W5: 14 | X5: =V5/W5 -> 0.92857143 | Y5: =W5/V5 -> 1.0769231
A6: ='Q1'!A32 -> 03.24.2025 | B6: ='Q1'!C32 -> Chase Argamosa | C6: ='Q1'!D32 -> 31 | D6: ='Q1'!E32 -> 33 | E6: ='Q1'!F32 -> 33 | F6: ='Q1'!G32 -> 30 | G6: ='Q1'!H32 -> 33 | H6: ='Q1'!I32 -> 27 | I6: ='Q1'!J32 -> 11 | ... Q6: ='Q1'!R32 -> 33 | R6: =MIN(D6:Q6) -> 11 | U6: Irish Ferreras | V6: 72 | W6: 53 | X6: =V6/W6 -> 1.3584906 | Y6: =W6/V6 -> 0.73611111
A7: ='Q1'!A78 -> 45761 | B7: ='Q1'!B78 -> Vera Hibaya | C7: ='Q1'!D78 -> 18 | D7: ='Q1'!E78 -> 19 | E7: ='Q1'!F78 -> 19 | F7: ='Q1'!G78 -> 18 | G7: ='Q1'!H78 -> 19 | H7: ='Q1'!I78 -> 18 | I7: N/A | J7: ='Q1'!K78 -> 19 | K7: ='Q1'!L78 -> 19 | L7: N/A | M7: N/A | N7: N/A | O7: ='Q1'!P78 -> 19 | P7: N/A | Q7: ='Q1'!R78 -> 19 | R7: =MIN(D7:Q7) -> 18 | U7: Jean LuZada | V7: 57 | W7: 41 | X7: =V7/W7 -> 1.3902439 | Y7: =W7/V7 -> 0.71929825
A8: ='Q1'!A78 -> 45761 | B8: ='Q1'!C78 -> Catherine Cachero | C8: ='Q1'!D78 -> 18 | D8: ='Q1'!E78 -> 19 | E8: ='Q1'!F78 -> 19 | F8: ='Q1'!G78 -> 18 | G8: ='Q1'!H78 -> 19 | H8: ='Q1'!I78 -> 18 | I8: N/A | J8: ='Q1'!K78 -> 19 | K8: ='Q1'!L78 -> 19 | L8: N/A | M8: N/A | N8: N/A | O8: ='Q1'!P78 -> 19 | P8: N/A | Q8: ='Q1'!R78 -> 19 | R8: =MIN(D8:Q8) -> 18 | U8: Jeff Janda | V8: 27 | W8: 34 | X8: =V8/W8 -> 0.79411765 | Y8: =W8/V8 -> 1.2592593
A9: ='Q1'!A99 -> 45768 | B9: ='Q1'!B99 -> Nancy Price | C9: ='Q1'!D99 -> 18 | D9: ='Q1'!E99 -> 19 | E9: ='Q1'!F99 -> 19 | F9: ='Q1'!G99 -> 18 | G9: ='Q1'!H99 -> 19 | H9: ='Q1'!I99 -> 18 | I9: ='Q1'!J99 -> 19 | J9: ='Q1'!K99 -> 19 | ... Q9: ='Q1'!R99 -> 19 | R9: =MIN(D9:Q9) -> 18 | U9: Jennifer Ramirez | V9: 26 | W9: 28 | X9: =V9/W9 -> 0.92857143 | Y9: =W9/V9 -> 1.0769231
A10: ='Q1'!A99 -> 45768 | B10: ='Q1'!C99 -> Kate Saigo | C10: ='Q1'!D99 -> 18 | D10: ='Q1'!E99 -> 19 | E10: ='Q1'!F99 -> 19 | F10: ='Q1'!G99 -> 18 | G10: ='Q1'!H99 -> 19 | H10: ='Q1'!I99 -> 18 | I10: ='Q1'!J99 -> 19 | ... Q10: ='Q1'!R99 -> 19 | R10: =MIN(D10:Q10) -> 18 | U10: Kate Postres | V10: 30 | W10: 30 | X10: =V10/W10 -> 1 | Y10: =W10/V10 -> 1
A11: ='Q1'!A119 -> 45775 | B11: ='Q1'!B119 -> Donna Caliling | C11: ='Q1'!D119 -> 13 | D11: ='Q1'!E119 -> 15 | E11: ='Q1'!F119 -> 15 | F11: ='Q1'!G119 -> 14 | G11: ='Q1'!H119 -> 15 | H11: ='Q1'!I119 -> 14 | I11: ='Q1'!J119 -> 15 | J11: ='Q1'!K119 -> 15 | ... Q11: ='Q1'!R119 -> 15 | R11: =MIN(D11:Q11) -> 14 | U11: Kate Saigo | V11: 41 | W11: 43 | X11: =V11/W11 -> 0.95348837 | Y11: =W11/V11 -> 1.0487805
A12: ='Q1'!A119 -> 45775 | B12: ='Q1'!C119 -> Jeff Janda | C12: ='Q1'!D119 -> 13 | D12: ='Q1'!E119 -> 15 | E12: ='Q1'!F119 -> 15 | F12: ='Q1'!G119 -> 14 | G12: ='Q1'!H119 -> 15 | H12: ='Q1'!I119 -> 14 | I12: ='Q1'!J119 -> 15 | ... Q12: ='Q1'!R119 -> 15 | R12: =MIN(D12:Q12) -> 14 | U12: Kenneth Vera Hibaya | V12: 19 | W12: 0 | X12: =V12/W12 -> #DIV/0! | Y12: =W12/V12 -> 0
A13: ='Q1'!A139 -> 45789 | B13: ='Q1'!B139 -> Viena Lacena | C13: ='Q1'!D139 -> 16 | D13: ='Q1'!E139 -> 18 | E13: ='Q1'!F139 -> 18 | F13: ='Q1'!G139 -> 16 | G13: ='Q1'!H139 -> 18 | H13: ='Q1'!I139 -> 16 | I13: ='Q1'!J139 -> 16 | J13: ='Q1'!K139 -> 18 | ... Q13: ='Q1'!R139 -> 18 | R13: =MIN(D13:Q13) -> 16 | U13: Maria Lourdes Tendenilla | V13: 15 | W13: 16 | X13: =V13/W13 -> 0.9375 | Y13: =W13/V13 -> 1.0666667
A14: ='Q1'!A139 -> 45789 | B14: ='Q1'!C139 -> Kate Postres | C14: ='Q1'!D139 -> 16 | D14: ='Q1'!E139 -> 18 | E14: ='Q1'!F139 -> 18 | F14: ='Q1'!G139 -> 16 | G14: ='Q1'!H139 -> 18 | H14: ='Q1'!I139 -> 16 | I14: ='Q1'!J139 -> 16 | ... Q14: ='Q1'!R139 -> 18 | R14: =MIN(D14:Q14) -> 16 | U14: Maynard Soriano | V14: 44 | W14: 40 | X14: =V14/W14 -> 1.1 | Y14: =W14/V14 -> 0.90909091
A15: ='Q1'!A163 -> 45797 | B15: ='Q1'!B163 -> Chase Argamosa | C15: ='Q1'!D163 -> 11 | D15: ='Q1'!E163 -> 12 | E15: ='Q1'!F163 -> 12 | F15: ='Q1'!G163 -> 11 | G15: ='Q1'!H163 -> 12 | H15: ='Q1'!I163 -> 12 | I15: ='Q1'!J163 -> 11 | J15: ='Q1'!K163 -> 12 | ... Q15: ='Q1'!R163 -> 11 | R15: =MIN(D15:Q15) -> 11 | U15: Mel Cajucom | V15: 48 | W15: 26 | X15: =V15/W15 -> 1.8461538 | Y15: =W15/V15 -> 0.54166667
A16: ='Q1'!A163 -> 45797 | B16: ='Q1'!C163 -> Vhea De Fiesta | C16: ='Q1'!D163 -> 11 | D16: ='Q1'!E163 -> 12 | E16: ='Q1'!F163 -> 12 | F16: ='Q1'!G163 -> 11 | G16: ='Q1'!H163 -> 12 | H16: ='Q1'!I163 -> 12 | I16: ='Q1'!J163 -> 11 | ... Q16: ='Q1'!R163 -> 11 | R16: =MIN(D16:Q16) -> 11 | U16: Nancy Price | V16: 62 | W16: 58 | X16: =V16/W16 -> 1.0689655 | Y16: =W16/V16 -> 0.93548387
A17: ='Q1'!A178 -> 45803 | B17: ='Q1'!B178 -> Jean Luzada | C17: ='Q1'!D178 -> 14 | D17: ='Q1'!E178 -> 16 | E17: ='Q1'!F178 -> 16 | F17: ='Q1'!G178 -> 15 | G17: ='Q1'!H178 -> 16 | H17: ='Q1'!I178 -> 15 | I17: N/A | J17: ='Q1'!K178 -> 16 | K17: ='Q1'!L178 -> 16 | L17: N/A | M17: N/A | N17: N/A | O17: ='Q1'!P178 -> 16 | P17: N/A | Q17: ='Q1'!R178 -> 16 | R17: =MIN(D17:Q17) -> 15 | U17: Sneha Menda | V17: 30 | W17: 25 | X17: =V17/W17 -> 1.2 | Y17: =W17/V17 -> 0.83333333
A18: ='Q1'!A178 -> 45803 | B18: ='Q1'!C178 -> Maynard Soriano | C18: ='Q1'!D178 -> 14 | D18: ='Q1'!E178 -> 16 | E18: ='Q1'!F178 -> 16 | F18: ='Q1'!G178 -> 15 | G18: ='Q1'!H178 -> 16 | H18: ='Q1'!I178 -> 15 | I18: N/A | J18: ='Q1'!K178 -> 16 | K18: ='Q1'!L178 -> 16 | L18: N/A | M18: N/A | N18: N/A | O18: ='Q1'!P178 -> 16 | P18: N/A | Q18: ='Q1'!R178 -> 16 | R18: =MIN(D18:Q18) -> 15 | U18: Vera Hibaya | V18: 63 | W18: 55 | X18: =V18/W18 -> 1.1454545 | Y18: =W18/V18 -> 0.87301587
A19: ='Q1'!A178 -> 45803 | B19: ='Q1'!U178 -> Jennifer Ramirez | C19: ='Q1'!D178 -> 14 | D19: ='Q1'!E178 -> 16 | E19: ='Q1'!F178 -> 16 | F19: ='Q1'!G178 -> 15 | G19: ='Q1'!H178 -> 16 | H19: ='Q1'!I178 -> 15 | I19: N/A | J19: ='Q1'!K178 -> 16 | K19: ='Q1'!L178 -> 16 | L19: N/A | M19: N/A | N19: N/A | O19: ='Q1'!P178 -> 16 | P19: N/A | Q19: ='Q1'!R178 -> 16 | R19: =MIN(D19:Q19) -> 15 | U19: Vhea De Fiesta | V19: 37 | W19: 36 | X19: =V19/W19 -> 1.0277778 | Y19: =W19/V19 -> 0.97297297
A20: ='Q2'!A2 -> 06.09.2025 | B20: ='Q2'!B2 -> Anabelle Pizon | C20: ='Q2'!D2 -> 14 | D20: ='Q2'!E2 -> 15 | E20: ='Q2'!F2 -> 15 | F20: ='Q2'!G2 -> 15 | G20: ='Q2'!H2 -> 15 | H20: ='Q2'!I2 -> 15 | I20: N/A | J20: ='Q2'!K2 -> 15 | K20: ='Q2'!L2 -> 15 | L20: N/A | M20: N/A | N20: N/A | O20: ='Q2'!P2 -> 15 | P20: N/A | Q20: ='Q2'!R2 -> 15 | R20: =MIN(D20:Q20) -> 15 | U20: Viena Lacena | V20: 16 | W20: 16 | X20: =V20/W20 -> 1 | Y20: =W20/V20 -> 1
A21: ='Q2'!A2 -> 06.09.2025 | B21: ='Q2'!C2 -> Irish Ferreras | C21: ='Q2'!D2 -> 14 | D21: ='Q2'!E2 -> 15 | E21: ='Q2'!F2 -> 15 | F21: ='Q2'!G2 -> 15 | G21: ='Q2'!H2 -> 15 | H21: ='Q2'!I2 -> 15 | I21: N/A | J21: ='Q2'!K2 -> 15 | K21: ='Q2'!L2 -> 15 | L21: N/A | M21: N/A | N21: N/A | O21: ='Q2'!P2 -> 15 | P21: N/A | Q21: ='Q2'!R2 -> 15 | R21: =MIN(D21:Q21) -> 15 | U21: (blank) | X21: =V21/W21 -> #DIV/0! | Y21: =W21/V21 -> #DIV/0!
A22: ='Q2'!A22 -> 06.23.2025 | B22: ='Q2'!B22 -> Kate Saigo | C22: ='Q2'!D22 -> 10 | D22: ='Q2'!E22 -> 11 | E22: ='Q2'!F22 -> 11 | F22: ='Q2'!G22 -> 11 | G22: ='Q2'!H22 -> 11 | H22: ='Q2'!I22 -> 11 | I22: ='Q2'!J22 -> 10 | J22: ='Q2'!K22 -> 11 | ... Q22: ='Q2'!R22 -> 11 | R22: =MIN(D22:Q22) -> 10 | U22: Kaylum Jonkers | V22: 14 | W22: 15 | X22: =V22/W22 -> 0.93333333 | Y22: =W22/V22 -> 1.0714286
A23: ='Q2'!A22 -> 06.23.2025 | B23: ='Q2'!C22 -> Jeff Janda | C23: ='Q2'!D22 -> 10 | D23: ='Q2'!E22 -> 11 | E23: ='Q2'!F22 -> 11 | F23: ='Q2'!G22 -> 11 | G23: ='Q2'!H22 -> 11 | H23: ='Q2'!I22 -> 11 | I23: ='Q2'!J22 -> 10 | ... Q23: ='Q2'!R22 -> 11 | R23: =MIN(D23:Q23) -> 10 | U23: Mary Anne Cruz | V23: 23 | W23: 10 | X23: =V23/W23 -> 2.3 | Y23: =W23/V23 -> 0.43478261
A24: ='Q2'!A36 -> 06.23.2025 | B24: ='Q2'!B36 -> Nancy Price | C24: ='Q2'!D36 -> 30 | D24: ='Q2'!E36 -> 37 | E24: ='Q2'!F36 -> 37 | F24: ='Q2'!G36 -> 34 | G24: ='Q2'!H36 -> 36 | H24: ='Q2'!I36 -> 35 | I24: ='Q2'!J36 -> 37 | J24: ='Q2'!K36 -> 36 | ... Q24: ='Q2'!R36 -> 25 | R24: =MIN(D24:Q24) -> 25 | U24: Patrick James Reosia | V24: 19 | W24: 19 | X24: =V24/W24 -> 1 | Y24: =W24/V24 -> 1
A25: ='Q2'!A36 -> 06.23.2025 | B25: ='Q2'!C36 -> Sneha Menda | C25: ='Q2'!D36 -> 30 | D25: ='Q2'!E36 -> 37 | E25: ='Q2'!F36 -> 37 | F25: ='Q2'!G36 -> 34 | G25: ='Q2'!H36 -> 36 | H25: ='Q2'!I36 -> 35 | I25: ='Q2'!J36 -> 37 | ... Q25: ='Q2'!R36 -> 25 | R25: =MIN(D25:Q25) -> 25 | U25: Jarry Calilung | V25: 16 | W25: 16 | X25: =V25/W25 -> 1 | Y25: =W25/V25 -> 1
A26: ='Q2'!A36 -> 06.23.2025 | B26: ='Q2'!U36 -> Mel Cajucom | C26: ='Q2'!D36 -> 30 | D26: ='Q2'!E36 -> 37 | E26: ='Q2'!F36 -> 37 | F26: ='Q2'!G36 -> 34 | G26: ='Q2'!H36 -> 36 | H26: ='Q2'!I36 -> 35 | I26: ='Q2'!J36 -> 37 | J26: ='Q2'!K36 -> 36 | ... Q26: ='Q2'!R36 -> 25 | R26: =MIN(D26:Q26) -> 25 | U26: Anabelle Pizon | V26: 26 | W26: 28 | X26: =V26/W26 -> 0.92857143 | Y26: =W26/V26 -> 1.0769231
A27: ='Q2'!A36 -> 06.23.2025 | B27: ='Q2'!V36 -> Maynard Soriano | C27: ='Q2'!D36 -> 30 | D27: ='Q2'!E36 -> 37 | E27: ='Q2'!F36 -> 37 | F27: ='Q2'!G36 -> 34 | G27: ='Q2'!H36 -> 36 | H27: ='Q2'!I36 -> 35 | I27: ='Q2'!J36 -> 37 | J27: ='Q2'!K36 -> 36 | ... Q27: ='Q2'!R36 -> 25 | R27: =MIN(D27:Q27) -> 25 | U27: Robin Yasona | V27: 13 | W27: 15 | X27: =V27/W27 -> 0.86666667 | Y27: =W27/V27 -> 1.1538462
A28: 06.30.2025 | B28: ='Q2'!B81 -> Vera Hibaya | C28: ='Q2'!D81 -> 31 | D28: ='Q2'!E81 -> 22 | E28: ='Q2'!F81 -> 22 | F28: ='Q2'!G81 -> 22 | G28: ='Q2'!H81 -> 22 | H28: ='Q2'!I81 -> 22 | I28: ='Q2'!J81 -> N/A | J28: ='Q2'!K81 -> 22 | ... Q28: ='Q2'!R81 -> 22 | R28: =MIN(D28:Q28) -> 22 | U28: Maynard Soriano | V28: 13 | W28: 13
A29: 06.30.2025 | B29: Catherine Cachero | C29: ='Q2'!D81 -> 31 | D29: ='Q2'!E81 -> 22 | E29: ='Q2'!F81 -> 22 | F29: ='Q2'!G81 -> 22 | G29: ='Q2'!H81 -> 22 | H29: ='Q2'!I81 -> 22 | I29: ='Q2'!J81 -> N/A | J29: ='Q2'!K81 -> 22 | ... Q29: ='Q2'!R81 -> 22 | R29: =MIN(D29:Q29) -> 22 | U29: Jack Malumbelumbe | V29: 0 | W29: 0
A30: ='Q2'!A98 -> 07.07.2025 | B30: ='Q2'!B98 -> Jean Luzada | C30: ='Q2'!D98 -> 10 | D30: ='Q2'!E98 -> 10 | E30: ='Q2'!F98 -> 10 | F30: ='Q2'!G98 -> 10 | G30: ='Q2'!H98 -> 10 | H30: ='Q2'!I98 -> 9 | I30: ='Q2'!J98 -> N/A | J30: ='Q2'!K98 -> 10 | ... Q30: ='Q2'!R98 -> 10 | R30: =MIN(D30:Q30) -> 9 | U30: Maleka Legodi | V30: 0 | W30: 0
A31: ='Q2'!A98 -> 07.07.2025 | B31: ='Q2'!C98 -> Vhea De Fiesta | C31: 10 | D31: 10 | E31: 10 | F31: 10 | G31: 10 | H31: 9 | I31: N/A | J31: 10 | K31: 10 | L31: N/A | M31: N/A | N31: N/A | O31: 10 | P31: N/A | Q31: 10 | R31: =MIN(D31:Q31) -> 9 | U31: Surprise Mosehla | V31: 0 | W31: 0
A32: 7.22.2025 | B32: ='Q2'!B116 -> Irish Ferreras | C32: ='Q2'!D116 -> 14 | D32: ='Q2'!E116 -> 14 | E32: ='Q2'!F116 -> 14 | F32: ='Q2'!G116 -> 14 | G32: ='Q2'!H116 -> 14 | H32: ='Q2'!I116 -> 15 | I32: ='Q2'!J116 -> N/A | J32: ='Q2'!K116 -> 14 | ... Q32: ='Q2'!R116 -> 14 | R32: =MIN(D32:Q32) -> 14 | U32: Tshepo Nkumelini | V32: 0 | W32: 0
A33: 7.22.2025 | B33: ='Q2'!C116 -> Kate Postres | C33: ='Q2'!D116 -> 14 | D33: ='Q2'!E116 -> 14 | E33: ='Q2'!F116 -> 14 | F33: ='Q2'!G116 -> 14 | G33: ='Q2'!H116 -> 14 | H33: ='Q2'!I116 -> 15 | I33: ='Q2'!J116 -> N/A | ... Q33: ='Q2'!R116 -> 14 | R33: =MIN(D33:Q33) -> 14 | U33: Siyabulele Mvimbi | V33: 0 | W33: 0
A34: 07.28.2025 | B34: ='[1]Class Summary'!$B$11 -> Jean Luzada | C34: ='Q2'!D135 -> 15 | D34: ='Q2'!E135 -> 17 | E34: ='Q2'!F135 -> 17 | F34: ='Q2'!G135 -> 16 | G34: ='Q2'!H135 -> 17 | H34: ='Q2'!I135 -> 16 | I34: ='Q2'!J135 -> 17 | J34: ='Q2'!K135 -> 18 | ... Q34: ='Q2'!R135 -> 18 | R34: =MIN(D34:Q34) -> 16 | U34: Grand Total | V34: 838 | W34: 722
A35: 07.28.2025 | B35: ='[1]Class Summary'!$B$12 -> Maria Lourdes Tendenilla | C35: ='Q2'!D135 -> 15 | D35: ='Q2'!E135 -> 17 | E35: ='Q2'!F135 -> 17 | F35: ='Q2'!G135 -> 16 | G35: ='Q2'!H135 -> 17 | H35: ='Q2'!I135 -> 16 | I35: ='Q2'!J135 -> 17 | J35: ='Q2'!K135 -> 18 | ... Q35: ='Q2'!R135 -> 18 | R35: =MIN(D35:Q35) -> 16
A36: 08.18.2025 | B36: ='Q2'!B154 -> Anabelle Pizon | C36: ='Q2'!D154 -> 12 | D36: ='Q2'!E154 -> 13 | E36: ='Q2'!F154 -> 13 | F36: ='Q2'!G154 -> 13 | G36: ='Q2'!H154 -> 13 | H36: ='Q2'!I154 -> 13 | I36: ='Q2'!J154 -> N/A | J36: ='Q2'!K154 -> 13 | ... Q36: ='Q2'!R154 -> 13 | R36: =MIN(D36:Q36) -> 13
A37: 08.18.2025 | B37: ='Q2'!C154 -> Jennifer Ramirez | C37: ='Q2'!D154 -> 12 | D37: ='Q2'!E154 -> 13 | E37: ='Q2'!F154 -> 13 | F37: ='Q2'!G154 -> 13 | G37: ='Q2'!H154 -> 13 | H37: ='Q2'!I154 -> 13 | I37: ='Q2'!J154 -> N/A | ... Q37: ='Q2'!R154 -> 13 | R37: =MIN(D37:Q37) -> 13
A38: 08.18.2025 | B38: ='Q2'!B169 -> Kate Saigo | C38: ='Q2'!D169 -> 13 | D38: ='Q2'!E169 -> 16 | E38: ='Q2'!F169 -> 16 | F38: ='Q2'!G169 -> 15 | G38: ='Q2'!H169 -> 16 | H38: ='Q2'!I169 -> 15 | I38: ='Q2'!J169 -> 16 | J38: ='Q2'!K169 -> 16 | ... Q38: ='Q2'!R169 -> 16 | R38: =MIN(D38:Q38) -> 15
A39: 08.18.2025 | B39: ='Q2'!C169 -> Robin Yasona | C39: ='Q2'!D169 -> 13 | D39: ='Q2'!E169 -> 16 | E39: ='Q2'!F169 -> 16 | F39: ='Q2'!G169 -> 15 | G39: ='Q2'!H169 -> 16 | H39: ='Q2'!I169 -> 15 | I39: ='Q2'!J169 -> 16 | ... Q39: ='Q2'!R169 -> 16 | R39: =MIN(D39:Q39) -> 15
A40: 08.18.2025 | B40: Nancy Price | C40: ='Q2'!D187 -> 14 | D40: ='Q2'!E187 -> 15 | E40: ='Q2'!F187 -> 15 | F40: ='Q2'!G187 -> 15 | G40: ='Q2'!H187 -> 15 | H40: ='Q2'!I187 -> 15 | I40: ='Q2'!J187 -> N/A | J40: ='Q2'!K187 -> 15 | ... Q40: ='Q2'!R187 -> 15 | R40: =MIN(D40:Q40) -> 15
...

Sheet Q1
A1: Class Start Date | B1: Trainer Name | C1: 0 | D1: Number of Agent Transition to Nesting | E1: Whistleblowing | F1: PCB Compliance Coaching Model | G1: Complaint Management Theory | H1: NTT BPO PCB AML - General | I1: Senior's Fraud | J1: Corporate Policy and Procedure Employee Sign off | K1: NTT BPO CASL | L1: NTT BPO AODA | M1: NTT BPO Health and Safety - Onshore or Offshore version | N1: NTT BPO WHMIS | O1: NTT BPO Violence and Harassment in the Workplace Quiz | P1: NTT BPO Insider Fraud Awareness | Q1: NTT BPO Privacy + Security | R1: NTT BPO Human Rights Code | S1: Notes | T1: Last day in Training
A2: 03.10.2025 | B2: Jean LuZada | C2: Mel Cajucom | D2: =SUM(D3:D31) -> 18 | E2: =COUNTIF(E3:E31, ">79%") -> 25 | F2: =COUNTIF(F3:F31, ">79%") -> 25 | G2: =COUNTIF(G3:G31, ">79%") -> 22 | H2: =COUNTIF(H3:H31, ">79%") -> 25 | I2: =COUNTIF(I3:I31, ">79%") -> 22 | J2: =COUNTIF(J3:J31, ">99.9%") -> 25 | K2: =COUNTIF(K3:K31, ">79%") -> 25 | L2: =COUNTIF(L3:L31, ">79%") -> 25 | M2: =COUNTIF(M3:M31, ">79%") -> 25 | N2: =COUNTIF(N3:N31, ">79%") -> 1 | O2: =COUNTIF(O3:O31, ">79%") -> 1 | P2: =COUNTIF(P3:P31, ">79%") -> 25 | Q2: =COUNTIF(Q3:Q31, ">79%") -> 25 | R2: =COUNTIF(R3:R31, ">79%") -> 25
A3: ='[2]Student Data'!M5 -> 341480 | B3: =[2]Reporting!C4 -> Transition to Production with SMART plan | C3: =[2]Reporting!F4 -> Cristy Abaya | D3: {=--(SUM(COUNTIF(B3,{"*nest*","*grad*","*trans*","*1B*","*1C*"}))>0)} -> 1 | E3: =[2]Performance!Q5 -> 1 | F3: =[2]Performance!R5 -> 1 | G3: =[2]Performance!S5 -> 0.9 | H3: =[2]Performance!T5 -> 1 | I3: =[2]Performance!U5 -> 0.83 | J3: =[2]Performance!H5 -> 1 | K3: =[2]Performance!I5 -> 0.88 | L3: =[2]Performance!J5 -> 0.8 | M3: =[2]Performance!K5 -> 1 | N3: =[2]Performance!L5 -> N/A | O3: =[2]Performance!M5 -> N/A | P3: =[2]Performance!N5 -> 1 | Q3: =[2]Performance!O5 -> 1 | R3: =[2]Performance!P5 -> 0.91
A4: ='[2]Student Data'!M6 -> 341515 | B4: =[2]Reporting!C5 -> Transition to Production with SMART plan | C4: =[2]Reporting!F5 -> Sheryl Villegas | D4: {=--(SUM(COUNTIF(B4,{"*nest*","*grad*","*trans*","*1B*","*1C*"}))>0)} -> 1 | E4: =[2]Performance!Q6 -> 1 | F4: =[2]Performance!R6 -> 1 | G4: =[2]Performance!S6 -> 0.96 | H4: =[2]Performance!T6 -> 1 | I4: =[2]Performance!U6 -> 0.86 | J4: =[2]Performance!H6 -> 1 | K4: =[2]Performance!I6 -> 0.88 | L4: =[2]Performance!J6 -> 1 | M4: =[2]Performance!K6 -> 1 | N4: =[2]Performance!L6 -> N/A | O4: =[2]Performance!M6 -> N/A | P4: =[2]Performance!N6 -> 1 | Q4: =[2]Performance!O6 -> 1 | R4: =[2]Performance!P6 -> 1
A5: ='[2]Student Data'!M7 -> 341511 | B5: =[2]Reporting!C6 -> Resigned-Nesting 1A | C5: =[2]Reporting!F6 -> Nikki Jane Macaraig | D5: {=--(SUM(COUNTIF(B5,{"*nest*","*grad*","*trans*","*1B*","*1C*"}))>0)} -> 1 | E5: =[2]Performance!Q7 -> 1 | F5: =[2]Performance!R7 -> 1 | G5: =[2]Performance!S7 -> n/a | H5: =[2]Performance!T7 -> 0.8 | I5: =[2]Performance!U7 -> n/a | J5: =[2]Performance!H7 -> 1 | K5: =[2]Performance!I7 -> 0.88 | L5: =[2]Performance!J7 -> 1 | M5: =[2]Performance!K7 -> 1 | N5: =[2]Performance!L7 -> N/A | O5: =[2]Performance!M7 -> N/A | P5: =[2]Performance!N7 -> 1 | Q5: =[2]Performance!O7 -> 1 | R5: =[2]Performance!P7 -> 1
A6: ='[2]Student Data'!M8 -> 341492 | B6: =[2]Reporting!C7 -> Resigned Tier 1A | C6: =[2]Reporting!F7 -> Jeny Rose Cadiz | D6: {=--(SUM(COUNTIF(B6,{"*nest*","*grad*","*trans*","*1B*","*1C*"}))>0)} -> 0 | E6: =[2]Performance!Q8 -> 1 | F6: =[2]Performance!R8 -> 1 | G6: =[2]Performance!S8 -> 0.86 | H6: =[2]Performance!T8 -> 1 | I6: =[2]Performance!U8 -> 1 | J6: =[2]Performance!H8 -> 1 | K6: =[2]Performance!I8 -> 1 | L6: =[2]Performance!J8 -> 1 | M6: =[2]Performance!K8 -> 1 | N6: =[2]Performance!L8 -> N/A | O6: =[2]Performance!M8 -> N/A | P6: =[2]Performance!N8 -> 1 | Q6: =[2]Performance!O8 -> 1 | R6: =[2]Performance!P8 -> 1
A7: ='[2]Student Data'!M9 -> 341481 | B7: =[2]Reporting!C8 -> Transition to Production | C7: =[2]Reporting!F8 -> Avelene Bernardo | D7: {=--(SUM(COUNTIF(B7,{"*nest*","*grad*","*trans*","*1B*","*1C*"}))>0)} -> 1 | E7: =[2]Performance!Q9 -> 1 | F7: =[2]Performance!R9 -> 1 | G7: =[2]Performance!S9 -> 1 | H7: =[2]Performance!T9 -> 1 | I7: =[2]Performance!U9 -> 1 | J7: =[2]Performance!H9 -> 1 | K7: =[2]Performance!I9 -> 1 | L7: =[2]Performance!J9 -> 1 | M7: =[2]Performance!K9 -> 1 | N7: =[2]Performance!L9 -> N/A | O7: =[2]Performance!M9 -> N/A | P7: =[2]Performance!N9 -> 1 | Q7: =[2]Performance!O9 -> 1 | R7: =[2]Performance!P9 -> 0.94
A8: ='[2]Student Data'!M10 -> 341520 | B8: =[2]Reporting!C9 -> Transition to Production | C8: =[2]Reporting!F9 -> Christian Rojo | D8: {=--(SUM(COUNTIF(B8,{"*nest*","*grad*","*trans*","*1B*","*1C*"}))>0)} -> 1 | E8: =[2]Performance!Q10 -> 1 | F8: =[2]Performance!R10 -> 1 | G8: =[2]Performance!S10 -> 0.9 | H8: =[2]Performance!T10 -> 1 | I8: =[2]Performance!U10 -> 1 | J8: =[2]Performance!H10 -> 1 | K8: =[2]Performance!I10 -> 1 | L8: =[2]Performance!J10 -> 1 | M8: =[2]Performance!K10 -> 1 | N8: =[2]Performance!L10 -> N/A | O8: =[2]Performance!M10 -> N/A | P8: =[2]Performance!N10 -> 1 | Q8: =[2]Performance!O10 -> 1 | R8: =[2]Performance!P10 -> 1
A9: ='[2]Student Data'!M11 -> 341517 | B9: =[2]Reporting!C10 -> Transition to Production with SMART plan | C9: =[2]Reporting!F10 -> Tyrone Albert Gonzales | D9: {=--(SUM(COUNTIF(B9,{"*nest*","*grad*","*trans*","*1B*","*1C*"}))>0)} -> 1 | E9: =[2]Performance!Q11 -> 1 | F9: =[2]Performance!R11 -> 1 | G9: =[2]Performance!S11 -> 0.88 | H9: =[2]Performance!T11 -> 1 | I9: =[2]Performance!U11 -> 0.86 | J9: =[2]Performance!H11 -> 1 | K9: =[2]Performance!I11 -> 0.88 | L9: =[2]Performance!J11 -> 1 | M9: =[2]Performance!K11 -> 1 | N9: =[2]Performance!L11 -> N/A | O9: =[2]Performance!M11 -> N/A | P9: =[2]Performance!N11 -> 1 | Q9: =[2]Performance!O11 -> 1 | R9: =[2]Performance!P11 -> 0.86
A10: ='[2]Student Data'!M12 -> 0 | B10: =[2]Reporting!C11 -> Moved/Joining Alternate Class/Program | C10: =[2]Reporting!F11 -> Cristel Ann Melgar | D10: {=--(SUM(COUNTIF(B10,{"*nest*","*grad*","*trans*","*1B*","*1C*"}))>0)} -> 0 | E10: =[2]Performance!Q12 -> n/a | F10: =[2]Performance!R12 -> n/a | G10: =[2]Performance!S12 -> n/a | H10: =[2]Performance!T12 -> n/a | I10: =[2]Performance!U12 -> n/a | J10: =[2]Performance!H12 -> n/a | K10: =[2]Performance!I12 -> n/a | L10: =[2]Performance!J12 -> n/a | M10: =[2]Performance!K12 -> n/a | N10: =[2]Performance!L12 -> N/A | O10: =[2]Performance!M12 -> N/A | P10: =[2]Performance!N12 -> n/a | Q10: =[2]Performance!O12 -> n/a | R10: =[2]Performance!P12 -> n/a
A11: ='[2]Student Data'!M13 -> 0 | B11: =[2]Reporting!C12 -> Did not Start | C11: =[2]Reporting!F12 -> Orpha Isabel Percy | D11: {=--(SUM(COUNTIF(B11,{"*nest*","*grad*","*trans*","*1B*","*1C*"}))>0)} -> 0 | E11: =[2]Performance!Q13 -> n/a | F11: =[2]Performance!R13 -> n/a | G11: =[2]Performance!S13 -> n/a | H11: =[2]Performance!T13 -> n/a | I11: =[2]Performance!U13 -> n/a | J11: =[2]Performance!H13 -> n/a | K11: =[2]Performance!I13 -> n/a | L11: =[2]Performance!J13 -> n/a | M11: =[2]Performance!K13 -> n/a | N11: =[2]Performance!L13 -> N/A | O11: =[2]Performance!M13 -> N/A | P11: =[2]Performance!N13 -> n/a | Q11: =[2]Performance!O13 -> n/a | R11: =[2]Performance!P13 -> n/a
A12: ='[2]Student Data'!M14 -> 341482 | B12: =[2]Reporting!C13 -> LOA | C12: =[2]Reporting!F13 -> Elias Mariano Bautista | D12: {=--(SUM(COUNTIF(B12,{"*nest*","*grad*","*trans*","*1B*","*1C*"}))>0)} -> 0 | E12: =[2]Performance!Q14 -> 1 | F12: =[2]Performance!R14 -> 1 | G12: =[2]Performance!S14 -> 1 | H12: =[2]Performance!T14 -> 1 | I12: =[2]Performance!U14 -> 1 | J12: =[2]Performance!H14 -> 1 | K12: =[2]Performance!I14 -> 1 | L12: =[2]Performance!J14 -> 1 | M12: =[2]Performance!K14 -> 1 | N12: =[2]Performance!L14 -> N/A | O12: =[2]Performance!M14 -> N/A | P12: =[2]Performance!N14 -> 1 | Q12: =[2]Performance!O14 -> 1 | R12: =[2]Performance!P14 -> 0.94
A13: ='[2]Student Data'!M15 -> 0 | B13: =[2]Reporting!C14 -> Did not Start | C13: =[2]Reporting!F14 -> Marianne Manicad | D13: {=--(SUM(COUNTIF(B13,{"*nest*","*grad*","*trans*","*1B*","*1C*"}))>0)} -> 0 | E13: =[2]Performance!Q15 -> n/a | F13: =[2]Performance!R15 -> n/a | G13: =[2]Performance!S15 -> n/a | H13: =[2]Performance!T15 -> n/a | I13: =[2]Performance!U15 -> n/a | J13: =[2]Performance!H15 -> n/a | K13: =[2]Performance!I15 -> n/a | L13: =[2]Performance!J15 -> n/a | M13: =[2]Performance!K15 -> n/a | N13: =[2]Performance!L15 -> N/A | O13: =[2]Performance!M15 -> N/A | P13: =[2]Performance!N15 -> n/a | Q13: =[2]Performance!O15 -> n/a | R13: =[2]Performance!P15 -> n/a
A14: ='[2]Student Data'!M16 -> 341489 | B14: =[2]Reporting!C15 -> Transition to Production | C14: =[2]Reporting!F15 -> Jan Christian Soriño | D14: {=--(SUM(COUNTIF(B14,{"*nest*","*grad*","*trans*","*1B*","*1C*"}))>0)} -> 1 | E14: =[2]Performance!Q16 -> 1 | F14: =[2]Performance!R16 -> 1 | G14: =[2]Performance!S16 -> 0.84 | H14: =[2]Performance!T16 -> 1 | I14: =[2]Performance!U16 -> 0.9 | J14: =[2]Performance!H16 -> 1 | K14: =[2]Performance!I16 -> 0.88 | L14: =[2]Performance!J16 -> 1 | M14: =[2]Performance!K16 -> 1 | N14: =[2]Performance!L16 -> N/A | O14: =[2]Performance!M16 -> N/A | P14: =[2]Performance!N16 -> 1 | Q14: =[2]Performance!O16 -> 1 | R14: =[2]Performance!P16 -> 1
... A31: ='[2]Student Data'!M33 -> 341021 | B31: =[2]Reporting!C32 -> Transition to Production | C31: =[2]Reporting!F32 -> Marvelous Dayo | D31: {=--(SUM(COUNTIF(B31,{"*nest*","*grad*","*trans*","*1B*","*1C*"}))>0)} -> 1 | E31: =[2]Performance!Q33 -> 1 | F31: =[2]Performance!R33 -> 1 | G31: =[2]Performance!S33 -> 1 | H31: =[2]Performance!T33 -> 1 | I31: =[2]Performance!U33 -> 0.89 | J31: =[2]Performance!H33 -> 1 | K31: =[2]Performance!I33 -> 1 | L31: =[2]Performance!J33 -> 1 | M31: =[2]Performance!K33 -> 1 | N31: =[2]Performance!L33 -> 1 | O31: =[2]Performance!M33 -> 1 | P31: =[2]Performance!N33 -> 1 | Q31: =[2]Performance!O33 -> 1 | R31: =[2]Performance!P33 -> 0.94
A32: 03.24.2025 | B32: Irish Ferreras | C32: Chase Argamosa | D32: =SUM(D33:D77) -> 31 | E32: =COUNTIF(E33:E77, ">79%") -> 33 | F32: =COUNTIF(F33:F77, ">79%") -> 33 | G32: =COUNTIF(G33:G77, ">79%") -> 30 | H32: =COUNTIF(H33:H77, ">79%") -> 33 | I32: =COUNTIF(I33:I77, ">79%") -> 27 | J32: =COUNTIF(J33:J77, ">99.9%") -> 11 | K32: =COUNTIF(K33:K77, ">79%") -> 33 | L32: =COUNTIF(L33:L77, ">79%") -> 33 | M32: =COUNTIF(M33:M77, ">79%") -> 11 | N32: =COUNTIF(N33:N77, ">79%") -> 11 | O32: =COUNTIF(O33:O77, ">79%") -> 11 | P32: =COUNTIF(P33:P77, ">79%") -> 32 | Q32: =COUNTIF(Q33:Q77, ">79%") -> 11 | R32: =COUNTIF(R33:R77, ">79%") -> 33 | ... T32: =COUNTIF(T33:T77, ">79%") -> 0
A33: ='[3]Student Data'!M5 -> 40439 | B33: =[3]Reporting!C4 -> Transition to Production with SMART plan | C33: =[3]Reporting!F4 -> Julie-Anne (Julie) Brideau | D33: {=--(SUM(COUNTIF(B33,{"*nest*","*grad*","*trans*","*1B*","*1C*"}))>0)} -> 1 | E33: =[3]Performance!Q5 -> 1 | F33: =[3]Performance!R5 -> 1 | G33: =[3]Performance!S5 -> 0.88 | H33: =[3]Performance!T5 -> 0.8 | I33: =[3]Performance!U5 -> 0.85 | J33: =[3]Performance!H5 -> 1 | K33: =[3]Performance!I5 -> 0.88 | L33: =[3]Performance!J5 -> 1 | M33: =[3]Performance!K5 -> 1 | N33: =[3]Performance!L5 -> 0.89 | O33: =[3]Performance!M5 -> 1 | P33: =[3]Performance!N5 -> 1 | Q33: =[3]Performance!O5 -> 0.91 | R33: =[3]Performance!P5 -> 0.82
A34: ='[3]Student Data'!M6 -> 39295 | B34: =[3]Reporting!C5 -> Terminated-Nesting 1B | C34: =[3]Reporting!F5 -> Melanie Caissie | D34: {=--(SUM(COUNTIF(B34,{"*nest*","*grad*","*trans*","*1B*","*1C*"}))>0)} -> 1 | E34: =[3]Performance!Q6 -> 1 | F34: =[3]Performance!R6 -> 1 | G34: =[3]Performance!S6 -> 0.82 | H34: =[3]Performance!T6 -> 0.8 | I34: =[3]Performance!U6 -> 0.9 | J34: =[3]Performance!H6 -> 1 | K34: =[3]Performance!I6 -> 1 | L34: =[3]Performance!J6 -> 0.8 | M34: =[3]Performance!K6 -> 1 | N34: =[3]Performance!L6 -> 0.89 | O34: =[3]Performance!M6 -> 1 | P34: =[3]Performance!N6 -> 1 | Q34: =[3]Performance!O6 -> 0.91 | R34: =[3]Performance!P6 -> 0.84
A35: ='[3]Student Data'!M7 -> 40443 | B35: =[3]Reporting!C6 -> Terminated-Nesting 3 | C35: =[3]Reporting!F6 -> Vanessa Irakoze | D35: {=--(SUM(COUNTIF(B35,{"*nest*","*grad*","*trans*","*1B*","*1C*"}))>0)} -> 1 | E35: =[3]Performance!Q7 -> 1 | F35: =[3]Performance!R7 -> 1 | G35: =[3]Performance!S7 -> 0.8 | H35: =[3]Performance!T7 -> 0.8 | I35: =[3]Performance!U7 -> 0.83 | J35: =[3]Performance!H7 -> 1 | K35: =[3]Performance!I7 -> 1 | L35: =[3]Performance!J7 -> 1 | M35: =[3]Performance!K7 -> 1 | N35: =[3]Performance!L7 -> 1 | O35: =[3]Performance!M7 -> 1 | P35: =[3]Performance!N7 -> 1 | Q35: =[3]Performance!O7 -> 1 | R35: =[3]Performance!P7 -> 0.82
A36: ='[3]Student Data'!M8 -> 40365 | B36: =[3]Reporting!C7 -> Terminated-Nesting 3 | C36: =[3]Reporting!F7 -> Clara-Delicia Itangamahoro | D36: {=--(SUM(COUNTIF(B36,{"*nest*","*grad*","*trans*","*1B*","*1C*"}))>0)} -> 1 | E36: =[3]Performance!Q8 -> 1 | F36: =[3]Performance!R8 -> 1 | G36: =[3]Performance!S8 -> 0.94 | H36: =[3]Performance!T8 -> 0.8 | I36: =[3]Performance!U8 -> 0.9 | J36: =[3]Performance!H8 -> 1 | K36: =[3]Performance!I8 -> 0.88 | L36: =[3]Performance!J8 -> 1 | M36: =[3]Performance!K8 -> 1 | N36: =[3]Performance!L8 -> 0.89 | O36: =[3]Performance!M8 -> 1 | P36: =[3]Performance!N8 -> 1 | Q36: =[3]Performance!O8 -> 0.82 | R36: =[3]Performance!P8 -> 1
A37: ='[3]Student Data'!M9 -> 40438 | B37: =[3]Reporting!C8 -> Terminated-Nesting 3 | C37: =[3]Reporting!F8 -> Marie Carmel Fedorah Joseph | D37: {=--(SUM(COUNTIF(B37,{"*nest*","*grad*","*trans*","*1B*","*1C*"}))>0)} -> 1 | E37: =[3]Performance!Q9 -> 1 | F37: =[3]Performance!R9 -> 1 | G37: =[3]Performance!S9 -> 0.8 | H37: =[3]Performance!T9 -> 1 | I37: =[3]Performance!U9 -> 1 | J37: =[3]Performance!H9 -> 1 | K37: =[3]Performance!I9 -> 1 | L37: =[3]Performance!J9 -> 1 | M37: =[3]Performance!K9 -> 1 | N37: =[3]Performance!L9 -> 1 | O37: =[3]Performance!M9 -> 1 | P37: =[3]Performance!N9 -> 1 | Q37: =[3]Performance!O9 -> 1 | R37: =[3]Performance!P9 -> 0.94
A38: ='[3]Student Data'!M10 -> 40441 | B38: =[3]Reporting!C9 -> Did not Start | C38: =[3]Reporting!F9 -> Loic Kamgang Foyet | D38: {=--(SUM(COUNTIF(B38,{"*nest*","*grad*","*trans*","*1B*","*1C*"}))>0)} -> 0 | E38: =[3]Performance!Q10 -> 0 | F38: =[3]Performance!R10 -> 0 | G38: =[3]Performance!S10 -> 0 | H38: =[3]Performance!T10 -> 0 | I38: =[3]Performance!U10 -> 0 | J38: =[3]Performance!H10 -> 0 | K38: =[3]Performance!I10 -> 0 | L38: =[3]Performance!J10 -> 0 | M38: =[3]Performance!K10 -> 0 | N38: =[3]Performance!L10 -> 0 | O38: =[3]Performance!M10 -> 0 | P38: =[3]Performance!N10 -> 0 | Q38: =[3]Performance!O10 -> 0 | R38: =[3]Performance!P10 -> 0
A39: ='[3]Student Data'!M11 -> 40444 | B39: =[3]Reporting!C10 -> Resigned-Nesting 1B | C39: =[3]Reporting!F10 -> Dakiel Latreille | D39: {=--(SUM(COUNTIF(B39,{"*nest*","*grad*","*trans*","*1B*","*1C*"}))>0)} -> 1 | E39: =[3]Performance!Q11 -> 1 | F39: =[3]Performance!R11 -> 1 | G39: =[3]Performance!S11 -> 0.82 | H39: =[3]Performance!T11 -> 1 | I39: =[3]Performance!U11 -> 0.9 | J39: =[3]Performance!H11 -> 1 | K39: =[3]Performance!I11 -> 1 | L39: =[3]Performance!J11 -> 1 | M39: =[3]Performance!K11 -> 1 | N39: =[3]Performance!L11 -> 0.89 | O39: =[3]Performance!M11 -> 1 | P39: =[3]Performance!N11 -> 1 | Q39: =[3]Performance!O11 -> 0.82 | R39: =[3]Performance!P11 -> 1
A40: ='[3]Student Data'!M12 -> 40436 | B40: =[3]Reporting!C11 -> Resigned-Nesting 1B | C40: =[3]Reporting!F11 -> Jeremy (Jay) Lavoie | D40: {=--(SUM(COUNTIF(B40,{"*nest*","*grad*","*trans*","*1B*","*1C*"}))>0)} -> 1 | E40: =[3]Performance!Q12 -> 1 | F40: =[3]Performance!R12 -> 1 | G40: =[3]Performance!S12 -> 0 | H40: =[3]Performance!T12 -> 0.8 | I40: =[3]Performance!U12 -> 0.87 | J40: =[3]Performance!H12 -> 1 | K40: =[3]Performance!I12 -> 0.88 | L40: =[3]Performance!J12 -> 1 | M40: =[3]Performance!K12 -> 1 | N40: =[3]Performance!L12 -> 1 | O40: =[3]Performance!M12 -> 1 | P40: =[3]Performance!N12 -> 1 | Q40: =[3]Performance!O12 -> 0.82 | R40: =[3]Performance!P12 -> 0.94
A41: ='[3]Student Data'!M13 -> 40437 | B41: =[3]Reporting!C12 -> Terminated Tier 1B | C41: =[3]Reporting!F12 -> Danika Legacy-Aubé | D41: {=--(SUM(COUNTIF(B41,{"*nest*","*grad*","*trans*","*1B*","*1C*"}))>0)} -> 1 | E41: =[3]Performance!Q13 -> 0.8 | F41: =[3]Performance!R13 -> 1 | G41: =[3]Performance!S13 -> 0 | H41: =[3]Performance!T13 -> 1 | I41: =[3]Performance!U13 -> 0 | J41: =[3]Performance!H13 -> 1 | K41: =[3]Performance!I13 -> 1 | L41: =[3]Performance!J13 -> 1 | M41: =[3]Performance!K13 -> 1 | N41: =[3]Performance!L13 -> 1 | O41: =[3]Performance!M13 -> 1 | P41: =[3]Performance!N13 -> 1 | Q41: =[3]Performance!O13 -> 0.82 | R41: =[3]Performance!P13 -> 0.88
A42: ='[3]Student Data'!M14 -> 14313 | B42: =[3]Reporting!C13 -> Transition to Production | C42: =[3]Reporting!F13 -> Jennifer (Jenn) MacLean | D42: {=--(SUM(COUNTIF(B42,{"*nest*","*grad*","*trans*","*1B*","*1C*"}))>0)} -> 1 | E42: =[3]Performance!Q14 -> 1 | F42: =[3]Performance!R14 -> 1 | G42: =[3]Performance!S14 -> 0.84 | H42: =[3]Performance!T14 -> 1 | I42: =[3]Performance!U14 -> 0.93 | J42: =[3]Performance!H14 -> 1 | K42: =[3]Performance!I14 -> 1 | L42: =[3]Performance!J14 -> 1 | M42: =[3]Performance!K14 -> 1 | N42: =[3]Performance!L14 -> 1 | O42: =[3]Performance!M14 -> 1 | P42: =[3]Performance!N14 -> 1 | Q42: =[3]Performance!O14 -> 0.91 | R42: =[3]Performance!P14 -> 0.88
A43: ='[3]Student Data'!M15 -> 40440 | B43: =[3]Reporting!C14 -> Transition to Production | C43: =[3]Reporting!F14 -> Diane Matanye Sofo | D43: {=--(SUM(COUNTIF(B43,{"*nest*","*grad*","*trans*","*1B*","*1C*"}))>0)} -> 1 | E43: =[3]Performance!Q15 -> 1 | F43: =[3]Performance!R15 -> 1 | G43: =[3]Performance!S15 -> 0.8 | H43: =[3]Performance!T15 -> 1 | I43: =[3]Performance!U15 -> 0.92 | J43: =[3]Performance!H15 -> 1 | K43: =[3]Performance!I15 -> 0.88 | L43: =[3]Performance!J15 -> 1 | M43: =[3]Performance!K15 -> 1 | N43: =[3]Performance!L15 -> 1 | O43: =[3]Performance!M15 -> 1 | P43: =[3]Performance!N15 -> 1 | Q43: =[3]Performance!O15 -> 1 | R43: =[3]Performance!P15 -> 0.88
A44: ='[3]Student Data'!M16 -> 37260 | B44: =[3]Reporting!C15 -> Transition to Production | C44: =[3]Reporting!F15 -> Sarah Matondo | D44: {=--(SUM(COUNTIF(B44,{"*nest*","*grad*","*trans*","*1B*","*1C*"}))>0)} -> 1 | E44: =[3]Performance!Q16 -> 1 | F44: =[3]Performance!R16 -> 1 | G44: =[3]Performance!S16 -> 0.9 | H44: =[3]Performance!T16 -> 0.8 | I44: =[3]Performance!U16 -> 0 | J44: =[3]Performance!H16 -> 1 | K44: =[3]Performance!I16 -> 0.88 | L44: =[3]Performance!J16 -> 0.8 | M44: =[3]Performance!K16 -> 1 | N44: =[3]Performance!L16 -> 1 | O44: =[3]Performance!M16 -> 1 | P44: =[3]Performance!N16 -> 1 | Q44: =[3]Performance!O16 -> 0.82 | R44: =[3]Performance!P16 -> 0.97
... A77: ='[3]Student Data'!M49 -> 342041 | B77: =[3]Reporting!C48 -> Transition to Production | C77: =[3]Reporting!F48 -> Kathleen Cleo (KC) Villasanta | D77: {=--(SUM(COUNTIF(B77,{"*nest*","*grad*","*trans*","*1B*","*1C*"}))>0)} -> 1 | E77: =[3]Performance!Q49 -> 0 | F77: =[3]Performance!R49 -> 0 | G77: =[3]Performance!S49 -> 0 | H77: =[3]Performance!T49 -> 0 | I77: =[3]Performance!U49 -> 0 | J77: =[3]Performance!H49 | K77: =[3]Performance!I49 -> 0 | L77: =[3]Performance!J49 -> 0 | M77: =[3]Performance!K49 | N77: =[3]Performance!L49 | O77: =[3]Performance!M49 | P77: =[3]Performance!N49 -> 0 | Q77: =[3]Performance!O49 | R77: =[3]Performance!P49 -> 0
A78: 45761 | B78: Vera Hibaya | C78: Catherine Cachero | D78: =SUM(D79:D98) -> 18 | E78: =COUNTIF(E79:E98, ">79%") -> 19 | F78: =COUNTIF(F79:F98, ">79%") -> 19 | G78: =COUNTIF(G79:G98, ">79%") -> 18 | H78: =COUNTIF(H79:H98, ">79%") -> 19 | I78: =COUNTIF(I79:I98, ">79%") -> 18 | J78: =COUNTIF(J79:J98, ">79%") -> 0 | K78: =COUNTIF(K79:K98, ">79%") -> 19 | L78: =COUNTIF(L79:L98, ">79%") -> 19 | ... R78: =COUNTIF(R79:R98, ">79%") -> 19 | S78: =COUNTIF(S79:S123, ">79%") -> 0 | T78: =COUNTIF(T79:T123, ">79%") -> 0
A79: ='[4]Student Data'!M5 -> 342810 | B79: =[4]Reporting!C4 -> Transition to Production | C79: =[4]Reporting!F4 -> Trixia Anne Abillon | D79: {=--(SUM(COUNTIF(B79,{"*nest*","*grad*","*trans*","*1B*","*1C*"}))>0)} -> 1 | E79: =[4]Performance!Q5 -> 1 | F79: =[4]Performance!R5 -> 1 | G79: =[4]Performance!S5 -> 1 | H79: =[4]Performance!T5 -> 1 | I79: =[4]Performance!U5 -> 0.86 | J79: =[4]Performance!H5 -> N/A | K79: =[4]Performance!I5 -> 1 | L79: =[4]Performance!J5 -> 1 | M79: =[4]Performance!K5 -> N/A | N79: =[4]Performance!L5 -> N/A | O79: =[4]Performance!M5 -> N/A | P79: =[4]Performance!N5 -> 1 | Q79: =[4]Performance!O5 -> N/A | R79: =[4]Performance!P5 -> 1
A80: ='[4]Student Data'!M6 -> 342804 | B80: =[4]Reporting!C5 -> Resigned-Nesting 1B | C80: =[4]Reporting!F5 -> Jose Basinillo | D80: {=--(SUM(COUNTIF(B80,{"*nest*","*grad*","*trans*","*1B*","*1C*"}))>0)} -> 1 | E80: =[4]Performance!Q6 -> 1 | F80: =[4]Performance!R6 -> 1 | G80: =[4]Performance!S6 -> 1 | H80: =[4]Performance!T6 -> 1 | I80: =[4]Performance!U6 -> 0.8 | J80: =[4]Performance!H6 -> N/A | K80: =[4]Performance!I6 -> 0.88 | L80: =[4]Performance!J6 -> 1 | M80: =[4]Performance!K6 -> N/A | N80: =[4]Performance!L6 -> N/A | O80: =[4]Performance!M6 -> N/A | P80: =[4]Performance!N6 -> 1 | Q80: =[4]Performance!O6 -> N/A | R80: =[4]Performance!P6 -> 0.94
A81: ='[4]Student Data'!M7 -> 342800 | B81: =[4]Reporting!C6 -> Moved/Joining Alternate Class/Program | C81: =[4]Reporting!F6 -> Jasper Bautista | D81: {=--(SUM(COUNTIF(B81,{"*nest*","*grad*","*trans*","*1B*","*1C*"}))>0)} -> 0 | E81: =[4]Performance!Q7 -> 1 | F81: =[4]Performance!R7 -> 1 | G81: =[4]Performance!S7 -> TRANSF | H81: =[4]Performance!T7 -> 1 | I81: =[4]Performance!U7 -> TRANSF | J81: =[4]Performance!H7 -> N/A | K81: =[4]Performance!I7 -> 1 | L81: =[4]Performance!J7 -> 1 | M81: =[4]Performance!K7 -> N/A | N81: =[4]Performance!L7 -> N/A | O81: =[4]Performance!M7 -> N/A | P81: =[4]Performance!N7 -> 1 | Q81: =[4]Performance!O7 -> N/A | R81: =[4]Performance!P7 -> 1
A82: ='[4]Student Data'!M8 -> 342809 | B82: =[4]Reporting!C7 -> Transition to Production | C82: =[4]Reporting!F7 -> Ma. Clarisse Cardeno | D82: {=--(SUM(COUNTIF(B82,{"*nest*","*grad*","*trans*","*1B*","*1C*"}))>0)} -> 1 | E82: =[4]Performance!Q8 -> 1 | F82: =[4]Performance!R8 -> 1 | G82: =[4]Performance!S8 -> 0.88 | H82: =[4]Performance!T8 -> 1 | I82: =[4]Performance!U8 -> 0.9 | J82: =[4]Performance!H8 -> N/A | K82: =[4]Performance!I8 -> 1 | L82: =[4]Performance!J8 -> 1 | M82: =[4]Performance!K8 -> N/A | N82: =[4]Performance!L8 -> N/A | O82: =[4]Performance!M8 -> N/A | P82: =[4]Performance!N8 -> 1 | Q82: =[4]Performance!O8 -> N/A | R82: =[4]Performance!P8 -> 1
A83: ='[4]Student Data'!M9 -> 342803 | B83: =[4]Reporting!C8 -> Resigned-Nesting 1A | C83: =[4]Reporting!F8 -> John Paulo Castillo | D83: {=--(SUM(COUNTIF(B83,{"*nest*","*grad*","*trans*","*1B*","*1C*"}))>0)} -> 1 | E83: =[4]Performance!Q9 -> 1 | F83: =[4]Performance!R9 -> 1 | G83: =[4]Performance!S9 -> 0.94 | H83: =[4]Performance!T9 -> 0.8 | I83: =[4]Performance!U9 -> 1 | J83: =[4]Performance!H9 -> N/A | K83: =[4]Performance!I9 -> 1 | L83: =[4]Performance!J9 -> 1 | M83: =[4]Performance!K9 -> N/A | N83: =[4]Performance!L9 -> N/A | O83: =[4]Performance!M9 -> N/A | P83: =[4]Performance!N9 -> 1 | Q83: =[4]Performance!O9 -> N/A | R83: =[4]Performance!P9 -> 1
A84: ='[4]Student Data'!M10 -> 342794 | B84: =[4]Reporting!C9 -> Transition to Production | C84: =[4]Reporting!F9 -> Cathrina Dizon | D84: {=--(SUM(COUNTIF(B84,{"*nest*","*grad*","*trans*","*1B*","*1C*"}))>0)} -> 1 | E84: =[4]Performance!Q10 -> 1 | F84: =[4]Performance!R10 -> 1 | G84: =[4]Performance!S10 -> 0.88 | H84: =[4]Performance!T10 -> 1 | I84: =[4]Performance!U10 -> 0.83 | J84: =[4]Performance!H10 -> N/A | K84: =[4]Performance!I10 -> 1 | L84: =[4]Performance!J10 -> 1 | M84: =[4]Performance!K10 -> N/A | N84: =[4]Performance!L10 -> N/A | O84: =[4]Performance!M10 -> N/A | P84: =[4]Performance!N10 -> 1 | Q84: =[4]Performance!O10 -> N/A | R84: =[4]Performance!P10 -> 0.94
A85: ='[4]Student Data'!M11 -> 342792 | B85: =[4]Reporting!C10 -> Transition to Production | C85: =[4]Reporting!F10 -> Carmae Rose Fabros | D85: {=--(SUM(COUNTIF(B85,{"*nest*","*grad*","*trans*","*1B*","*1C*"}))>0)} -> 1 | E85: =[4]Performance!Q11 -> 1 | F85: =[4]Performance!R11 -> 1 | G85: =[4]Performance!S11 -> 0.94 | H85: =[4]Performance!T11 -> 0.8 | I85: =[4]Performance!U11 -> 1 | J85: =[4]Performance!H11 -> N/A | K85: =[4]Performance!I11 -> 0.88 | L85: =[4]Performance!J11 -> 1 | M85: =[4]Performance!K11 -> N/A | N85: =[4]Performance!L11 -> N/A | O85: =[4]Performance!M11 -> N/A | P85: =[4]Performance!N11 -> 1 | Q85: =[4]Performance!O11 -> N/A | R85: =[4]Performance!P11 -> 0.82
A86: ='[4]Student Data'!M12 -> 342807 | B86: =[4]Reporting!C11 -> Transition to Production | C86: =[4]Reporting!F11 -> Joyce Jimenez | D86: {=--(SUM(COUNTIF(B86,{"*nest*","*grad*","*trans*","*1B*","*1C*"}))>0)} -> 1 | E86: =[4]Performance!Q12 -> 1 | F86: =[4]Performance!R12 -> 1 | G86: =[4]Performance!S12 -> 0.84 | H86: =[4]Performance!T12 -> 1 | I86: =[4]Performance!U12 -> 0.94 | J86: =[4]Performance!H12 -> N/A | K86: =[4]Performance!I12 -> 1 | L86: =[4]Performance!J12 -> 1 | M86: =[4]Performance!K12 -> N/A | N86: =[4]Performance!L12 -> N/A | O86: =[4]Performance!M12 -> N/A | P86: =[4]Performance!N12 -> 1 | Q86: =[4]Performance!O12 -> N/A | R86: =[4]Performance!P12 -> 0.9
A87: ='[4]Student Data'!M13 -> 342796 | B87: =[4]Reporting!C12 -> Transition to Production | C87: =[4]Reporting!F12 -> Carol Joy Macawili-Gatbonton | D87: {=--(SUM(COUNTIF(B87,{"*nest*","*grad*","*trans*","*1B*","*1C*"}))>0)} -> 1 | E87: =[4]Performance!Q13 -> 1 | F87: =[4]Performance!R13 -> 1 | G87: =[4]Performance!S13 -> 1 | H87: =[4]Performance!T13 -> 1 | I87: =[4]Performance!U13 -> 0.81 | J87: =[4]Performance!H13 -> N/A | K87: =[4]Performance!I13 -> 1 | L87: =[4]Performance!J13 -> 1 | M87: =[4]Performance!K13 -> N/A | N87: =[4]Performance!L13 -> N/A | O87: =[4]Performance!M13 -> N/A | P87: =[4]Performance!N13 -> 1 | Q87: =[4]Performance!O13 -> N/A | R87: =[4]Performance!P13 -> 0.94
A88: ='[4]Student Data'!M14 -> 342801 | B88: =[4]Reporting!C13 -> Transition to Production | C88: =[4]Reporting!F13 -> Janah Rose Medina | D88: {=--(SUM(COUNTIF(B88,{"*nest*","*grad*","*trans*","*1B*","*1C*"}))>0)} -> 1 | E88: =[4]Performance!Q14 -> 1 | F88: =[4]Performance!R14 -> 1 | G88: =[4]Performance!S14 -> 0.82 | H88: =[4]Performance!T14 -> 1 | I88: =[4]Performance!U14 -> 0.88 | J88: =[4]Performance!H14 -> N/A | K88: =[4]Performance!I14 -> 1 | L88: =[4]Performance!J14 -> 1 | M88: =[4]Performance!K14 -> N/A | N88: =[4]Performance!L14 -> N/A | O88: =[4]Performance!M14 -> N/A | P88: =[4]Performance!N14 -> 1 | Q88: =[4]Performance!O14 -> N/A | R88: =[4]Performance!P14 -> 1
...

Sheet Q2
A1: Class Start Date | B1: Trainer Name | D1: Number of Agent Transition to Nesting | E1: Whistleblowing | F1: PCB Compliance Coaching Model | G1: Complaint Management Theory | H1: NTT BPO PCB AML - General | I1: Senior's Fraud | J1: Corporate Policy and Procedure Employee Sign off | K1: NTT BPO CASL | L1: NTT BPO AODA | M1: NTT BPO Health and Safety - Onshore or Offshore version | N1: NTT BPO WHMIS | O1: NTT BPO Violence and Harassment in the Workplace Quiz | P1: NTT BPO Insider Fraud Awareness | Q1: NTT BPO Privacy + Security | R1: NTT BPO Human Rights Code | S1: Notes | T1: Last day in Training
A2: 06.09.2025 | B2: Anabelle Pizon | C2: Irish Ferreras | D2: =SUM(D3:D21) -> 14 | E2: =COUNTIF(E3:E21, ">79%") -> 15 | F2: =COUNTIF(F3:F21, ">79%") -> 15 | G2: =COUNTIF(G3:G21, ">79%") -> 15 | H2: =COUNTIF(H3:H21, ">79%") -> 15 | I2: =COUNTIF(I3:I21, ">79%") -> 15 | J2: =COUNTIF(J3:J21, ">79%") -> 0 | K2: =COUNTIF(K3:K21, ">79%") -> 15 | L2: =COUNTIF(L3:L21, ">79%") -> 15 | ... R2: =COUNTIF(R3:R21, ">79%") -> 15 | T2: ='[10]Class Summary'!$B$6 -> 45833
A3: ='[10]Student Data'!M5 -> 0 | B3: =[10]Reporting!C4 -> Did not Start | C3: =[10]Reporting!F4 -> Ann Christine Felomina Becerro | D3: {=--(SUM(COUNTIF(B3,{"*nest*","*grad*","*trans*","*1B*","*1C*"}))>0)} -> 0 | E3: =[10]Performance!Q5 -> 0 | F3: =[10]Performance!R5 -> 0 | G3: =[10]Performance!S5 -> 0 | H3: =[10]Performance!T5 -> 0 | I3: =[10]Performance!U5 -> 0 | J3: =[10]Performance!H5 -> 0 | K3: =[10]Performance!I5 -> 0 | L3: =[10]Performance!J5 -> 0 | M3: =[10]Performance!K5 -> 0 | N3: =[10]Performance!L5 -> 0 | O3: =[10]Performance!M5 -> 0 | P3: =[10]Performance!N5 -> 0 | Q3: =[10]Performance!O5 -> 0 | R3: =[10]Performance!P5 -> 0
A4: ='[10]Student Data'!M6 -> 344970 | B4: =[10]Reporting!C5 -> Transition to Production | C4: =[10]Reporting!F5 -> Allyza Cabiad | D4: {=--(SUM(COUNTIF(B4,{"*nest*","*grad*","*trans*","*1B*","*1C*"}))>0)} -> 1 | E4: =[10]Performance!Q6 -> 1 | F4: =[10]Performance!R6 -> 1 | G4: =[10]Performance!S6 -> 0.94 | H4: =[10]Performance!T6 -> 1 | I4: =[10]Performance!U6 -> 0.88 | J4: =[10]Performance!H6 -> NTT | K4: =[10]Performance!I6 -> 0.88 | L4: =[10]Performance!J6 -> 1 | M4: =[10]Performance!K6 -> NTT | N4: =[10]Performance!L6 -> NTT | O4: =[10]Performance!M6 -> N/A | P4: =[10]Performance!N6 -> 1 | Q4: =[10]Performance!O6 -> NTT | R4: =[10]Performance!P6 -> 1
A5: ='[10]Student Data'!M7 -> 0 | B5: =[10]Reporting!C6 -> Did not Start | C5: =[10]Reporting!F6 -> Myla May Delos Santos | D5: {=--(SUM(COUNTIF(B5,{"*nest*","*grad*","*trans*","*1B*","*1C*"}))>0)} -> 0 | E5: =[10]Performance!Q7 -> 0 | F5: =[10]Performance!R7 -> 0 | G5: =[10]Performance!S7 -> 0 | H5: =[10]Performance!T7 -> 0 | I5: =[10]Performance!U7 -> 0 | J5: =[10]Performance!H7 -> 0 | K5: =[10]Performance!I7 -> 0 | L5: =[10]Performance!J7 -> 0 | M5: =[10]Performance!K7 -> 0 | N5: =[10]Performance!L7 -> 0 | O5: =[10]Performance!M7 -> 0 | P5: =[10]Performance!N7 -> 0 | Q5: =[10]Performance!O7 -> 0 | R5: =[10]Performance!P7 -> 0
A6: ='[10]Student Data'!M8 -> 0 | B6: =[10]Reporting!C7 -> Did not Start | C6: =[10]Reporting!F7 -> Junmel Estiller | D6: {=--(SUM(COUNTIF(B6,{"*nest*","*grad*","*trans*","*1B*","*1C*"}))>0)} -> 0 | E6: =[10]Performance!Q8 -> 0 | F6: =[10]Performance!R8 -> 0 | G6: =[10]Performance!S8 -> 0 | H6: =[10]Performance!T8 -> 0 | I6: =[10]Performance!U8 -> 0 | J6: =[10]Performance!H8 -> 0 | K6: =[10]Performance!I8 -> 0 | L6: =[10]Performance!J8 -> 0 | M6: =[10]Performance!K8 -> 0 | N6: =[10]Performance!L8 -> 0 | O6: =[10]Performance!M8 -> 0 | P6: =[10]Performance!N8 -> 0 | Q6: =[10]Performance!O8 -> 0 | R6: =[10]Performance!P8 -> 0
A7: ='[10]Student Data'!M9 -> 344969 | B7: =[10]Reporting!C8 -> Resigned Tier 1B | C7: =[10]Reporting!F8 -> Jenifer Jainar | D7: {=--(SUM(COUNTIF(B7,{"*nest*","*grad*","*trans*","*1B*","*1C*"}))>0)} -> 1 | E7: =[10]Performance!Q9 -> 1 | F7: =[10]Performance!R9 -> 1 | G7: =[10]Performance!S9 -> 1 | H7: =[10]Performance!T9 -> 1 | I7: =[10]Performance!U9 -> 1 | J7: =[10]Performance!H9 -> NTT | K7: =[10]Performance!I9 -> 0.88 | L7: =[10]Performance!J9 -> 0.8 | M7: =[10]Performance!K9 -> NTT | N7: =[10]Performance!L9 -> NTT | O7: =[10]Performance!M9 -> N/A | P7: =[10]Performance!N9 -> 1 | Q7: =[10]Performance!O9 -> NTT | R7: =[10]Performance!P9 -> 0.94
A8: ='[10]Student Data'!M10 -> 344955 | B8: =[10]Reporting!C9 -> Transition to Production | C8: =[10]Reporting!F9 -> Guia Ericka Javier | D8: {=--(SUM(COUNTIF(B8,{"*nest*","*grad*","*trans*","*1B*","*1C*"}))>0)} -> 1 | E8: =[10]Performance!Q10 -> 1 | F8: =[10]Performance!R10 -> 1 | G8: =[10]Performance!S10 -> 1 | H8: =[10]Performance!T10 -> 0.8 | I8: =[10]Performance!U10 -> 0.88 | J8: =[10]Performance!H10 -> NTT | K8: =[10]Performance!I10 -> 1 | L8: =[10]Performance!J10 -> 0.8 | M8: =[10]Performance!K10 -> NTT | N8: =[10]Performance!L10 -> NTT | O8: =[10]Performance!M10 -> N/A | P8: =[10]Performance!N10 -> 1 | Q8: =[10]Performance!O10 -> NTT | R8: =[10]Performance!P10 -> 0.94
A9: ='[10]Student Data'!M11 -> 344967 | B9: =[10]Reporting!C10 -> Terminated-Nesting 3 | C9: =[10]Reporting!F10 -> Michelle Jayme | D9: {=--(SUM(COUNTIF(B9,{"*nest*","*grad*","*trans*","*1B*","*1C*"}))>0)} -> 1 | E9: =[10]Performance!Q11 -> 1 | F9: =[10]Performance!R11 -> 1 | G9: =[10]Performance!S11 -> 0.86 | H9: =[10]Performance!T11 -> 1 | I9: =[10]Performance!U11 -> 0.84 | J9: =[10]Performance!H11 -> NTT | K9: =[10]Performance!I11 -> 1 | L9: =[10]Performance!J11 -> 1 | M9: =[10]Performance!K11 -> NTT | N9: =[10]Performance!L11 -> NTT | O9: =[10]Performance!M11 -> N/A | P9: =[10]Performance!N11 -> 1 | Q9: =[10]Performance!O11 -> NTT | R9: =[10]Performance!P11 -> 0.94
A10: ='[10]Student Data'!M12 -> 344960 | B10: =[10]Reporting!C11 -> Resigned Tier 1B | C10: =[10]Reporting!F11 -> Diana Jane Juliano | D10: {=--(SUM(COUNTIF(B10,{"*nest*","*grad*","*trans*","*1B*","*1C*"}))>0)} -> 1 | E10: =[10]Performance!Q12 -> 1 | F10: =[10]Performance!R12 -> 1 | G10: =[10]Performance!S12 -> 0.83 | H10: =[10]Performance!T12 -> 1 | I10: =[10]Performance!U12 -> 0.85 | J10: =[10]Performance!H12 -> NTT | K10: =[10]Performance!I12 -> 0.88 | L10: =[10]Performance!J12 -> 1 | M10: =[10]Performance!K12 -> NTT | N10: =[10]Performance!L12 -> NTT | O10: =[10]Performance!M12 -> N/A | P10: =[10]Performance!N12 -> 1 | Q10: =[10]Performance!O12 -> NTT | R10: =[10]Performance!P12 -> 1
A11: ='[10]Student Data'!M13 -> 344966 | B11: =[10]Reporting!C12 -> Moved/Joining Alternate Class/Program | C11: =[10]Reporting!F12 -> Karen Joy Lambating | D11: {=--(SUM(COUNTIF(B11,{"*nest*","*grad*","*trans*","*1B*","*1C*"}))>0)} -> 0 | E11: =[10]Performance!Q13 -> 1 | F11: =[10]Performance!R13 -> 1 | G11: =[10]Performance!S13 -> 0.93 | H11: =[10]Performance!T13 -> 0.8 | I11: =[10]Performance!U13 -> 0.95 | J11: =[10]Performance!H13 -> NTT | K11: =[10]Performance!I13 -> 0.88 | L11: =[10]Performance!J13 -> 1 | M11: =[10]Performance!K13 -> NTT | N11: =[10]Performance!L13 -> NTT | O11: =[10]Performance!M13 -> N/A | P11: =[10]Performance!N13 -> 1 | Q11: =[10]Performance!O13 -> NTT | R11: =[10]Performance!P13 -> 0.94
A12: ='[10]Student Data'!M14 -> 344957 | B12: =[10]Reporting!C13 -> Transition to Production | C12: =[10]Reporting!F13 -> Jeremie Luchavez | D12: {=--(SUM(COUNTIF(B12,{"*nest*","*grad*","*trans*","*1B*","*1C*"}))>0)} -> 1 | E12: =[10]Performance!Q14 -> 1 | F12: =[10]Performance!R14 -> 1 | G12: =[10]Performance!S14 -> 0.9 | H12: =[10]Performance!T14 -> 1 | I12: =[10]Performance!U14 -> 0.9 | J12: =[10]Performance!H14 -> NTT | K12: =[10]Performance!I14 -> 1 | L12: =[10]Performance!J14 -> 0.8 | M12: =[10]Performance!K14 -> NTT | N12: =[10]Performance!L14 -> NTT | O12: =[10]Performance!M14 -> N/A | P12: =[10]Performance!N14 -> 1 | Q12: =[10]Performance!O14 -> NTT | R12: =[10]Performance!P14 -> 0.97
A13: ='[10]Student Data'!M15 -> 344965 | B13: =[10]Reporting!C14 -> Transition to Production | C13: =[10]Reporting!F14 -> Zechariah (Zach) Magusara | D13: {=--(SUM(COUNTIF(B13,{"*nest*","*grad*","*trans*","*1B*","*1C*"}))>0)} -> 1 | E13: =[10]Performance!Q15 -> 1 | F13: =[10]Performance!R15 -> 1 | G13: =[10]Performance!S15 -> 0.86 | H13: =[10]Performance!T15 -> 0.8 | I13: =[10]Performance!U15 -> 0.84 | J13: =[10]Performance!H15 -> NTT | K13: =[10]Performance!I15 -> 0.88 | L13: =[10]Performance!J15 -> 1 | M13: =[10]Performance!K15 -> NTT | N13: =[10]Performance!L15 -> NTT | O13: =[10]Performance!M15 -> N/A | P13: =[10]Performance!N15 -> 1 | Q13: =[10]Performance!O15 -> NTT | R13: =[10]Performance!P15 -> 0.98
A14: ='[10]Student Data'!M16 -> 344956 | B14: =[10]Reporting!C15 -> Transition to Production | C14: =[10]Reporting!F15 -> Justine Monedero | D14: {=--(SUM(COUNTIF(B14,{"*nest*","*grad*","*trans*","*1B*","*1C*"}))>0)} -> 1 | E14: =[10]Performance!Q16 -> 1 | F14: =[10]Performance!R16 -> 1 | G14: =[10]Performance!S16 -> 0.81 | H14: =[10]Performance!T16 -> 0.8 | I14: =[10]Performance!U16 -> 0.88 | J14: =[10]Performance!H16 -> NTT | K14: =[10]Performance!I16 -> 0.88 | L14: =[10]Performance!J16 -> 1 | M14: =[10]Performance!K16 -> NTT | N14: =[10]Performance!L16 -> NTT | O14: =[10]Performance!M16 -> N/A | P14: =[10]Performance!N16 -> 1 | Q14: =[10]Performance!O16 -> NTT | R14: =[10]Performance!P16 -> 0.82
... A21: ='[10]Student Data'!M23 -> 344961 | B21: =[10]Reporting!C22 -> Resigned-Nesting 1B | C21: =[10]Reporting!F22 -> Janna Rosalia Talabong | D21: {=--(SUM(COUNTIF(B21,{"*nest*","*grad*","*trans*","*1B*","*1C*"}))>0)} -> 1 | E21: =[10]Performance!Q23 -> 1 | F21: =[10]Performance!R23 -> 1 | G21: =[10]Performance!S23 -> 0.92 | H21: =[10]Performance!T23 -> 1 | I21: =[10]Performance!U23 -> 0.9 | J21: =[10]Performance!H23 -> NTT | K21: =[10]Performance!I23 -> 1 | L21: =[10]Performance!J23 -> 1 | M21: =[10]Performance!K23 -> NTT | N21: =[10]Performance!L23 -> NTT | O21: =[10]Performance!M23 -> N/A | P21: =[10]Performance!N23 -> 1 | Q21: =[10]Performance!O23 -> NTT | R21: =[10]Performance!P23 -> 0.82
A22: 06.23.2025 | B22: Kate Saigo | C22: Jeff Janda | D22: =SUM(D23:D35) -> 10 | E22: =COUNTIF(E23:E35, ">79%") -> 11 | F22: =COUNTIF(F23:F35, ">79%") -> 11 | G22: =COUNTIF(G23:G35, ">79%") -> 11 | H22: =COUNTIF(H23:H35, ">79%") -> 11 | I22: =COUNTIF(I23:I35, ">79%") -> 11 | J22: =COUNTIF(J23:J35, ">79%") -> 10 | K22: =COUNTIF(K23:K35, ">79%") -> 11 | L22: =COUNTIF(L23:L35, ">79%") -> 11 | ... R22: =COUNTIF(R23:R35, ">79%") -> 11 | T22: ='[11]Class Summary'!$B$6 -> 45847
A23: ='[12]Student Data'!M5 -> 345520 | B23: =[12]Reporting!C4 -> Resigned Tier 1A | C23: =[11]Reporting!F4 -> Anna Liza Valenzuela | D23: {=--(SUM(COUNTIF(B23,{"*nest*","*grad*","*trans*","*1B*","*1C*"}))>0)} -> 0 | E23: =[12]Performance!P5 -> 0 | F23: =[12]Performance!Q5 -> 0 | G23: =[12]Performance!R5 -> 0 | H23: =[12]Performance!S5 -> 0 | I23: =[12]Performance!T5 -> 0 | J23: =[12]Performance!H5 -> 0 | K23: =[12]Performance!I5 -> 0 | L23: =[12]Performance!J5 -> 0 | M23: =[12]Performance!K5 -> 0 | N23: =[12]Performance!L5 -> 0 | O23: =[12]Performance!M5 -> 0 | P23: =[12]Performance!N5 -> 0 | Q23: =[12]Performance!O5 -> 0 | R23: =[12]Performance!P5 -> 0
A24: ='[12]Student Data'!M6 -> 345568 | B24: =[12]Reporting!C5 -> Transition to Production | C24: =[11]Reporting!F5 -> Arvin Nareto De Leon | D24: {=--(SUM(COUNTIF(B24,{"*nest*","*grad*","*trans*","*1B*","*1C*"}))>0)} -> 1 | E24: =[12]Performance!P6 -> 1 | F24: =[12]Performance!Q6 -> 1 | G24: =[12]Performance!R6 -> 1 | H24: =[12]Performance!S6 -> 0.88 | I24: =[12]Performance!T6 -> 1 | J24: =[12]Performance!H6 -> 1 | K24: =[12]Performance!I6 -> 0.88 | L24: =[12]Performance!J6 -> 1 | M24: =[12]Performance!K6 -> 1 | N24: =[12]Performance!L6 -> 1 | O24: =[12]Performance!M6 -> 1 | P24: =[12]Performance!N6 -> 1 | Q24: =[12]Performance!O6 -> 1 | R24: =[12]Performance!P6 -> 1
A25: ='[12]Student Data'!M7 -> 345526 | B25: =[12]Reporting!C6 -> Transition to Production | C25: =[11]Reporting!F6 -> Asnor Alden | D25: {=--(SUM(COUNTIF(B25,{"*nest*","*grad*","*trans*","*1B*","*1C*"}))>0)} -> 1 | E25: =[12]Performance!P7 -> 1 | F25: =[12]Performance!Q7 -> 1 | G25: =[12]Performance!R7 -> 1 | H25: =[12]Performance!S7 -> 1 | I25: =[12]Performance!T7 -> 1 | J25: =[12]Performance!H7 -> 1 | K25: =[12]Performance!I7 -> 0.88 | L25: =[12]Performance!J7 -> 1 | M25: =[12]Performance!K7 -> 1 | N25: =[12]Performance!L7 -> 1 | O25: =[12]Performance!M7 -> 1 | P25: =[12]Performance!N7 -> 1 | Q25: =[12]Performance!O7 -> 1 | R25: =[12]Performance!P7 -> 1
A26: ='[12]Student Data'!M8 -> 345532 | B26: =[12]Reporting!C7 -> Transition to Production | C26: =[11]Reporting!F7 -> Edilito Nartea Jr. | D26: {=--(SUM(COUNTIF(B26,{"*nest*","*grad*","*trans*","*1B*","*1C*"}))>0)} -> 1 | E26: =[12]Performance!P8 -> 0.82 | F26: =[12]Performance!Q8 -> 1 | G26: =[12]Performance!R8 -> 1 | H26: =[12]Performance!S8 -> 0.88 | I26: =[12]Performance!T8 -> 1 | J26: =[12]Performance!H8 -> 1 | K26: =[12]Performance!I8 -> 0.88 | L26: =[12]Performance!J8 -> 1 | M26: =[12]Performance!K8 -> 1 | N26: =[12]Performance!L8 -> 1 | O26: =[12]Performance!M8 -> 1 | P26: =[12]Performance!N8 -> 1 | Q26: =[12]Performance!O8 -> 1 | R26: =[12]Performance!P8 -> 0.82
A27: ='[12]Student Data'!M9 -> 0 | B27: =[12]Reporting!C8 -> Did not Start | C27: =[11]Reporting!F8 -> Jemwell Morante | D27: {=--(SUM(COUNTIF(B27,{"*nest*","*grad*","*trans*","*1B*","*1C*"}))>0)} -> 0 | E27: =[12]Performance!P9 -> 0 | F27: =[12]Performance!Q9 -> 0 | G27: =[12]Performance!R9 -> 0 | H27: =[12]Performance!S9 -> 0 | I27: =[12]Performance!T9 -> 0 | J27: =[12]Performance!H9 -> 0 | K27: =[12]Performance!I9 -> 0 | L27: =[12]Performance!J9 -> 0 | M27: =[12]Performance!K9 -> 0 | N27: =[12]Performance!L9 -> 0 | O27: =[12]Performance!M9 -> 0 | P27: =[12]Performance!N9 -> 0 | Q27: =[12]Performance!O9 -> 0 | R27: =[12]Performance!P9 -> 0
A28: ='[12]Student Data'!M10 -> 345530 | B28: =[12]Reporting!C9 -> Transition to Production | C28: =[11]Reporting!F9 -> Joros Rian | D28: {=--(SUM(COUNTIF(B28,{"*nest*","*grad*","*trans*","*1B*","*1C*"}))>0)} -> 1 | E28: =[12]Performance!P10 -> 1 | F28: =[12]Performance!Q10 -> 1 | G28: =[12]Performance!R10 -> 1 | H28: =[12]Performance!S10 -> 0.96 | I28: =[12]Performance!T10 -> 0.8 | J28: =[12]Performance!H10 -> 1 | K28: =[12]Performance!I10 -> 0.88 | L28: =[12]Performance!J10 -> 0.8 | M28: =[12]Performance!K10 -> 1 | N28: =[12]Performance!L10 -> 1 | O28: =[12]Performance!M10 -> 1 | P28: =[12]Performance!N10 -> 1 | Q28: =[12]Performance!O10 -> 1 | R28: =[12]Performance!P10 -> 1
A29: ='[12]Student Data'!M11 -> 345556 | B29: =[12]Reporting!C10 -> Resigned Tier 1A | C29: =[11]Reporting!F10 -> Myla May Delos Santos | D29: {=--(SUM(COUNTIF(B29,{"*nest*","*grad*","*trans*","*1B*","*1C*"}))>0)} -> 0 | E29: =[12]Performance!P11 -> 1 | F29: =[12]Performance!Q11 -> 1 | G29: =[12]Performance!R11 -> 1 | H29: =[12]Performance!S11 -> 0.86 | I29: =[12]Performance!T11 -> 1 | J29: =[12]Performance!H11 -> 0 | K29: =[12]Performance!I11 -> 0.88 | L29: =[12]Performance!J11 -> 0.8 | M29: =[12]Performance!K11 -> 0 | N29: =[12]Performance!L11 -> 0 | O29: =[12]Performance!M11 -> 0 | P29: =[12]Performance!N11 -> 1 | Q29: =[12]Performance!O11 -> 1 | R29: =[12]Performance!P11 -> 1
A30: ='[12]Student Data'!M12 -> 345540 | B30: =[12]Reporting!C11 -> Transition to Production | C30: =[11]Reporting!F11 -> Nicole Sto. Domingo | D30: {=--(SUM(COUNTIF(B30,{"*nest*","*grad*","*trans*","*1B*","*1C*"}))>0)} -> 1 | E30: =[12]Performance!P12 -> 0.82 | F30: =[12]Performance!Q12 -> 1 | G30: =[12]Performance!R12 -> 1 | H30: =[12]Performance!S12 -> 0.94 | I30: =[12]Performance!T12 -> 1 | J30: =[12]Performance!H12 -> 1 | K30: =[12]Performance!I12 -> 1 | L30: =[12]Performance!J12 -> 1 | M30: =[12]Performance!K12 -> 1 | N30: =[12]Performance!L12 -> 1 | O30: =[12]Performance!M12 -> 1 | P30: =[12]Performance!N12 -> 1 | Q30: =[12]Performance!O12 -> 1 | R30: =[12]Performance!P12 -> 0.82
A31: ='[12]Student Data'!M13 -> 345542 | B31: =[12]Reporting!C12 -> Transition to Production | C31: =[11]Reporting!F12 -> Rey Jumar Ty | D31: {=--(SUM(COUNTIF(B31,{"*nest*","*grad*","*trans*","*1B*","*1C*"}))>0)} -> 1 | E31: =[12]Performance!P13 -> 0.88 | F31: =[12]Performance!Q13 -> 1 | G31: =[12]Performance!R13 -> 1 | H31: =[12]Performance!S13 -> 0.84 | I31: =[12]Performance!T13 -> 1 | J31: =[12]Performance!H13 -> 1 | K31: =[12]Performance!I13 -> 0.88 | L31: =[12]Performance!J13 -> 1 | M31: =[12]Performance!K13 -> 1 | N31: =[12]Performance!L13 -> 1 | O31: =[12]Performance!M13 -> 1 | P31: =[12]Performance!N13 -> 1 | Q31: =[12]Performance!O13 -> 1 | R31: =[12]Performance!P13 -> 0.88
A32: ='[12]Student Data'!M14 -> 345548 | B32: =[12]Reporting!C13 -> Transition to Production | C32: =[11]Reporting!F13 -> Russile Jepollo | D32: {=--(SUM(COUNTIF(B32,{"*nest*","*grad*","*trans*","*1B*","*1C*"}))>0)} -> 1 | E32: =[12]Performance!P14 -> 0.82 | F32: =[12]Performance!Q14 -> 1 | G32: =[12]Performance!R14 -> 1 | H32: =[12]Performance!S14 -> 0.94 | I32: =[12]Performance!T14 -> 1 | J32: =[12]Performance!H14 -> 1 | K32: =[12]Performance!I14 -> 0.88 | L32: =[12]Performance!J14 -> 1 | M32: =[12]Performance!K14 -> 1 | N32: =[12]Performance!L14 -> 1 | O32: =[12]Performance!M14 -> 1 | P32: =[12]Performance!N14 -> 1 | Q32: =[12]Performance!O14 -> 1 | R32: =[12]Performance!P14 -> 0.82
A33: ='[12]Student Data'!M15 -> 345554 | B33: =[12]Reporting!C14 -> Transition to Production | C33: =[11]Reporting!F14 -> Valerie Perez | D33: {=--(SUM(COUNTIF(B33,{"*nest*","*grad*","*trans*","*1B*","*1C*"}))>0)} -> 1 | E33: =[12]Performance!P15 -> 1 | F33: =[12]Performance!Q15 -> 1 | G33: =[12]Performance!R15 -> 1 | H33: =[12]Performance!S15 -> 1 | I33: =[12]Performance!T15 -> 0.8 | J33: =[12]Performance!H15 -> 1 | K33: =[12]Performance!I15 -> 0.88 | L33: =[12]Performance!J15 -> 1 | M33: =[12]Performance!K15 -> 1 | N33: =[12]Performance!L15 -> 1 | O33: =[12]Performance!M15 -> 1 | P33: =[12]Performance!N15 -> 1 | Q33: =[12]Performance!O15 -> 1 | R33: =[12]Performance!P15 -> 1
A34: ='[12]Student Data'!M16 -> 345543 | B34: =[12]Reporting!C15 -> Transition to Production | C34: =[11]Reporting!F15 -> Victor Fabro | D34: {=--(SUM(COUNTIF(B34,{"*nest*","*grad*","*trans*","*1B*","*1C*"}))>0)} -> 1 | E34: =[12]Performance!P16 -> 1 | F34: =[12]Performance!Q16 -> 1 | G34: =[12]Performance!R16 -> 1 | H34: =[12]Performance!S16 -> 0.82 | I34: =[12]Performance!T16 -> 1 | J34: =[12]Performance!H16 -> 1 | K34: =[12]Performance!I16 -> 1 | L34: =[12]Performance!J16 -> 1 | M34: =[12]Performance!K16 -> 1 | N34: =[12]Performance!L16 -> 1 | O34: =[12]Performance!M16 -> 1 | P34: =[12]Performance!N16 -> 1 | Q34: =[12]Performance!O16 -> 1 | R34: =[12]Performance!P16 -> 1
