Workbook
Name List_SalesAgents: #REF!
Name List_SalesCategories: #REF!
Name List_SalesPhases: #REF!
Name List_SalesRegions: #REF!
Name Starting_Month: #REF!

Sheet KPIs Dashboard
B2: Company Confidential
B3: Juanita's Training Team
B4: Key Performance Indicators (KPIs)
B5: Goal | C5: 80% or above | D5: 80% or above | E5: 1 | F5: 90% or above | G5: 80% or above | H5: 35% or below | I5: 80% or above | L5: =90*0.3 -> 27 | M5: =80*0.7 -> 56 | N5: =SUM(L5:M5) -> 83
B6: Weighting | C6: 0.1 | D6: 0.25 | E6: 0.15 | F6: 0.25 | H6: 0.25 | I6: N/A
B7: Team Average | C7: =AVERAGE(C9,C10,C11,C12,C13,C15,C16,C17,C19,C20,C21,C22,C23,C24,C25,C26,C27,C28,C29,C30,C32,C33,C34,C35,C36,C37) -> 0.81767019 | D7: =AVERAGE(D10,D11,D12,D13,D17,D20,D21,D22,D23:D28,D30,D33,D34,D36,D37,D39) -> 0.93659372 | E7: =AVERAGE(E11,E12,E13,E17,E20,E19,E22,E23,E24,E25,E26,E27,E28,E29,E33,E36,E39) -> 0.8456596 | F7: =AVERAGE(F10,F11,F12,F13,F16,F17,F19,F20,F21,F22,F23,F24,F25,F26,F27,F28,F29,F30,F33,F34,F35,F36,F37,F39) -> 0.87055151 | G7: =AVERAGE(G11,G12,G13,G16,G17,G19,G20,G21,G22,G23,G24,G25,G26,G27,G28,G29,G30,G33,G34,G36,G37,G39) -> 0.74682106 | H7: =AVERAGE(H10,H11,H12,H13,H16,H17,H19,H20,H21,H22,H23,H24,H25,H26,H27,H28,H29,H30,H33,H34,H36,H37,H39) -> 0.19277799 | I7: =AVERAGE(I10,I12,I13,I14,I16,I17,I19,I20,I21,I22,I23,I24,I25,I27,I31,I33,I34,I39) -> 0.83921971 | L7: =AVERAGE(L9:L35) -> 0.25697977 | M7: =AVERAGE(M9:M35) -> 0.51476611 | N7: =SUM(L7:M7) -> 0.77174587
B8: Name | C8: Productivity - YTD | D8: Training Satisfaction (Survey Results | E8: Compliance | F8: Knowledge Retention in Class | G8: Knowledge Retention Nesting | H8: New Hire Attrition | I8: Observation Scores
B9: Angeline Rubrico | C9: ='[1]Dashboard YTD'!$K$2 -> 0.63891349 | D9: =GETPIVOTDATA("Sum of Sum of Responses",'Survey Raw Data'!$A$1,"Select the name of your primary trainer for this course.","Angeline Rubrico")/GETPIVOTDATA("Sum of Sum of User Score",'Survey Raw Data'!$A$1,"Select the name of your primary trainer for this course.","Angeline Rubrico") -> #REF! | E9: =GETPIVOTDATA("Sum of Total",'Compliance Pivot Table'!$A$3,"Trainer Name","Angeline Rubrico")/GETPIVOTDATA("Sum of Number of Agent Transition to Nesting",'Compliance Pivot Table'!$A$3,"Trainer Name","Angeline Rubrico") -> #REF! | F9: =GETPIVOTDATA("Average of Test Avg",'Pivot Tables'!$A$1,"Trainer 1","Angeline Rubrico") -> #REF! | G9: =GETPIVOTDATA("Average of QA Avg",'Pivot Tables'!$A$1,"Trainer 1","Angeline Rubrico") -> #REF! | H9: =GETPIVOTDATA("Average of Attrition less Terms",'Pivot Tables'!$A$1,"Trainer 1","Angeline Rubrico") -> #REF! | I9: ='Observation Metrics'!G2 -> #DIV/0!
B10: Anita Bliss-Dias | C10: ='[2]Dashboard YTD'!$K$2 -> 0.83211974 | D10: =GETPIVOTDATA("Sum of Sum of Responses",'Survey Raw Data'!$A$1,"Select the name of your primary trainer for this course.","Anita Bliss-Dias")/GETPIVOTDATA("Sum of Sum of User Score",'Survey Raw Data'!$A$1,"Select the name of your primary trainer for this course.","Anita Bliss-Dias") -> 0.9122807 | E10: =GETPIVOTDATA("Sum of Total",'Compliance Pivot Table'!$A$3,"Trainer Name","Anita Bliss-Dias")/GETPIVOTDATA("Sum of Number of Agent Transition to Nesting",'Compliance Pivot Table'!$A$3,"Trainer Name","Anita Bliss-Dias") -> #REF! | F10: =GETPIVOTDATA("Average of Test Avg",'Pivot Tables'!$A$1,"Trainer 1","Anita Bliss-Dias") -> 0.82474155 | G10: =GETPIVOTDATA("Average of QA Avg",'Pivot Tables'!$A$1,"Trainer 1","Anita Bliss-Dias") -> 0.73566468 | H10: =GETPIVOTDATA("Average of Attrition less Terms",'Pivot Tables'!$A$1,"Trainer 1","Anita Bliss-Dias") -> 0.066993464 | I10: ='Observation Metrics'!G3 -> 0.83809524 | L10: =Table_ForecastInput[[#This Row],[Knowledge Retention in Class]]*0.3 -> 0.24742246 | M10: =Table_ForecastInput[[#This Row],[Knowledge Retention Nesting]]*0.7 -> 0.51496528 | N10: =SUM(L10:M10) -> 0.76238774
B11: Bibi Alli | C11: ='[3]Dashboard YTD'!$K$2 -> 0.87170317 | D11: =GETPIVOTDATA("Sum of Sum of Responses",'Survey Raw Data'!$A$1,"Select the name of your primary trainer for this course.","Bibi Alli")/GETPIVOTDATA("Sum of Sum of User Score",'Survey Raw Data'!$A$1,"Select the name of your primary trainer for this course.","Bibi Alli") -> 1 | E11: =GETPIVOTDATA("Sum of Total",'Compliance Pivot Table'!$A$3,"Trainer Name","Bib Alli")/GETPIVOTDATA("Sum of Number of Agent Transition to Nesting",'Compliance Pivot Table'!$A$3,"Trainer Name","Bib Alli") -> 1 | F11: =GETPIVOTDATA("Average of Test Avg",'Pivot Tables'!$A$1,"Trainer 1","Bibi Alli") -> 0.84286333 | G11: =GETPIVOTDATA("Average of QA Avg",'Pivot Tables'!$A$1,"Trainer 1","Bibi Alli") -> 0.88375 | H11: =GETPIVOTDATA("Average of Attrition less Terms",'Pivot Tables'!$A$1,"Trainer 1","Bibi Alli") -> 0.42857143 | I11: ='Observation Metrics'!G4 -> LOA | L11: =Table_ForecastInput[[#This Row],[Knowledge Retention in Class]]*0.3 -> 0.252859 | M11: =Table_ForecastInput[[#This Row],[Knowledge Retention Nesting]]*0.7 -> 0.618625 | N11: =SUM(L11:M11) -> 0.871484
B12: John David Lim | C12: ='[4]Dashboard YTD'!$K$2 -> 0.85570844 | D12: =GETPIVOTDATA("Sum of Sum of Responses",'Survey Raw Data'!$A$1,"Select the name of your primary trainer for this course.","Dave Lim")/GETPIVOTDATA("Sum of Sum of User Score",'Survey Raw Data'!$A$1,"Select the name of your primary trainer for this course.","Dave Lim") -> 0.94949495 | E12: =GETPIVOTDATA("Sum of Total",'Compliance Pivot Table'!$A$3,"Trainer Name","Dave Lim")/GETPIVOTDATA("Sum of Number of Agent Transition to Nesting",'Compliance Pivot Table'!$A$3,"Trainer Name","Dave Lim") -> 0.725 | F12: =GETPIVOTDATA("Average of Test Avg",'Pivot Tables'!$A$1,"Trainer 1","John David Lim") -> 0.89444749 | G12: =GETPIVOTDATA("Average of QA Avg",'Pivot Tables'!$A$1,"Trainer 1","John David Lim") -> 0.73599562 | H12: =GETPIVOTDATA("Average of Attrition less Terms",'Pivot Tables'!$A$1,"Trainer 1","John David Lim") -> 0.13770053 | I12: ='Observation Metrics'!G5 -> 0.8172043 | L12: =Table_ForecastInput[[#This Row],[Knowledge Retention in Class]]*0.3 -> 0.26833425 | M12: =Table_ForecastInput[[#This Row],[Knowledge Retention Nesting]]*0.7 -> 0.51519694 | N12: =SUM(L12:M12) -> 0.78353118
B13: Gilisa Roberts | C13: ='[5]Dashboard YTD'!$K$2 -> 0.86813781 | D13: =GETPIVOTDATA("Sum of Sum of Responses",'Survey Raw Data'!$A$1,"Select the name of your primary trainer for this course.","Gilisa Roberts")/GETPIVOTDATA("Sum of Sum of User Score",'Survey Raw Data'!$A$1,"Select the name of your primary trainer for this course.","Gilisa Roberts") -> 0.94444444 | E13: =GETPIVOTDATA("Sum of Total",'Compliance Pivot Table'!$A$3,"Trainer Name","Gilisa Roberts")/GETPIVOTDATA("Sum of Number of Agent Transition to Nesting",'Compliance Pivot Table'!$A$3,"Trainer Name","Gilisa Roberts") -> 0.96296296 | F13: =GETPIVOTDATA("Average of Test Avg",'Pivot Tables'!$A$1,"Trainer 1","Gilisa Roberts") -> 0.87081337 | G13: =GETPIVOTDATA("Average of QA Avg",'Pivot Tables'!$A$1,"Trainer 1","Gilisa Roberts") -> 0.71984702 | H13: =GETPIVOTDATA("Average of Attrition less Terms",'Pivot Tables'!$A$1,"Trainer 1","Gilisa Roberts") -> 0.13920455 | I13: ='Observation Metrics'!G6 -> 0.99411765 | L13: =Table_ForecastInput[[#This Row],[Knowledge Retention in Class]]*0.3 -> 0.26124401 | M13: =Table_ForecastInput[[#This Row],[Knowledge Retention Nesting]]*0.7 -> 0.50389292 | N13: =SUM(L13:M13) -> 0.76513693
B14: Irish Ferreras | C14: ='[6]Dashboard YTD'!$K$2 -> 0 | D14: N/A | E14: =GETPIVOTDATA("Sum of Total",'Compliance Pivot Table'!$A$3,"Trainer Name","Irish Ferreras")/GETPIVOTDATA("Sum of Number of Agent Transition to Nesting",'Compliance Pivot Table'!$A$3,"Trainer Name","Irish Ferreras") -> #REF! | F14: =GETPIVOTDATA("Average of Test Avg",'Pivot Tables'!$A$1,"Trainer 1","Irish Ferreras") -> #REF! | G14: =GETPIVOTDATA("Average of QA Avg",'Pivot Tables'!$A$1,"Trainer 1","Irish Ferreras") -> #REF! | H14: =GETPIVOTDATA("Average of Attrition less Terms",'Pivot Tables'!$A$1,"Trainer 1","Irish Ferreras") -> #REF! | I14: ='Observation Metrics'!G10 -> 0.90977778
B15: Jean Luzada | C15: ='[7]Dashboard YTD'!$K$2 -> 0.44642857 | D15: =GETPIVOTDATA("Sum of Sum of Responses",'Survey Raw Data'!$A$1,"Select the name of your primary trainer for this course.","Jean Luzada")/GETPIVOTDATA("Sum of Sum of User Score",'Survey Raw Data'!$A$1,"Select the name of your primary trainer for this course.","Jean Luzada") -> #REF! | E15: =GETPIVOTDATA("Sum of Total",'Compliance Pivot Table'!$A$3,"Trainer Name","Jean Luzada")/GETPIVOTDATA("Sum of Number of Agent Transition to Nesting",'Compliance Pivot Table'!$A$3,"Trainer Name","Jean Luzada") -> #REF! | F15: =GETPIVOTDATA("Average of Test Avg",'Pivot Tables'!$A$1,"Trainer 1","Jean Luzada") -> #REF! | G15: =GETPIVOTDATA("Average of QA Avg",'Pivot Tables'!$A$1,"Trainer 1","Jean Luzada") -> #REF! | H15: =GETPIVOTDATA("Average of Attrition less Terms",'Pivot Tables'!$A$1,"Trainer 1","Jean Luzada") -> #REF! | I15: ='Observation Metrics'!G8 -> 0.78431373
B16: Jill Hirtle | C16: ='[8]Dashboard YTD'!$K$2 -> 0.82647989 | D16: =GETPIVOTDATA("Sum of Sum of Responses",'Survey Raw Data'!$A$1,"Select the name of your primary trainer for this course.","Jill Hirtle")/GETPIVOTDATA("Sum of Sum of User Score",'Survey Raw Data'!$A$1,"Select the name of your primary trainer for this course.","Jill Hirtle") -> #REF! | E16: =GETPIVOTDATA("Sum of Total",'Compliance Pivot Table'!$A$3,"Trainer Name","Jill Hirtle")/GETPIVOTDATA("Sum of Number of Agent Transition to Nesting",'Compliance Pivot Table'!$A$3,"Trainer Name","Jill Hirtle") -> #REF! | F16: =GETPIVOTDATA("Average of Test Avg",'Pivot Tables'!$A$1,"Trainer 1","Jill Hirtle") -> 0.87632757 | G16: =GETPIVOTDATA("Average of QA Avg",'Pivot Tables'!$A$1,"Trainer 1","Jill Hirtle") -> 0.67614277 | H16: =GETPIVOTDATA("Average of Attrition less Terms",'Pivot Tables'!$A$1,"Trainer 1","Jill Hirtle") -> 0.2381685 | I16: ='Observation Metrics'!G9 -> 0.90666667 | L16: =Table_ForecastInput[[#This Row],[Knowledge Retention in Class]]*0.3 -> 0.26289827 | M16: =Table_ForecastInput[[#This Row],[Knowledge Retention Nesting]]*0.7 -> 0.47329994 | N16: =SUM(L16:M16) -> 0.73619821
B17: Jordan Saulnier | C17: ='[9]Dashboard YTD'!$K$2 -> 0.8626551 | D17: =GETPIVOTDATA("Sum of Sum of Responses",'Survey Raw Data'!$A$1,"Select the name of your primary trainer for this course.","Jordan Saulnier")/GETPIVOTDATA("Sum of Sum of User Score",'Survey Raw Data'!$A$1,"Select the name of your primary trainer for this course.","Jordan Saulnier") -> 0.96666667 | E17: =GETPIVOTDATA("Sum of Total",'Compliance Pivot Table'!$A$3,"Trainer Name","Jordan Saulnier")/GETPIVOTDATA("Sum of Number of Agent Transition to Nesting",'Compliance Pivot Table'!$A$3,"Trainer Name","Jordan Saulnier") -> 0.74074074 | F17: =GETPIVOTDATA("Average of Test Avg",'Pivot Tables'!$A$1,"Trainer 1","Jordan Saulnier") -> 0.86541463 | G17: =GETPIVOTDATA("Average of QA Avg",'Pivot Tables'!$A$1,"Trainer 1","Jordan Saulnier") -> 0.69153075 | H17: =GETPIVOTDATA("Average of Attrition less Terms",'Pivot Tables'!$A$1,"Trainer 1","Jordan Saulnier") -> 0.1979798 | I17: ='Observation Metrics'!G10 -> 0.90977778 | L17: =Table_ForecastInput[[#This Row],[Knowledge Retention in Class]]*0.3 -> 0.25962439 | M17: =Table_ForecastInput[[#This Row],[Knowledge Retention Nesting]]*0.7 -> 0.48407153 | N17: =SUM(L17:M17) -> 0.74369592
B18: Kaitlind Allard | C18: NLE | D18: NLE | E18: NLE | F18: NLE | G18: NLE | H18: NLE | I18: NLE
B19: Catherine Saigo | C19: ='[10]Dashboard YTD'!$K$2 -> 0.77869467 | D19: =GETPIVOTDATA("Sum of Sum of Responses",'Survey Raw Data'!$A$1,"Select the name of your primary trainer for this course.","Kate Saigo")/GETPIVOTDATA("Sum of Sum of User Score",'Survey Raw Data'!$A$1,"Select the name of your primary trainer for this course.","Kate Saigo") -> 1 | E19: =GETPIVOTDATA("Sum of Total",'Compliance Pivot Table'!$A$3,"Trainer Name","Catherine Saigo2")/GETPIVOTDATA("Sum of Number of Agent Transition to Nesting",'Compliance Pivot Table'!$A$3,"Trainer Name","Catherine Saigo2") -> 1 | F19: =GETPIVOTDATA("Average of Test Avg",'Pivot Tables'!$A$1,"Trainer 1","Catherine Saigo2") -> 0.86468229 | G19: =GETPIVOTDATA("Average of QA Avg",'Pivot Tables'!$A$1,"Trainer 1","Catherine Saigo2") -> 0.78391193 | H19: =GETPIVOTDATA("Average of Attrition Class",'Pivot Tables'!$A$1,"Trainer 1","Catherine Saigo2") -> 0.045454545 | I19: ='Observation Metrics'!G12 -> 0.89263016 | L19: =Table_ForecastInput[[#This Row],[Knowledge Retention in Class]]*0.3 -> 0.25940469 | M19: =Table_ForecastInput[[#This Row],[Knowledge Retention Nesting]]*0.7 -> 0.54873835 | N19: =SUM(L19:M19) -> 0.80814304
B20: Kristi Stead | C20: ='[11]Dashboard YTD'!$K$2 -> 0.72350049 | D20: =GETPIVOTDATA("Sum of Sum of Responses",'Survey Raw Data'!$A$1,"Select the name of your primary trainer for this course.","Kristi Stead")/GETPIVOTDATA("Sum of Sum of User Score",'Survey Raw Data'!$A$1,"Select the name of your primary trainer for this course.","Kristi Stead") -> 0.88888889 | E20: =GETPIVOTDATA("Sum of Total",'Compliance Pivot Table'!$A$3,"Trainer Name","Kristi Stead")/GETPIVOTDATA("Sum of Number of Agent Transition to Nesting",'Compliance Pivot Table'!$A$3,"Trainer Name","Kristi Stead") -> 1 | F20: =GETPIVOTDATA("Average of Test Avg",'Pivot Tables'!$A$1,"Trainer 1","Kristi Stead") -> 0.87280076 | G20: =GETPIVOTDATA("Average of QA Avg",'Pivot Tables'!$A$1,"Trainer 1","Kristi Stead") -> 0.70694369 | H20: =GETPIVOTDATA("Average of Attrition Class",'Pivot Tables'!$A$1,"Trainer 1","Kristi Stead") -> 0.088235294 | I20: ='Observation Metrics'!G12 -> 0.89263016 | L20: =Table_ForecastInput[[#This Row],[Knowledge Retention in Class]]*0.3 -> 0.26184023 | M20: =Table_ForecastInput[[#This Row],[Knowledge Retention Nesting]]*0.7 -> 0.49486058 | N20: =SUM(L20,M20) -> 0.75670081
B21: Maida Musse | C21: ='[12]Dashboard YTD'!$K$2 -> 0.74576271 | D21: =GETPIVOTDATA("Sum of Sum of Responses",'Survey Raw Data'!$A$1,"Select the name of your primary trainer for this course.","Maida Musse")/GETPIVOTDATA("Sum of Sum of User Score",'Survey Raw Data'!$A$1,"Select the name of your primary trainer for this course.","Maida Musse") -> 0.92735043 | E21: =GETPIVOTDATA("Sum of Total",'Compliance Pivot Table'!$A$3,"Trainer Name","Maida Musse")/GETPIVOTDATA("Sum of Number of Agent Transition to Nesting",'Compliance Pivot Table'!$A$3,"Trainer Name","Maida Musse") -> 1 | F21: =GETPIVOTDATA("Average of Test Avg",'Pivot Tables'!$A$1,"Trainer 1","Maida Musse") -> 0.95911111 | G21: =GETPIVOTDATA("Average of QA Avg",'Pivot Tables'!$A$1,"Trainer 1","Maida Musse") -> 0.75688355 | H21: =GETPIVOTDATA("Average of Attrition Class",'Pivot Tables'!$A$1,"Trainer 1","Maida Musse") -> 0.050649351 | I21: ='Observation Metrics'!G13 -> 0.8091954 | L21: =Table_ForecastInput[[#This Row],[Knowledge Retention in Class]]*0.3 -> 0.28773333 | M21: =Table_ForecastInput[[#This Row],[Knowledge Retention Nesting]]*0.7 -> 0.52981848 | N21: =SUM(L21,M21) -> 0.81755182
B22: Maria Skubiszewska | C22: ='[13]Dashboard YTD'!$K$2 -> 0.82201838 | D22: =GETPIVOTDATA("Sum of Sum of Responses",'Survey Raw Data'!$A$1,"Select the name of your primary trainer for this course.","MariaSkubiszewska")/GETPIVOTDATA("Sum of Sum of User Score",'Survey Raw Data'!$A$1,"Select the name of your primary trainer for this course.","MariaSkubiszewska") -> 1 | E22: =GETPIVOTDATA("Sum of Total",'Compliance Pivot Table'!$A$3,"Trainer Name","Maria Skubiszewska")/GETPIVOTDATA("Sum of Number of Agent Transition to Nesting",'Compliance Pivot Table'!$A$3,"Trainer Name","Maria Skubiszewska") -> 1.2 | F22: =GETPIVOTDATA("Average of Test Avg",'Pivot Tables'!$A$1,"Trainer 1","Maria Skubiszewska") -> 0.89197718 | G22: =GETPIVOTDATA("Average of QA Avg",'Pivot Tables'!$A$1,"Trainer 1","Maria Skubiszewska") -> 0.78706063 | H22: =GETPIVOTDATA("Average of Attrition less Terms",'Pivot Tables'!$A$1,"Trainer 1","Maria Skubiszewska") -> 0.057142857 | I22: ='Observation Metrics'!G14 -> 0.8 | L22: =Table_ForecastInput[[#This Row],[Knowledge Retention in Class]]*0.3 -> 0.26759315 | M22: =Table_ForecastInput[[#This Row],[Knowledge Retention Nesting]]*0.7 -> 0.55094244 | N22: =SUM(L22,M22) -> 0.81853559
B23: Nancy Price | C23: ='[14]Dashboard YTD'!$K$2 -> 0.7779798 | D23: =GETPIVOTDATA("Sum of Sum of Responses",'Survey Raw Data'!$A$1,"Select the name of your primary trainer for this course.","Nancy Price")/GETPIVOTDATA("Sum of Sum of User Score",'Survey Raw Data'!$A$1,"Select the name of your primary trainer for this course.","Nancy Price") -> 0.95833333 | E23: =GETPIVOTDATA("Sum of Total",'Compliance Pivot Table'!$A$3,"Trainer Name","Nancy Price")/GETPIVOTDATA("Sum of Number of Agent Transition to Nesting",'Compliance Pivot Table'!$A$3,"Trainer Name","Nancy Price") -> 1 | F23: =GETPIVOTDATA("Average of Test Avg",'Pivot Tables'!$A$1,"Trainer 1","Nancy Price") -> 0.8482637 | G23: =GETPIVOTDATA("Average of QA Avg",'Pivot Tables'!$A$1,"Trainer 1","Nancy Price") -> 0.62308383 | H23: =GETPIVOTDATA("Average of Attrition less Terms",'Pivot Tables'!$A$1,"Trainer 1","Nancy Price") -> 0.12261905 | I23: ='Observation Metrics'!G15 -> 1.0320186 | L23: =Table_ForecastInput[[#This Row],[Knowledge Retention in Class]]*0.3 -> 0.25447911 | M23: =Table_ForecastInput[[#This Row],[Knowledge Retention Nesting]]*0.7 -> 0.43615868 | N23: =SUM(L23,M23) -> 0.69063779
B24: Rowena Lasala | C24: ='[15]Dashboard YTD'!$K$2 -> 0.86669352 | D24: =GETPIVOTDATA("Sum of Sum of Responses",'Survey Raw Data'!$A$1,"Select the name of your primary trainer for this course.","Rowena Lasala")/GETPIVOTDATA("Sum of Sum of User Score",'Survey Raw Data'!$A$1,"Select the name of your primary trainer for this course.","Rowena Lasala") -> 0.97916667 | E24: =GETPIVOTDATA("Sum of Total",'Compliance Pivot Table'!$A$3,"Trainer Name","Rowena Lasala")/GETPIVOTDATA("Sum of Number of Agent Transition to Nesting",'Compliance Pivot Table'!$A$3,"Trainer Name","Rowena Lasala") -> 1.0344828 | F24: =GETPIVOTDATA("Average of Test Avg",'Pivot Tables'!$A$1,"Trainer 1","Rowena Lasala") -> 0.88733156 | G24: =GETPIVOTDATA("Average of QA Avg",'Pivot Tables'!$A$1,"Trainer 1","Rowena Lasala") -> 0.78619345 | H24: =GETPIVOTDATA("Average of Attrition Class",'Pivot Tables'!$A$1,"Trainer 1","Rowena Lasala") -> 0.23080808 | I24: ='Observation Metrics'!G16 -> 0.8045977 | L24: =Table_ForecastInput[[#This Row],[Knowledge Retention in Class]]*0.3 -> 0.26619947 | M24: =Table_ForecastInput[[#This Row],[Knowledge Retention Nesting]]*0.7 -> 0.55033542 | N24: =SUM(L24,M24) -> 0.81653489
B25: Ruschel Bartolome | C25: ='[16]Dashboard YTD'!$K$2 -> 0.88045523 | D25: =GETPIVOTDATA("Sum of Sum of Responses",'Survey Raw Data'!$A$1,"Select the name of your primary trainer for this course.","Ruschel Bartolome")/GETPIVOTDATA("Sum of Sum of User Score",'Survey Raw Data'!$A$1,"Select the name of your primary trainer for this course.","Ruschel Bartolome") -> 0.91025641 | E25: =GETPIVOTDATA("Sum of Total",'Compliance Pivot Table'!$A$3,"Trainer Name","Ruschel Bartolome")/GETPIVOTDATA("Sum of Number of Agent Transition to Nesting",'Compliance Pivot Table'!$A$3,"Trainer Name","Ruschel Bartolome") -> 0.55555556 | F25: =GETPIVOTDATA("Average of Test Avg",'Pivot Tables'!$A$1,"Trainer 1","Ruschel Bartolome") -> 0.92652525 | G25: =GETPIVOTDATA("Average of QA Avg",'Pivot Tables'!$A$1,"Trainer 1","Ruschel Bartolome") -> 0.84057368 | H25: =GETPIVOTDATA("Average of Attrition Class",'Pivot Tables'!$A$1,"Trainer 1","Ruschel Bartolome") -> 0.21590909 | I25: ='Observation Metrics'!G17 -> 0.7655914 | L25: =Table_ForecastInput[[#This Row],[Knowledge Retention in Class]]*0.3 -> 0.27795758 | M25: =Table_ForecastInput[[#This Row],[Knowledge Retention Nesting]]*0.7 -> 0.58840157 | N25: =SUM(L25,M25) -> 0.86635915
B26: Scott McDonald | C26: ='[17]Dashboard YTD'!$K$2 -> 0.80860534 | D26: =GETPIVOTDATA("Sum of Sum of Responses",'Survey Raw Data'!$A$1,"Select the name of your primary trainer for this course.","Scott McDonald")/GETPIVOTDATA("Sum of Sum of User Score",'Survey Raw Data'!$A$1,"Select the name of your primary trainer for this course.","Scott McDonald") -> 0.90666667 | E26: =GETPIVOTDATA("Sum of Total",'Compliance Pivot Table'!$A$3,"Trainer Name","Scott McDonald")/GETPIVOTDATA("Sum of Number of Agent Transition to Nesting",'Compliance Pivot Table'!$A$3,"Trainer Name","Scott McDonald") -> 0.72413793 | F26: =GETPIVOTDATA("Average of Test Avg",'Pivot Tables'!$A$1,"Trainer 1","Scott McDonald") -> 0.82765257 | G26: =GETPIVOTDATA("Average of QA Avg",'Pivot Tables'!$A$1,"Trainer 1","Siya Nugent") -> 0.46779004 | H26: =GETPIVOTDATA("Average of Attrition Class",'Pivot Tables'!$A$1,"Trainer 1","Scott McDonald") -> 0.25786713 | I26: ='Observation Metrics'!G19 -> NEW LOB | L26: =Table_ForecastInput[[#This Row],[Knowledge Retention in Class]]*0.3 -> 0.24829577 | M26: =Table_ForecastInput[[#This Row],[Knowledge Retention Nesting]]*0.7 -> 0.32745303 | N26: =SUM(L26,M26) -> 0.5757488
B27: Siya Nugent | C27: ='[18]Dashboard YTD'!$K$2 -> 0.8015104 | D27: =GETPIVOTDATA("Sum of Sum of Responses",'Survey Raw Data'!$A$1,"Select the name of your primary trainer for this course.","Siya Nugent")/GETPIVOTDATA("Sum of Sum of User Score",'Survey Raw Data'!$A$1,"Select the name of your primary trainer for this course.","Siya Nugent") -> 0.88888889 | E27: =GETPIVOTDATA("Sum of Total",'Compliance Pivot Table'!$A$3,"Trainer Name","Siya Nugent")/GETPIVOTDATA("Sum of Number of Agent Transition to Nesting",'Compliance Pivot Table'!$A$3,"Trainer Name","Siya Nugent") -> 0.3 | F27: =GETPIVOTDATA("Average of Test Avg",'Pivot Tables'!$A$1,"Trainer 1","Siya Nugent") -> 0.87585762 | G27: =GETPIVOTDATA("Average of QA Avg",'Pivot Tables'!$A$1,"Trainer 1","Scott McDonald") -> 0.78231209 | H27: =GETPIVOTDATA("Average of Attrition less Terms",'Pivot Tables'!$A$1,"Trainer 1","Siya Nugent") -> 0.21928897 | I27: ='Observation Metrics'!G20 -> 0.80860215 | L27: =Table_ForecastInput[[#This Row],[Knowledge Retention in Class]]*0.3 -> 0.26275729 | M27: =Table_ForecastInput[[#This Row],[Knowledge Retention Nesting]]*0.7 -> 0.54761847 | N27: =SUM(L27,M27) -> 0.81037575
B28: Sneha Menda | C28: ='[19]Dashboard YTD'!$K$2 -> 0.86747788 | D28: =GETPIVOTDATA("Sum of Sum of Responses",'Survey Raw Data'!$A$1,"Select the name of your primary trainer for this course.","Sneha Menda")/GETPIVOTDATA("Sum of Sum of User Score",'Survey Raw Data'!$A$1,"Select the name of your primary trainer for this course.","Sneha Menda") -> 0.94202899 | E28: =GETPIVOTDATA("Sum of Total",'Compliance Pivot Table'!$A$3,"Trainer Name","Sneha Menda")/GETPIVOTDATA("Sum of Number of Agent Transition to Nesting",'Compliance Pivot Table'!$A$3,"Trainer Name","Sneha Menda") -> 1 | F28: =GETPIVOTDATA("Average of Test Avg",'Pivot Tables'!$A$1,"Trainer 1","Sneha Menda") -> 0.88942604 | G28: =GETPIVOTDATA("Average of QA Avg",'Pivot Tables'!$A$1,"Trainer 1","Sneha Menda") -> 0.70198954 | H28: =GETPIVOTDATA("Average of Attrition less Terms",'Pivot Tables'!$A$1,"Trainer 1","Sneha Menda") -> 0.16282051 | I28: ='Observation Metrics'!G21 -> LOA | L28: =Table_ForecastInput[[#This Row],[Knowledge Retention in Class]]*0.3 -> 0.26682781 | M28: =Table_ForecastInput[[#This Row],[Knowledge Retention Nesting]]*0.7 -> 0.49139268 | N28: =SUM(L28,M28) -> 0.75822049
B29: Stephany Chavez | C29: ='[20]Dashboard YTD'!$K$2 -> 0.99096249 | D29: =GETPIVOTDATA("Sum of Sum of Responses",'Survey Raw Data'!$A$1,"Select the name of your primary trainer for this course.","Stephany Chavez")/GETPIVOTDATA("Sum of Sum of User Score",'Survey Raw Data'!$A$1,"Select the name of your primary trainer for this course.","Stephany Chavez") -> 0.875 | E29: =GETPIVOTDATA("Sum of Total",'Compliance Pivot Table'!$A$3,"Trainer Name","Stephany Chavez")/GETPIVOTDATA("Sum of Number of Agent Transition to Nesting",'Compliance Pivot Table'!$A$3,"Trainer Name","Stephany Chavez") -> 0 | F29: =GETPIVOTDATA("Average of Test Avg",'Pivot Tables'!$A$1,"Trainer 1","Stephany Chavez") -> 0.87625 | G29: =GETPIVOTDATA("Average of QA Avg",'Pivot Tables'!$A$1,"Trainer 1","Stephany Chavez") -> 0.81518939 | H29: =GETPIVOTDATA("Average of Attrition less Terms",'Pivot Tables'!$A$1,"Trainer 1","Stephany Chavez") -> 0.10456731 | I29: ='Observation Metrics'!G22 -> #DIV/0! | L29: =Table_ForecastInput[[#This Row],[Knowledge Retention in Class]]*0.3 -> 0.262875 | M29: =Table_ForecastInput[[#This Row],[Knowledge Retention Nesting]]*0.7 -> 0.57063258 | N29: =SUM(L29,M29) -> 0.83350758
B30: Tom Tse | C30: ='[21]Dashboard YTD'!$K$2 -> 0.90588235 | D30: =GETPIVOTDATA("Sum of Sum of Responses",'Survey Raw Data'!$A$1,"Select the name of your primary trainer for this course.","Tom Tse")/GETPIVOTDATA("Sum of Sum of User Score",'Survey Raw Data'!$A$1,"Select the name of your primary trainer for this course.","Tom Tse") -> 1 | E30: =GETPIVOTDATA("Sum of Total",'Compliance Pivot Table'!$A$3,"Trainer Name","Tom Tse")/GETPIVOTDATA("Sum of Number of Agent Transition to Nesting",'Compliance Pivot Table'!$A$3,"Trainer Name","Tom Tse") -> 1 | F30: =GETPIVOTDATA("Average of Test Avg",'Pivot Tables'!$A$1,"Trainer 1","Tom Tse") -> 0.81995413 | G30: =GETPIVOTDATA("Average of QA Avg",'Pivot Tables'!$A$1,"Trainer 1","Tom Tse") -> 0.69426124 | H30: =GETPIVOTDATA("Average of Attrition less Terms",'Pivot Tables'!$A$1,"Trainer 1","Tom Tse") -> 0.16452991 | I30: ='Observation Metrics'!G23 -> NEW LOB | L30: =Table_ForecastInput[[#This Row],[Knowledge Retention in Class]]*0.3 -> 0.24598624 | M30: =Table_ForecastInput[[#This Row],[Knowledge Retention Nesting]]*0.7 -> 0.48598287 | N30: =SUM(L30,M30) -> 0.73196911
B31: Vera Hibaya | C31: ='[22]Dashboard YTD'!$K$2 -> 0 | D31: =GETPIVOTDATA("Sum of Sum of Responses",'Survey Raw Data'!$A$1,"Select the name of your primary trainer for this course.","Vera Hibaya")/GETPIVOTDATA("Sum of Sum of User Score",'Survey Raw Data'!$A$1,"Select the name of your primary trainer for this course.","Vera Hibaya") -> #REF! | E31: =GETPIVOTDATA("Sum of Total",'Compliance Pivot Table'!$A$3,"Trainer Name","Vera Hibaya")/GETPIVOTDATA("Sum of Number of Agent Transition to Nesting",'Compliance Pivot Table'!$A$3,"Trainer Name","Vera Hibaya") -> #REF! | F31: =GETPIVOTDATA("Average of Test Avg",'Pivot Tables'!$A$1,"Trainer 1","Vera Hibaya") -> #REF! | G31: =GETPIVOTDATA("Average of QA Avg",'Pivot Tables'!$A$1,"Trainer 1","Vera Hibaya") -> #REF! | H31: =GETPIVOTDATA("Average of Attrition less Terms",'Pivot Tables'!$A$1,"Trainer 1","Vera Hibaya") -> #REF! | I31: ='Observation Metrics'!G27 -> 0.70123457
B32: Vhea De Fiesta | C32: ='[23]Dashboard YTD'!$K$2 -> 0.72151899 | D32: =GETPIVOTDATA("Sum of Sum of Responses",'Survey Raw Data'!$A$1,"Select the name of your primary trainer for this course.","Vhea De Fiesta")/GETPIVOTDATA("Sum of Sum of User Score",'Survey Raw Data'!$A$1,"Select the name of your primary trainer for this course.","Vhea De Fiesta") -> #REF! | E32: =GETPIVOTDATA("Sum of Total",'Compliance Pivot Table'!$A$3,"Trainer Name","Vhea De Fiesta")/GETPIVOTDATA("Sum of Number of Agent Transition to Nesting",'Compliance Pivot Table'!$A$3,"Trainer Name","Vhea De Fiesta") -> #REF! | F32: =GETPIVOTDATA("Average of Test Avg",'Pivot Tables'!$A$1,"Trainer 1","Vhea De Fiesta") -> #REF! | G32: =GETPIVOTDATA("Average of QA Avg",'Pivot Tables'!$A$1,"Trainer 1","Vhea De Fiesta") -> #REF! | H32: =GETPIVOTDATA("Average of Attrition less Terms",'Pivot Tables'!$A$1,"Trainer 1","Vhea De Fiest") -> #REF! | I32: ='Observation Metrics'!G28 -> #DIV/0!
B33: Viena Lacena | C33: ='[24]Dashboard YTD'!$K$2 -> 0.96386555 | D33: =GETPIVOTDATA("Sum of Sum of Responses",'Survey Raw Data'!$A$1,"Select the name of your primary trainer for this course.","Viena Lacena")/GETPIVOTDATA("Sum of Sum of User Score",'Survey Raw Data'!$A$1,"Select the name of your primary trainer for this course.","Viena Lacena") -> 0.9 | E33: =GETPIVOTDATA("Sum of Total",'Compliance Pivot Table'!$A$3,"Trainer Name","Viena Lacena")/GETPIVOTDATA("Sum of Number of Agent Transition to Nesting",'Compliance Pivot Table'!$A$3,"Trainer Name","Viena Lacena") -> 1 | F33: =GETPIVOTDATA("Average of Test Avg",'Pivot Tables'!$A$1,"Trainer 1","Viena Lacena") -> 0.4469697 | G33: =GETPIVOTDATA("Average of QA Avg",'Pivot Tables'!$A$1,"Trainer 1","Viena Lacena") -> 0.78309893 | H33: =GETPIVOTDATA("Average of Attrition less Terms",'Pivot Tables'!$A$1,"Trainer 1","Viena Lacena") -> 0.13636364 | I33: ='Observation Metrics'!G26 -> 0.8172043 | L33: =Table_ForecastInput[[#This Row],[Knowledge Retention in Class]]*0.3 -> 0.13409091 | M33: =Table_ForecastInput[[#This Row],[Knowledge Retention Nesting]]*0.7 -> 0.54816925 | N33: =SUM(L33,M33) -> 0.68226016
B34: Ankit Vishnoi | C34: ='[25]Dashboard YTD'!$K$2 -> 0.9017567 | D34: =GETPIVOTDATA("Sum of Sum of Responses",'Survey Raw Data'!$A$1,"Select the name of your primary trainer for this course.","Ankit Vishnoi")/GETPIVOTDATA("Sum of Sum of User Score",'Survey Raw Data'!$A$1,"Select the name of your primary trainer for this course.","Ankit Vishnoi") -> 0.90740741 | E34: =GETPIVOTDATA("Sum of Total",'Compliance Pivot Table'!$A$3,"Trainer Name","Ankit Vishnoi")/GETPIVOTDATA("Sum of Number of Agent Transition to Nesting",'Compliance Pivot Table'!$A$3,"Trainer Name","Ankit Vishnoi") -> #REF! | F34: =GETPIVOTDATA("Average of Test Avg",'Pivot Tables'!$A$1,"Trainer 1","Ankit Vishnoi") -> 0.97057466 | G34: =GETPIVOTDATA("Average of QA Avg",'Pivot Tables'!$A$1,"Trainer 1","Ankit Vishnoi") -> 0.86337153 | H34: =GETPIVOTDATA("Average of Attrition less Terms",'Pivot Tables'!$A$1,"Trainer 1","Ankit Vishnoi") -> 0.5 | I34: ='Observation Metrics'!G27 -> 0.70123457
B35: Chantelle Thomas | C35: ='[26]Dashboard YTD'!$K$2 -> 0.76388889 | E35: =GETPIVOTDATA("Sum of Total",'Compliance Pivot Table'!$A$3,"Trainer Name","Chantelle Thomas")/GETPIVOTDATA("Sum of Number of Agent Transition to Nesting",'Compliance Pivot Table'!$A$3,"Trainer Name","Chantelle Thomas") -> #REF! | F35: =GETPIVOTDATA("Average of Test Avg",'Pivot Tables'!$A$1,"Trainer 1","Ankit Vishnoi") -> 0.97057466 | G35: =GETPIVOTDATA("Average of QA Avg",'Pivot Tables'!$A$1,"Trainer 1","Chantelle Thomas") -> #REF! | H35: =GETPIVOTDATA("Average of Attrition less Terms",'Pivot Tables'!$A$1,"Trainer 1","Chantelle Thomas") -> #REF! | I35: ='Observation Metrics'!G28 -> #DIV/0! | L35: =Table_ForecastInput[[#This Row],[Knowledge Retention in Class]]*0.3 -> 0.2911724 | N35: =SUM(L35,M35) -> 0.2911724
B36: Hira Umair | C36: ='[27]Dashboard YTD'!$K$2 -> 0.82905808 | D36: =GETPIVOTDATA("Sum of Sum of Responses",'Survey Raw Data'!$A$1,"Select the name of your primary trainer for this course.","Hira Umair")/GETPIVOTDATA("Sum of Sum of User Score",'Survey Raw Data'!$A$1,"Select the name of your primary trainer for this course.","Hira Umair") -> 0.95634921 | E36: =GETPIVOTDATA("Sum of Total",'Compliance Pivot Table'!$A$3,"Trainer Name","Hira Umair")/GETPIVOTDATA("Sum of Number of Agent Transition to Nesting",'Compliance Pivot Table'!$A$3,"Trainer Name","Hira Umair") -> 1 | F36: =GETPIVOTDATA("Average of Test Avg",'Pivot Tables'!$A$1,"Trainer 1","Hira Umair") -> 0.88304929 | G36: =GETPIVOTDATA("Average of QA Avg",'Pivot Tables'!$A$1,"Trainer 1","Hira Umair") -> 0.72890377 | H36: =GETPIVOTDATA("Average of Attrition less Terms",'Pivot Tables'!$A$1,"Trainer 1","Hira Umair") -> 0.17457542 | I36: ='Observation Metrics'!G29 -> #DIV/0!
B37: Mahalakshmi Ramasubramanian | C37: ='[28]Dashboard YTD'!$K$2 -> 0.90764728 | D37: =GETPIVOTDATA("Sum of Sum of Responses",'Survey Raw Data'!$A$1,"Select the name of your primary trainer for this course.","Mahalakshmi Ramasubramanian")/GETPIVOTDATA("Sum of Sum of User Score",'Survey Raw Data'!$A$1,"Select the name of your primary trainer for this course.","Mahalakshmi Ramasubramanian") -> 0.96031746 | E37: =GETPIVOTDATA("Sum of Total",'Compliance Pivot Table'!$A$3,"Trainer Name","Mahalakshmi Ramasubramanian")/GETPIVOTDATA("Sum of Number of Agent Transition to Nesting",'Compliance Pivot Table'!$A$3,"Trainer Name","Mahalakshmi Ramasubramanian") -> #REF! | F37: =GETPIVOTDATA("Average of Test Avg",'Pivot Tables'!$A$1,"Trainer 1","Mahalakshmi Ramasubramanian") -> 0.9543509 | G37: =GETPIVOTDATA("Average of QA Avg",'Pivot Tables'!$A$1,"Trainer 1","Mahalakshmi Ramasubramanian") -> 0.80365253 | H37: =GETPIVOTDATA("Average of Attrition less Terms",'Pivot Tables'!$A$1,"Trainer 1","Mahalakshmi Ramasubramanian") -> 0.5 | I37: ='Observation Metrics'!G30 -> #DIV/0!
B38: Rachel Daury | C38: NLE | D38: NLE | E38: NLE | F38: NLE | G38: NLE | H38: NLE | I38: ='Observation Metrics'!G31 -> NLE
B39: Debbie Anthony | C39: ='[29]Dashboard YTD'!$K$2 -> 0.918 | D39: =GETPIVOTDATA("Sum of Sum of Responses",'Survey Raw Data'!$A$1,"Select the name of your primary trainer for this course.","Debbie Anthony")/GETPIVOTDATA("Sum of Sum of User Score",'Survey Raw Data'!$A$1,"Select the name of your primary trainer for this course.","Debbie Anthony") -> 0.83333333 | E39: =GETPIVOTDATA("Sum of Total",'Compliance Pivot Table'!$A$3,"Trainer Name","Debbie Anthony")/GETPIVOTDATA("Sum of Number of Agent Transition to Nesting",'Compliance Pivot Table'!$A$3,"Trainer Name","Debbie Anthony") -> 1.1333333 | F39: =GETPIVOTDATA("Average of Test Avg",'Pivot Tables'!$A$1,"Trainer 1","Debbie Anthony") -> 0.95327698 | G39: =GETPIVOTDATA("Average of QA Avg",'Pivot Tables'!$A$1,"Trainer 1","Debbie Anthony") -> 0.79757722 | H39: =GETPIVOTDATA("Average of Attrition less Terms",'Pivot Tables'!$A$1,"Trainer 1","Debbie Anthony") -> 0.19444444 | I39: ='Observation Metrics'!G32 -> 0.70537634

Sheet Scores - Raw Data
A1: PR Number | B1: Class Type | C1: Trainer 1 | D1: Trainer 2 | E1: Test Avg | F1: QA Avg | G1: Attrition Class | H1: Attrition Nesting | I1: Attrition less Terms | J1: Grad Rate
A2: 20 | B2: Tier 1 | C2: Sneha Menda | E2: =[30]Performance!$AI$45 -> 0.87778176 | F2: ='[30]PCB Nesting QA'!$L$44 -> 0.5296875 | G2: ='[30]Class Summary'!$E$21 -> 0.11764706 | H2: ='[30]Class Summary'!$I$21 -> 0.2 | I2: ='[31]GradRates - Tier 1'!$S$138 -> 0.30769231
A3: 20 | B3: Tier 1 | C3: Jill Hirtle | E3: =[30]Performance!$AI$45 -> 0.87778176 | F3: ='[30]PCB Nesting QA'!$L$44 -> 0.5296875 | G3: ='[30]Class Summary'!$E$21 -> 0.11764706 | H3: ='[30]Class Summary'!$I$21 -> 0.2 | I3: ='[31]GradRates - Tier 1'!$S$138 -> 0.30769231
A4: 21 | B4: FSA | C4: Maida Musse | F4: ='[32]PCB Nesting QA'!$H24 -> 0.75333333 | G4: ='[32]Class Summary'!$E$21 -> 0 | H4: ='[32]Class Summary'!$I$21 -> 0 | I4: ='[31]GradRates - RSA'!$S$122 -> 0 | J4: ='[31]GradRates - RSA'!$L$25 -> 0.9375
A5: 21 | B5: FSA | C5: Anita Bliss-Dias | F5: ='[32]PCB Nesting QA'!$H24 -> 0.75333333 | G5: ='[32]Class Summary'!$E$21 -> 0 | H5: ='[32]Class Summary'!$I$21 -> 0 | I5: ='[31]GradRates - RSA'!$S$122 -> 0 | J5: ='[31]GradRates - RSA'!$L$25 -> 0.9375
A6: 22 | B6: Tier 1 | C6: John David Lim | E6: =[33]Performance!$AI$45 -> 0.83844769 | F6: ='[33]PCB Nesting QA'!$L$44 -> 0.50940972 | G6: ='[33]Class Summary'!$E$21 -> 0.375 | H6: ='[33]Class Summary'!$I$21 -> 0.2 | I6: ='[31]GradRates - Tier 1'!$S$139 -> 0.2
A7: 22 | B7: Tier 1 | C7: Jill Hirtle | E7: =[33]Performance!$AI$45 -> 0.83844769 | F7: ='[33]PCB Nesting QA'!$L$44 -> 0.50940972 | G7: ='[33]Class Summary'!$E$21 -> 0.375 | H7: ='[33]Class Summary'!$I$21 -> 0.2 | I7: ='[31]GradRates - Tier 1'!$S$139 -> 0.2
A8: 23 | B8: Tier 1 | C8: Hira Umair | E8: =[34]Performance!$AJ$21 -> 0.87275934 | F8: ='[34]PCB Nesting QA'!$L$20 -> 0.55972222 | G8: ='[34]Class Summary'!$E$21 -> 0.26666667 | H8: ='[34]Class Summary'!$I$21 -> 0.27272727 | I8: ='[31]GradRates - Tier 1'!$S$140 -> 0.18181818
A9: 24 | B9: Tier 1 | C9: Kristi Stead | E9: =[35]Performance!$AH$45 -> 0.82997652 | F9: ='[35]PCB Nesting QA'!$L$44 -> 0.55560897 | G9: ='[35]Class Summary'!$E$21 -> 0.17647059 | H9: ='[35]Class Summary'!$I$21 -> 0.28571429 | I9: ='[31]GradRates - Tier 1'!$S$142 -> 0.23529412
A10: 25 | B10: Tier 1 | C10: Rowena Lasala | E10: =[36]Performance!$AI$45 -> 0.87936071 | F10: ='[36]PCB Nesting QA'!$L$44 -> 0.775 | G10: ='[36]Class Summary'!$E$21 -> 0.25 | H10: ='[36]Class Summary'!$I$21 -> 0 | I10: ='[31]GradRates - Tier 1'!$S$144 -> 0.26666667
A11: 26 | B11: Tier 1 | C11: Gilisa Roberts | E11: =[37]Performance!$AI$45 -> 0.76853632 | F11: ='[37]PCB Nesting QA'!$L$44 -> 0.635 | G11: ='[37]Class Summary'!$E$21 -> 0.2 | H11: ='[37]Class Summary'!$I$21 -> 0 | I11: ='[31]GradRates - Tier 1'!$S$145 -> 0.25
A12: 26 | B12: Tier 1 | C12: Jordan Saulnier | E12: =[37]Performance!$AI$45 -> 0.76853632 | F12: ='[37]PCB Nesting QA'!$L$44 -> 0.635 | G12: ='[37]Class Summary'!$E$21 -> 0.2 | H12: ='[37]Class Summary'!$I$21 -> 0 | I12: ='[31]GradRates - Tier 1'!$S$145 -> 0.25
A13: 27 | B13: Tier 1 | C13: Nancy Price | E13: =[38]Performance!$AJ$35 -> 0.82438717 | F13: ='[38]PCB Nesting QA'!$L$34 -> 0.51654762 | G13: ='[38]Class Summary'!$E$21 -> 0.46666667 | H13: ='[38]Class Summary'!$I$21 -> 0.125 | I13: ='[31]GradRates - Tier 1'!$S$143 -> 0.25
A14: 27 | B14: Tier 1 | C14: Tom Tse | E14: =[38]Performance!$AJ$35 -> 0.82438717 | F14: ='[38]PCB Nesting QA'!$L$34 -> 0.51654762 | G14: ='[38]Class Summary'!$E$21 -> 0.46666667 | H14: ='[38]Class Summary'!$I$21 -> 0.125 | I14: ='[31]GradRates - Tier 1'!$S$143 -> 0.25
A15: 28 | B15: Tier 2 SLP | C15: Mahalakshmi Ramasubramanian | E15: =[39]Performance!$AI$45 -> 0.96857143 | F15: ='[39]PCB Nesting QA'!$L$44 -> 0.76446429 | G15: ='[39]Class Summary'!$E$21 -> 0 | H15: ='[39]Class Summary'!$I$21 -> 0 | I15: ='[31]GradRates - Tier 2'!$S$15 -> 0 | J15: ='[31]GradRates - Tier 2'!$M$15 -> 0.93333333
A16: 29 | B16: Tier 1 | C16: John David Lim | E16: =[40]Performance!$AI$45 -> 0.82474155 | F16: ='[40]PCB Nesting QA'!$L$44 -> 0.73791667 | G16: ='[40]Class Summary'!$E$21 -> 0 | H16: ='[40]Class Summary'!$I$21 -> 0.6 | I16: ='[31]GradRates - Tier 1'!$S$146 -> 0.23529412
A17: 29 | B17: Tier 1 | C17: Anita Bliss-Dias | E17: =[40]Performance!$AI$45 -> 0.82474155 | F17: ='[40]PCB Nesting QA'!$L$44 -> 0.73791667 | G17: ='[40]Class Summary'!$E$21 -> 0 | H17: ='[40]Class Summary'!$I$21 -> 0.6 | I17: ='[31]GradRates - Tier 1'!$S$146 -> 0.23529412
A18: 30 | B18: Tier 1 | C18: Bibi Alli | E18: =[41]Performance!$AI$45 -> 0.84286333 | F18: ='[41]PCB Nesting QA'!$L$44 -> 0.88375 | G18: ='[41]Class Summary'!$E$21 -> 0.5 | H18: ='[41]Class Summary'!$I$21 -> 0 | I18: ='[31]GradRates - Tier 1'!$S$147 -> 0.42857143
A19: 30 | B19: Tier 1 | C19: Scott McDonald | E19: =[41]Performance!$AI$45 -> 0.84286333 | F19: ='[41]PCB Nesting QA'!$L$44 -> 0.88375 | G19: ='[41]Class Summary'!$E$21 -> 0.5 | H19: ='[41]Class Summary'!$I$21 -> 0 | I19: ='[31]GradRates - Tier 1'!$S$147 -> 0.42857143
A20: 31 | B20: Tier 1 | C20: Sneha Menda | E20: =[42]Performance!$AH$45 -> 0.90324619 | F20: ='[42]PCB Nesting QA'!$L$44 -> 0.82381944 | G20: ='[42]Class Summary'!$E$21 -> 0.2 | H20: ='[42]Class Summary'!$I$21 -> 0.125 | I20: ='[31]GradRates - Tier 1'!$S$149 -> 0.076923077
A21: 31 | B21: Tier 1 | C21: Tom Tse | E21: =[42]Performance!$AH$45 -> 0.90324619 | F21: ='[42]PCB Nesting QA'!$L$44 -> 0.82381944 | G21: ='[42]Class Summary'!$E$21 -> 0.2 | H21: ='[42]Class Summary'!$I$21 -> 0.125 | I21: ='[31]GradRates - Tier 1'!$S$149 -> 0.076923077
A22: 32 | B22: Tier 1 | C22: Nancy Price | E22: =[43]Performance!$AI$45 -> 0.83741964 | F22: ='[43]PCB Nesting QA'!$L$44 -> 0.71550926 | G22: ='[43]Class Summary'!$E$21 -> 0.61538462 | H22: ='[43]Class Summary'!$I$21 -> 0.4 | I22: ='[31]GradRates - Tier 1'!$S$150 -> 0.071428571
A23: 32 | B23: Tier 1 | C23: Maria Skubiszewska | E23: =[43]Performance!$AI$45 -> 0.83741964 | F23: ='[43]PCB Nesting QA'!$L$44 -> 0.71550926 | G23: ='[43]Class Summary'!$E$21 -> 0.61538462 | H23: ='[43]Class Summary'!$I$21 -> 0.4 | I23: ='[31]GradRates - Tier 1'!$S$150 -> 0.071428571
A24: 33 | B24: Tier 2 SLP | C24: Ankit Vishnoi | E24: ='[44]Perform Tier 2'!$T$35 -> 0.96549411 | F24: ='[44]PCB Nesting QA'!$L$44 -> 0.75841667 | G24: ='[44]Class Summary'!$E$21 -> 0 | H24: ='[44]Class Summary'!$I$21 -> 0 | I24: ='[31]GradRates - Tier 2'!$S$16 -> 0 | J24: ='[31]GradRates - Tier 2'!$M$16 -> 1
A25: 34 | B25: Tier 1 | C25: Hira Umair | E25: =[45]Performance!$AI$45 -> 0.92079875 | F25: ='[45]PCB Nesting QA'!$L$44 -> 0.75026786 | G25: ='[45]Class Summary'!$E$21 -> 0.27272727 | H25: ='[45]Class Summary'!$I$21 -> 0.25 | I25: ='[31]GradRates - Tier 1'!$S$151 -> 0.28571429
A26: 34 | B26: Tier 1 | C26: Jill Hirtle | E26: =[45]Performance!$AI$45 -> 0.92079875 | F26: ='[45]PCB Nesting QA'!$L$44 -> 0.75026786 | G26: ='[45]Class Summary'!$E$21 -> 0.27272727 | H26: ='[45]Class Summary'!$I$21 -> 0.25 | I26: ='[31]GradRates - Tier 1'!$S$151 -> 0.28571429
A27: 35 | B27: Tier 1 | C27: Rowena Lasala | E27: =[46]Performance!$AH$45 -> 0.87546524 | F27: ='[46]PCB Nesting QA'!$L$44 -> 0.70857143 | G27: ='[46]Class Summary'!$E$21 -> 0.27777778 | H27: ='[46]Class Summary'!$I$21 -> 0 | I27: ='[31]GradRates - Tier 1'!$S$152 -> 0.2173913
A28: 35 | B28: Tier 1 | C28: Siya Nugent | E28: =[46]Performance!$AH$45 -> 0.87546524 | F28: ='[46]PCB Nesting QA'!$L$44 -> 0.70857143 | G28: ='[46]Class Summary'!$E$21 -> 0.27777778 | H28: ='[46]Class Summary'!$I$21 -> 0 | I28: ='[31]GradRates - Tier 1'!$S$152 -> 0.2173913
A29: 36 | B29: Tier 1 | C29: Jordan Saulnier | E29: =[47]Performance!$AH$45 -> 0.90997644 | F29: ='[47]PCB Nesting QA'!$L$44 -> 0.63458333 | G29: ='[47]Class Summary'!$E$21 -> 0.5 | H29: ='[47]Class Summary'!$I$21 -> 0 | I29: ='[31]GradRates - Tier 1'!$S$154 -> 0.125
A30: 36 | B30: Tier 1 | C30: Gilisa Roberts | E30: =[47]Performance!$AH$45 -> 0.90997644 | F30: ='[47]PCB Nesting QA'!$L$44 -> 0.63458333 | G30: ='[47]Class Summary'!$E$21 -> 0.5 | H30: ='[47]Class Summary'!$I$21 -> 0 | I30: ='[31]GradRates - Tier 1'!$S$154 -> 0.125
A31: 37 | B31: Tier 1 | C31: Nancy Price | E31: =[48]Performance!$AH$45 -> 0.8595852 | F31: ='[48]PCB Nesting QA'!$L$44 -> 0.53839744 | G31: ='[46]Class Summary'!$E$21 -> 0.27777778 | H31: ='[48]Class Summary'!$I$21 -> 0 | I31: ='[31]GradRates - Tier 1'!$S$155 -> 0
A32: 38 | B32: DSA | C32: Maida Musse | F32: ='[49]PCB Nesting QA'!$L$44 -> 0.61633333 | G32: ='[49]Class Summary'!$E$21 -> 0 | H32: ='[49]Class Summary'!$I$21 -> 0 | I32: =G32+H32 -> 0
A33: 38 | B33: DSA | C33: Anita Bliss-Dias | F33: ='[49]PCB Nesting QA'!$L$44 -> 0.61633333 | G33: ='[49]Class Summary'!$E$21 -> 0 | H33: ='[49]Class Summary'!$I$21 -> 0 | I33: =G33+H33 -> 0
A34: 39 | B34: Tier 1 | C34: Scott McDonald | E34: =[50]Performance!$AH$45 -> 0.73222903 | F34: ='[50]PCB Nesting QA'!$L$44 -> 0.74241667 | G34: ='[50]Class Summary'!$E$21 -> 0.076923077 | H34: ='[50]Class Summary'!$I$21 -> 0 | I34: ='[31]GradRates - Tier 1'!$S$156 -> 0.16666667
A35: 39 | B35: Tier 1 | C35: Tom Tse | E35: =[50]Performance!$AH$45 -> 0.73222903 | F35: ='[50]PCB Nesting QA'!$L$44 -> 0.74241667 | G35: ='[50]Class Summary'!$E$21 -> 0.076923077 | H35: ='[50]Class Summary'!$I$21 -> 0 | I35: ='[31]GradRates - Tier 1'!$S$156 -> 0.16666667
A36: 40 | B36: Tier 1 | C36: Sneha Menda | E36: =[51]Performance!$AH$45 -> 0.90267619 | F36: ='[51]PCB Nesting QA'!$L$44 -> 0.64242424 | G36: ='[51]Class Summary'!$E$21 -> 0.25 | H36: ='[51]Class Summary'!$I$21 -> 0.25 | I36: ='[31]GradRates - Tier 1'!$S$161 -> 0.26666667
A37: 41 | B37: Tier 1 | C37: Hira Umair | E37: =[52]Performance!$AH$21 -> 0.91580778 | F37: ='[52]PCB Nesting QA'!$L$20 -> 0.8078125 | G37: ='[52]Class Summary'!$E$21 -> 0.2 | H37: ='[52]Class Summary'!$I$21 -> 0.25 | I37: ='[31]GradRates - Tier 1'!$S$162 -> 0
A38: 41 | B38: Tier 1 | C38: Mahalakshmi Ramasubramanian | E38: =[52]Performance!$AH$21 -> 0.91580778 | F38: ='[52]PCB Nesting QA'!$L$20 -> 0.8078125 | G38: ='[52]Class Summary'!$E$21 -> 0.2 | H38: ='[52]Class Summary'!$I$21 -> 0.25 | I38: ='[31]GradRates - Tier 1'!$S$162 -> 0
A39: 42 | B39: Tier 1 | C39: John David Lim | E39: =[53]Performance!$AH$45 -> 0.89147083 | F39: ='[53]PCB Nesting QA'!$L$44 -> 0.7075 | G39: ='[53]Class Summary'!$E$21 -> 0.22222222 | H39: ='[53]Class Summary'!$I$21 -> 0.14285714 | I39: ='[31]GradRates - Tier 1'!$S$163 -> 0.13333333
A40: 42 | B40: Tier 1 | C40: Jordan Saulnier | E40: =[53]Performance!$AH$45 -> 0.89147083 | F40: ='[53]PCB Nesting QA'!$L$44 -> 0.7075 | G40: ='[53]Class Summary'!$E$21 -> 0.22222222 | H40: ='[53]Class Summary'!$I$21 -> 0.14285714 | I40: ='[31]GradRates - Tier 1'!$S$163 -> 0.13333333
...

Sheet Survey Raw Data
A1: Select the name of your primary trainer for this course. | B1: Sum of Sum of User Score | C1: Sum of Sum of Responses | D1: Average | F1: Attempt Date | G1: Sum of User Score | H1: Sum of Responses | I1: name | J1: Select your location from the drop-down menu. | K1: What is your training start date? | L1: Select the name of your primary trainer for this course. | M1: If there was a secondary trainer assisting your class, then please select their name or select None. | N1: What is your department? | O1: It was easy for me to get actively involved during this program. | P1: I was comfortable with the pace of this program. | Q1: I had many opportunities to get answers to my questions. | R1: I had opportunities to practice the skills I was asked to learn. | S1: My learning was enhanced by the knowledge of the facilitator. | T1: My learning was enhanced by the experiences shared by the facilitator. | U1: What are three things the facilitator did well that encouraged you? | V1: What are three things that the facilitator could do differently next time?
A2: Anita Bliss-Dias | B2: 114 | C2: 104 | D2: =GETPIVOTDATA("Sum of Sum of Responses",$A$1,"Select the name of your primary trainer for this course.","Anita Bliss-Dias")/GETPIVOTDATA("Sum of Sum of User Score",$A$1,"Select the name of your primary trainer for this course.","Anita Bliss-Dias") -> 0.9122807 | F2: Nov 16, 2023 15:39:56 | G2: 6 | H2: =COUNTIF(O2:T2,">3") -> 6 | I2: Guest | J2: Manila, PHL | K2: 2023-11-16 | L2: Mahalakshmi Ramasubramanian | M2: Ankit Vishnoi | N2: Tier 2 | O2: 5 | P2: 5 | Q2: 5 | R2: 5 | S2: 5 | T2: 5 | V2: None. She is perfectly excellent.
A3: Ankit Vishnoi | B3: 108 | C3: 98 | D3: =GETPIVOTDATA("Sum of Sum of Responses",$A$1,"Select the name of your primary trainer for this course.","Ankit Vishnoi")/GETPIVOTDATA("Sum of Sum of User Score",$A$1,"Select the name of your primary trainer for this course.","Ankit Vishnoi") -> 0.90740741 | F3: Nov 16, 2023 13:36:51 | G3: 6 | H3: =COUNTIF(O3:T3,">3") -> 6 | I3: Guest | J3: Ottawa | K3: 2023-09-20 | L3: Mahalakshmi Ramasubramanian | M3: Ankit Vishnoi | N3: Tier 2 | O3: 5 | P3: 5 | Q3: 5 | R3: 5 | S3: 5 | T3: 5 | U3: she was available to help , active listening, patient with us | V3: nothing to add every thing was perfect for the training.
A4: Bibi Alli | B4: 42 | C4: 42 | D4: =GETPIVOTDATA("Sum of Sum of Responses",$A$1,"Select the name of your primary trainer for this course.","Bibi Alli")/GETPIVOTDATA("Sum of Sum of User Score",$A$1,"Select the name of your primary trainer for this course.","Bibi Alli") -> 1 | F4: Nov 16, 2023 13:20:35 | G4: 6 | H4: =COUNTIF(O4:T4,">3") -> 6 | I4: Guest | J4: Edmundson, NB | K4: 2023-10-12 | L4: Ankit Vishnoi | M4: Ankit Vishnoi | N4: Tier 2 | O4: 5 | P4: 4 | Q4: 5 | R4: 5 | S4: 5 | T4: 5 | U4: Ankit made sure he was always available for our questions, always willing and ready to explain until everyone understood, also when answering our queries he made sure to explain with detail so that we go back to the cardholder and explain in clear terms | V4: Everything Ankit did was Great, the only thing that i was bummed about it that not everyone was willing to participate and speak on voice, that makes the training so much more interesting
A5: Dave Lim | B5: 198 | C5: 188 | D5: =GETPIVOTDATA("Sum of Sum of Responses",$A$1,"Select the name of your primary trainer for this course.","Dave Lim")/GETPIVOTDATA("Sum of Sum of User Score",$A$1,"Select the name of your primary trainer for this course.","Dave Lim") -> 0.94949495 | F5: Nov 16, 2023 11:49:51 | G5: 6 | H5: =COUNTIF(O5:T5,">3") -> 6 | I5: Guest | J5: Manila, PHL | K5: 2023-10-11 | L5: Ankit Vishnoi | M5: Ankit Vishnoi | N5: Tier 2 | O5: 4 | P5: 4 | Q5: 4 | R5: 4 | S5: 4 | T5: 4 | U5: Always ask probing questions, always check SOP and always thank the Card holder | V5: N/A
A6: Debbie Anthony | B6: 72 | C6: 60 | D6: =GETPIVOTDATA("Sum of Sum of Responses",$A$1,"Select the name of your primary trainer for this course.","Debbie Anthony")/GETPIVOTDATA("Sum of Sum of User Score",$A$1,"Select the name of your primary trainer for this course.","Debbie Anthony") -> 0.83333333 | F6: Nov 16, 2023 10:38:56 | G6: 6 | H6: =COUNTIF(O6:T6,">3") -> 6 | I6: Guest | J6: Manila, PHL | K6: 2023-10-11 | L6: Ankit Vishnoi | M6: Ankit Vishnoi | N6: Tier 2 | O6: 4 | P6: 4 | Q6: 5 | R6: 5 | S6: 5 | T6: 5 | U6: Ankit always do a recap each day regarding the first time calls we encountered. When one of us asked for his help, he make sure that all of us will be able to know that new knowledge as well, so that if where going to encounter it we already have a prior knowledge about that concern. He always takes time to asked us if we\'re able to get the self led module. | V6: N/A
A7: Gilisa Roberts | B7: 108 | C7: 102 | D7: =GETPIVOTDATA("Sum of Sum of Responses",$A$1,"Select the name of your primary trainer for this course.","Gilisa Roberts")/GETPIVOTDATA("Sum of Sum of User Score",$A$1,"Select the name of your primary trainer for this course.","Gilisa Roberts") -> 0.94444444 | F7: Oct 10, 2023 18:33:06 | G7: 6 | H7: =COUNTIF(O7:T7,">3") -> 5 | I7: Guest | J7: Manila, PHL | K7: 2023-09-05 | L7: Scott McDonald | M7: Scott McDonald | N7: Tier 1 | O7: 3 | P7: 5 | Q7: 4 | R7: 4 | S7: 4 | T7: 4 | U7: learned, correct process,follow instructions | V7: more familiarization, sidebarged,and more details
A8: Hira Umair | B8: 252 | C8: 241 | D8: =GETPIVOTDATA("Sum of Sum of Responses",$A$1,"Select the name of your primary trainer for this course.","Hira Umair")/GETPIVOTDATA("Sum of Sum of User Score",$A$1,"Select the name of your primary trainer for this course.","Hira Umair") -> 0.95634921 | F8: Oct 10, 2023 18:15:53 | G8: 6 | H8: =COUNTIF(O8:T8,">3") -> 6 | I8: Guest | J8: Manila, PHL | K8: 2023-10-10 | L8: Scott McDonald | M8: Scott McDonald | N8: Tier 1 | O8: 5 | P8: 5 | Q8: 5 | R8: 5 | S8: 5 | T8: 5 | U8: They\'re lways remind me to use the sop, always be mindful in terms of validation & must do the call flow | V8: I think for the future was nothing I can\'t tell right now because they\'re gave more information that we need in diffirent scenario in terms of skills, tools and the flow
A9: Jordan Saulnier | B9: 30 | C9: 29 | D9: =GETPIVOTDATA("Sum of Sum of Responses",$A$1,"Select the name of your primary trainer for this course.","Jordan Saulnier")/GETPIVOTDATA("Sum of Sum of User Score",$A$1,"Select the name of your primary trainer for this course.","Jordan Saulnier") -> 0.96666667 | F9: Oct 10, 2023 18:11:17 | G9: 6 | H9: =COUNTIF(O9:T9,">3") -> 6 | I9: Guest | J9: Manila, PHL | K9: 2023-09-05 | L9: Scott McDonald | M9: Scott McDonald | N9: Tier 1 | O9: 5 | P9: 5 | Q9: 5 | R9: 5 | S9: 5 | T9: 5 | U9: considerate, having long patience, answering accurately the questions i had | V9: none
A10: Kate Saigo | B10: 24 | C10: 24 | D10: =GETPIVOTDATA("Sum of Sum of Responses",$A$1,"Select the name of your primary trainer for this course.","Kate Saigo")/GETPIVOTDATA("Sum of Sum of User Score",$A$1,"Select the name of your primary trainer for this course.","Kate Saigo") -> 1 | F10: Oct 10, 2023 18:06:18 | G10: 6 | H10: =COUNTIF(O10:T10,">3") -> 6 | I10: Guest | J10: Manila, PHL | K10: 2023-09-05 | L10: Scott McDonald | M10: Scott McDonald | N10: Tier 1 | O10: 4 | P10: 4 | Q10: 4 | R10: 4 | S10: 4 | T10: 4 | U10: by explaining how we can handle the call, giving appropriate examples to provide resolution and teaching the concerns that might be encountered. | V10: None
A11: Kristi Stead | B11: 108 | C11: 96 | D11: =GETPIVOTDATA("Sum of Sum of Responses",$A$1,"Select the name of your primary trainer for this course.","Kristi Stead")/GETPIVOTDATA("Sum of Sum of User Score",$A$1,"Select the name of your primary trainer for this course.","Kristi Stead") -> 0.88888889 | F11: Oct 10, 2023 18:05:56 | G11: 6 | H11: =COUNTIF(O11:T11,">3") -> 6 | I11: Guest | J11: Manila, PHL | K11: 2023-09-11 | L11: Scott McDonald | M11: Dave Lim | N11: Tier 1 | O11: 5 | P11: 5 | Q11: 5 | R11: 5 | S11: 5 | T11: 5 | U11: For me, I had a hard time to find the right SOP for the given concern. \\nHowever, Ate Sheena, told us that we really need to allot time in order for me to understand the SOP easily and also to give the best solution to the given problem. \\n\\nThe second thing was, we always from our mistakes. During the second day of the nesting week, the pressure was lessen and so far I was able to enjoy the call because of how kind the customer is. \\n\\nLastly, the floor support was very hands on even though there are some chances that all of us need them, but then they can still manage their time to rotate from one another to help and cater the concern of the card holder. | V11: -able to have another floor support \\n-it is way more enjoyable if we can meet the trainer because it is totally different to have a face to face training\\n-I don\'t think that there\'s still a need to improve or give the facilitator an advise because without them, trainees are nothing. \\n\\n\\nTHANK YOU SO MUCH, SCOTT & MS. CATHE! :)
A12: Mahalakshmi Ramasubramanian | B12: 126 | C12: 121 | D12: =GETPIVOTDATA("Sum of Sum of Responses",$A$1,"Select the name of your primary trainer for this course.","Mahalakshmi Ramasubramanian")/GETPIVOTDATA("Sum of Sum of User Score",$A$1,"Select the name of your primary trainer for this course.","Mahalakshmi Ramasubramanian") -> 0.96031746 | F12: Oct 10, 2023 18:05:03 | G12: 6 | H12: =COUNTIF(O12:T12,">3") -> 6 | I12: Guest | J12: Manila, PHL | K12: 2023-09-05 | L12: Scott McDonald | M12: Scott McDonald | N12: Tier 1 | O12: 5 | P12: 4 | Q12: 4 | R12: 4 | S12: 4 | T12: 4 | U12: Mr Scoot and Miss Catherine is very approachable when asking a question also they very generosity | V12: none so far Mr scoot and Miss Catherine is very professional during our training period
A13: Maida Musse | B13: 234 | C13: 217 | D13: =GETPIVOTDATA("Sum of Sum of Responses",$A$1,"Select the name of your primary trainer for this course.","Maida Musse")/GETPIVOTDATA("Sum of Sum of User Score",$A$1,"Select the name of your primary trainer for this course.","Maida Musse") -> 0.92735043 | F13: Oct 10, 2023 18:04:01 | G13: 6 | H13: =COUNTIF(O13:T13,">3") -> 6 | I13: Guest | J13: Manila, PHL | K13: 2023-09-11 | L13: Scott McDonald | M13: Scott McDonald | N13: Tier 1 | O13: 5 | P13: 5 | Q13: 5 | R13: 5 | S13: 5 | T13: 5 | U13: Patience on discussing, Kindness that we can see every single day of training, Passion that we can feel through the whole training days. :) | V13: Nothing, the facilitator did a good job on educating us 8) :)
A14: MariaSkubiszewska | B14: 54 | C14: 54 | D14: =GETPIVOTDATA("Sum of Sum of Responses",$A$1,"Select the name of your primary trainer for this course.","MariaSkubiszewska")/GETPIVOTDATA("Sum of Sum of User Score",$A$1,"Select the name of your primary trainer for this course.","MariaSkubiszewska") -> 1 | F14: Oct 10, 2023 18:03:21 | G14: 6 | H14: =COUNTIF(O14:T14,">3") -> 3 | I14: Guest | J14: Manila, PHL | K14: 2023-09-05 | L14: Scott McDonald | M14: Dave Lim | N14: Tier 1 | O14: 3 | P14: 3 | Q14: 2 | R14: 4 | S14: 4 | T14: 5 | U14: THEY BOOST OUR CONFIDENT ESP US NEWBIE, GUIDE US WELL TO ENGAGED WELL TO THE ENVIRONMENT, HAVING MORE PATIENCE | V14: NONE SO FAR
A15: Nancy Price | B15: 96 | C15: 92 | D15: =GETPIVOTDATA("Sum of Sum of Responses",$A$1,"Select the name of your primary trainer for this course.","Nancy Price")/GETPIVOTDATA("Sum of Sum of User Score",$A$1,"Select the name of your primary trainer for this course.","Nancy Price") -> 0.95833333 | F15: Oct 10, 2023 18:02:42 | G15: 6 | H15: =COUNTIF(O15:T15,">3") -> 6 | I15: Guest | J15: Manila, PHL | K15: 2023-09-05 | L15: Scott McDonald | M15: Scott McDonald | N15: Tier 1 | O15: 5 | P15: 5 | Q15: 5 | R15: 5 | S15: 5 | T15: 5 | U15: Motivates me, Trained me well, and encourage me | V15: Nothing, everyday was actually perfect
A16: Rowena Lasala | B16: 240 | C16: 235 | D16: =GETPIVOTDATA("Sum of Sum of Responses",$A$1,"Select the name of your primary trainer for this course.","Rowena Lasala")/GETPIVOTDATA("Sum of Sum of User Score",$A$1,"Select the name of your primary trainer for this course.","Rowena Lasala") -> 0.97916667 | F16: Oct 10, 2023 18:01:57 | G16: 6 | H16: =COUNTIF(O16:T16,">3") -> 6 | I16: Guest | J16: Manila, PHL | K16: 2023-09-05 | L16: Scott McDonald | M16: Dave Lim | N16: Tier 1 | O16: 5 | P16: 5 | Q16: 5 | R16: 5 | S16: 5 | T16: 5 | U16: Helping us to answer our question during training | V16: n/a
A17: Ruschel Bartolome | B17: 78 | C17: 71 | D17: =GETPIVOTDATA("Sum of Sum of Responses",$A$1,"Select the name of your primary trainer for this course.","Ruschel Bartolome")/GETPIVOTDATA("Sum of Sum of User Score",$A$1,"Select the name of your primary trainer for this course.","Ruschel Bartolome") -> 0.91025641 | F17: Oct 10, 2023 17:59:40 | G17: 6 | H17: =COUNTIF(O17:T17,">3") -> 6 | I17: Guest | J17: Manila, PHL | K17: 2023-09-05 | L17: Scott McDonald | M17: Scott McDonald | N17: Tier 1 | O17: 4 | P17: 5 | Q17: 5 | R17: 5 | S17: 5 | T17: 5 | U17: the facilitator did well that encourage me would be process and procedure., activate listening | V17: N/A
A18: Scott McDonald | B18: 150 | C18: 136 | D18: =GETPIVOTDATA("Sum of Sum of Responses",$A$1,"Select the name of your primary trainer for this course.","Scott McDonald")/GETPIVOTDATA("Sum of Sum of User Score",$A$1,"Select the name of your primary trainer for this course.","Scott McDonald") -> 0.90666667 | F18: Oct 10, 2023 17:54:48 | G18: 6 | H18: =COUNTIF(O18:T18,">3") -> 6 | I18: Guest | J18: Manila, PHL | K18: 2023-10-10 | L18: Scott McDonald | M18: Scott McDonald | N18: Tier 1 | O18: 4 | P18: 4 | Q18: 4 | R18: 4 | S18: 4 | T18: 4
A19: Siya Nugent | B19: 18 | C19: 16 | D19: =GETPIVOTDATA("Sum of Sum of Responses",$A$1,"Select the name of your primary trainer for this course.","Siya Nugent")/GETPIVOTDATA("Sum of Sum of User Score",$A$1,"Select the name of your primary trainer for this course.","Siya Nugent") -> 0.88888889 | F19: Oct 09, 2023 09:53:44 | G19: 6 | H19: =COUNTIF(O19:T19,">3") -> 6 | I19: Guest | J19: Manila, PHL | K19: 2023-10-09 | L19: Rowena Lasala | M19: Nancy Price | N19: Tier 1 | O19: 5 | P19: 4 | Q19: 4 | R19: 5 | S19: 5 | T19: 5
A20: Sneha Menda | B20: 276 | C20: 260 | D20: =GETPIVOTDATA("Sum of Sum of Responses",$A$1,"Select the name of your primary trainer for this course.","Sneha Menda")/GETPIVOTDATA("Sum of Sum of User Score",$A$1,"Select the name of your primary trainer for this course.","Sneha Menda") -> 0.94202899 | F20: Oct 06, 2023 09:45:21 | G20: 6 | H20: =COUNTIF(O20:T20,">3") -> 6 | I20: Guest | J20: Manila, PHL | K20: 2023-08-08 | L20: Rowena Lasala | M20: Rowena Lasala | N20: Tier 1 | O20: 5 | P20: 4 | Q20: 5 | R20: 5 | S20: 5 | T20: 5 | U20: provide all information for this account\\n | V20: miss rowena is the best
A21: Stephany Chavez | B21: 24 | C21: 21 | D21: =GETPIVOTDATA("Sum of Sum of Responses",$A$1,"Select the name of your primary trainer for this course.","Stephany Chavez")/GETPIVOTDATA("Sum of Sum of User Score",$A$1,"Select the name of your primary trainer for this course.","Stephany Chavez") -> 0.875 | F21: Oct 05, 2023 15:28:45 | G21: 6 | H21: =COUNTIF(O21:T21,">3") -> 6 | I21: Guest | J21: Manila, PHL | K21: 2023-08-08 | L21: Rowena Lasala | M21: Nancy Price | N21: Tier 1 | O21: 5 | P21: 5 | Q21: 5 | R21: 5 | S21: 5 | T21: 5 | U21: Their positivity towards success, their encouragement, and willingness to share their knowledge. | V21: All is well. They are doing great.
