Workbook
Name Calendar_Year: 'Calendar View'!$C$3
Name ColumnTitle3: Employees[[#Headers],[Employee names]]
Name ColumnTitle4: LeaveTypes[[#Headers],[List of leave types]]
Name ColumnTitle5: CompanyHolidays[[#Headers],[Company holidays]]
Name ColumnTitleRegion..AC22.1: 'Calendar View'!$C$19:$E$19
Name lstEDates: LeaveTracker[End date]
Name lstEmployees: Employees[Employee names]
Name lstEmpNames: LeaveTracker[Employee name]
Name lstHolidays: CompanyHolidays[Company holidays]
Name lstHolidayTypes: LeaveTypes[List of leave types]
Name lstHTypes: LeaveTracker[Type of leave]
Name lstSdates: LeaveTracker[Start date]
Name Title1: AttendanceRecord[[#Headers],[Weekday/Month]]
Name Title2: LeaveTracker[[#Headers],[Employee name]]
Name valSelEmployee: 'Calendar View'!$C$2

Sheet Calendar View
B1: EMPLOYEE ATTENDANCE RECORD
B2: Select an employee: | C2: Sneha Menda
B3: Enter year: | C3: =YEAR(TODAY()) -> 2026
B5: Weekday/Month | C5: SUN | D5: MON | E5: TUE | F5: WED | G5: THU | H5: FRI | I5: SAT | J5: SUN | K5: MON | L5: TUE | M5: WED | N5: THU | O5: FRI | P5: SAT | Q5: SUN | R5: MON | S5: TUE | T5: WED | U5: THU | V5: FRI | W5: SAT | X5: SUN | Y5: MON | Z5: TUE | AA5: WED | AB5: THU | AC5: FRI | AD5: SAT | AE5: SUN | AF5: MON | AG5: TUE | AH5: WED | AI5: THU | AJ5: FRI | AK5: SAT | AL5: SUN | AM5: MON | AN5: TUE | AO5: WED | AP5: THU 2 | AQ5: FRI | AR5: SAT
B6: January | C6: =IFERROR(IF(TEXT(DATE(Calendar_Year,ROW($A1),1),"ddd")=LEFT(C$5,3),DATE(Calendar_Year,ROW($A1),1),""),"") | D6: =IFERROR(IF(TEXT(DATE(Calendar_Year,ROW($A1),1),"ddd")=LEFT(D$5,3),DATE(Calendar_Year,ROW($A1),1),IF(C6>=1,C6+1,"")),"") | E6: =IFERROR(IF(TEXT(DATE(Calendar_Year,ROW($A1),1),"ddd")=LEFT(E$5,3),DATE(Calendar_Year,ROW($A1),1),IF(D6>=1,D6+1,"")),"") | F6: =IFERROR(IF(TEXT(DATE(Calendar_Year,ROW($A1),1),"ddd")=LEFT(F$5,3),DATE(Calendar_Year,ROW($A1),1),IF(E6>=1,E6+1,"")),"") | G6: =IFERROR(IF(TEXT(DATE(Calendar_Year,ROW($A1),1),"ddd")=LEFT(G$5,3),DATE(Calendar_Year,ROW($A1),1),IF(F6>=1,F6+1,"")),"") -> 46023 | H6: =IFERROR(IF(TEXT(DATE(Calendar_Year,ROW($A1),1),"ddd")=LEFT(H$5,3),DATE(Calendar_Year,ROW($A1),1),IF(G6>=1,G6+1,"")),"") -> 46024 | I6: =IFERROR(IF(TEXT(DATE(Calendar_Year,ROW($A1),1),"ddd")=LEFT(I$5,3),DATE(Calendar_Year,ROW($A1),1),IF(H6>=1,H6+1,"")),"") -> 46025 | J6: =IFERROR(IF(I6>=1,I6+1,""),"") -> 46026 | K6: =IFERROR(IF(J6>=1,J6+1,""),"") -> 46027 | L6: =IFERROR(IF(K6>=1,K6+1,""),"") -> 46028 | M6: =IFERROR(IF(L6>=1,L6+1,""),"") -> 46029 | N6: =IFERROR(IF(M6>=1,M6+1,""),"") -> 46030 | O6: =IFERROR(IF(N6>=1,N6+1,""),"") -> 46031 | P6: =IFERROR(IF(O6>=1,O6+1,""),"") -> 46032 | Q6: =IFERROR(IF(P6>=1,P6+1,""),"") -> 46033 | ... AK6: =IFERROR(IF(AJ6>=1,AJ6+1,""),"") -> 46053 | AL6: =IFERROR(IF(AND(AK6>=1,AK6+1<=DATE(Calendar_Year,ROW($A1)+1,0)),AK6+1,""),"") | AM6: =IFERROR(IF(AND(AL6>=1,AL6+1<=DATE(Calendar_Year,ROW($A1)+1,0)),AL6+1,""),"") | AN6: =IFERROR(IF(AND(AM6>=1,AM6+1<=DATE(Calendar_Year,ROW($A1)+1,0)),AM6+1,""),"") | AO6: =IFERROR(IF(AND(AN6>=1,AN6+1<=DATE(Calendar_Year,ROW($A1)+1,0)),AN6+1,""),"") | AP6: =IFERROR(IF(AND(AO6>=1,AO6+1<=DATE(Calendar_Year,ROW($A1)+1,0)),AO6+1,""),"") | AQ6: =IFERROR(IF(AND(AP6>=1,AP6+1<=DATE(Calendar_Year,ROW($A1)+1,0)),AP6+1,""),"") | AR6: =IFERROR(IF(AND(AQ6>=1,AQ6+1<=DATE(Calendar_Year,ROW($A1)+1,0)),AQ6+1,""),"")
B7: February | C7: =IFERROR(IF(TEXT(DATE(Calendar_Year,ROW($A2),1),"ddd")=LEFT(C$5,3),DATE(Calendar_Year,ROW($A2),1),""),"") -> 46054 | D7: =IFERROR(IF(TEXT(DATE(Calendar_Year,ROW($A2),1),"ddd")=LEFT(D$5,3),DATE(Calendar_Year,ROW($A2),1),IF(C7>=1,C7+1,"")),"") -> 46055 | E7: =IFERROR(IF(TEXT(DATE(Calendar_Year,ROW($A2),1),"ddd")=LEFT(E$5,3),DATE(Calendar_Year,ROW($A2),1),IF(D7>=1,D7+1,"")),"") -> 46056 | F7: =IFERROR(IF(TEXT(DATE(Calendar_Year,ROW($A2),1),"ddd")=LEFT(F$5,3),DATE(Calendar_Year,ROW($A2),1),IF(E7>=1,E7+1,"")),"") -> 46057 | G7: =IFERROR(IF(TEXT(DATE(Calendar_Year,ROW($A2),1),"ddd")=LEFT(G$5,3),DATE(Calendar_Year,ROW($A2),1),IF(F7>=1,F7+1,"")),"") -> 46058 | H7: =IFERROR(IF(TEXT(DATE(Calendar_Year,ROW($A2),1),"ddd")=LEFT(H$5,3),DATE(Calendar_Year,ROW($A2),1),IF(G7>=1,G7+1,"")),"") -> 46059 | I7: =IFERROR(IF(TEXT(DATE(Calendar_Year,ROW($A2),1),"ddd")=LEFT(I$5,3),DATE(Calendar_Year,ROW($A2),1),IF(H7>=1,H7+1,"")),"") -> 46060 | J7: =IFERROR(IF(I7>=1,I7+1,""),"") -> 46061 | K7: =IFERROR(IF(J7>=1,J7+1,""),"") -> 46062 | L7: =IFERROR(IF(K7>=1,K7+1,""),"") -> 46063 | M7: =IFERROR(IF(L7>=1,L7+1,""),"") -> 46064 | N7: =IFERROR(IF(M7>=1,M7+1,""),"") -> 46065 | O7: =IFERROR(IF(N7>=1,N7+1,""),"") -> 46066 | P7: =IFERROR(IF(O7>=1,O7+1,""),"") -> 46067 | Q7: =IFERROR(IF(P7>=1,P7+1,""),"") -> 46068 | ... AK7: =IFERROR(IF(AJ7>=1,AJ7+1,""),"") -> 46088 | AL7: =IFERROR(IF(AND(AK7>=1,AK7+1<=DATE(Calendar_Year,ROW($A2)+1,0)),AK7+1,""),"") | AM7: =IFERROR(IF(AND(AL7>=1,AL7+1<=DATE(Calendar_Year,ROW($A2)+1,0)),AL7+1,""),"") | AN7: =IFERROR(IF(AND(AM7>=1,AM7+1<=DATE(Calendar_Year,ROW($A2)+1,0)),AM7+1,""),"") | AO7: =IFERROR(IF(AND(AN7>=1,AN7+1<=DATE(Calendar_Year,ROW($A2)+1,0)),AN7+1,""),"") | AP7: =IFERROR(IF(AND(AO7>=1,AO7+1<=DATE(Calendar_Year,ROW($A2)+1,0)),AO7+1,""),"") | AQ7: =IFERROR(IF(AND(AP7>=1,AP7+1<=DATE(Calendar_Year,ROW($A2)+1,0)),AP7+1,""),"") | AR7: =IFERROR(IF(AND(AQ7>=1,AQ7+1<=DATE(Calendar_Year,ROW($A2)+1,0)),AQ7+1,""),"")
B8: March | C8: =IFERROR(IF(TEXT(DATE(Calendar_Year,ROW($A3),1),"ddd")=LEFT(C$5,3),DATE(Calendar_Year,ROW($A3),1),""),"") -> 46082 | D8: =IFERROR(IF(TEXT(DATE(Calendar_Year,ROW($A3),1),"ddd")=LEFT(D$5,3),DATE(Calendar_Year,ROW($A3),1),IF(C8>=1,C8+1,"")),"") -> 46083 | E8: =IFERROR(IF(TEXT(DATE(Calendar_Year,ROW($A3),1),"ddd")=LEFT(E$5,3),DATE(Calendar_Year,ROW($A3),1),IF(D8>=1,D8+1,"")),"") -> 46084 | F8: =IFERROR(IF(TEXT(DATE(Calendar_Year,ROW($A3),1),"ddd")=LEFT(F$5,3),DATE(Calendar_Year,ROW($A3),1),IF(E8>=1,E8+1,"")),"") -> 46085 | G8: =IFERROR(IF(TEXT(DATE(Calendar_Year,ROW($A3),1),"ddd")=LEFT(G$5,3),DATE(Calendar_Year,ROW($A3),1),IF(F8>=1,F8+1,"")),"") -> 46086 | H8: =IFERROR(IF(TEXT(DATE(Calendar_Year,ROW($A3),1),"ddd")=LEFT(H$5,3),DATE(Calendar_Year,ROW($A3),1),IF(G8>=1,G8+1,"")),"") -> 46087 | I8: =IFERROR(IF(TEXT(DATE(Calendar_Year,ROW($A3),1),"ddd")=LEFT(I$5,3),DATE(Calendar_Year,ROW($A3),1),IF(H8>=1,H8+1,"")),"") -> 46088 | J8: =IFERROR(IF(I8>=1,I8+1,""),"") -> 46089 | K8: =IFERROR(IF(J8>=1,J8+1,""),"") -> 46090 | L8: =IFERROR(IF(K8>=1,K8+1,""),"") -> 46091 | M8: =IFERROR(IF(L8>=1,L8+1,""),"") -> 46092 | N8: =IFERROR(IF(M8>=1,M8+1,""),"") -> 46093 | O8: =IFERROR(IF(N8>=1,N8+1,""),"") -> 46094 | P8: =IFERROR(IF(O8>=1,O8+1,""),"") -> 46095 | Q8: =IFERROR(IF(P8>=1,P8+1,""),"") -> 46096 | ... AK8: =IFERROR(IF(AJ8>=1,AJ8+1,""),"") -> 46116 | AL8: =IFERROR(IF(AND(AK8>=1,AK8+1<=DATE(Calendar_Year,ROW($A3)+1,0)),AK8+1,""),"") | AM8: =IFERROR(IF(AND(AL8>=1,AL8+1<=DATE(Calendar_Year,ROW($A3)+1,0)),AL8+1,""),"") | AN8: =IFERROR(IF(AND(AM8>=1,AM8+1<=DATE(Calendar_Year,ROW($A3)+1,0)),AM8+1,""),"") | AO8: =IFERROR(IF(AND(AN8>=1,AN8+1<=DATE(Calendar_Year,ROW($A3)+1,0)),AN8+1,""),"") | AP8: =IFERROR(IF(AND(AO8>=1,AO8+1<=DATE(Calendar_Year,ROW($A3)+1,0)),AO8+1,""),"") | AQ8: =IFERROR(IF(AND(AP8>=1,AP8+1<=DATE(Calendar_Year,ROW($A3)+1,0)),AP8+1,""),"") | AR8: =IFERROR(IF(AND(AQ8>=1,AQ8+1<=DATE(Calendar_Year,ROW($A3)+1,0)),AQ8+1,""),"")
B9: April | C9: =IFERROR(IF(TEXT(DATE(Calendar_Year,ROW($A4),1),"ddd")=LEFT(C$5,3),DATE(Calendar_Year,ROW($A4),1),""),"") | D9: =IFERROR(IF(TEXT(DATE(Calendar_Year,ROW($A4),1),"ddd")=LEFT(D$5,3),DATE(Calendar_Year,ROW($A4),1),IF(C9>=1,C9+1,"")),"") | E9: =IFERROR(IF(TEXT(DATE(Calendar_Year,ROW($A4),1),"ddd")=LEFT(E$5,3),DATE(Calendar_Year,ROW($A4),1),IF(D9>=1,D9+1,"")),"") | F9: =IFERROR(IF(TEXT(DATE(Calendar_Year,ROW($A4),1),"ddd")=LEFT(F$5,3),DATE(Calendar_Year,ROW($A4),1),IF(E9>=1,E9+1,"")),"") -> 46113 | G9: =IFERROR(IF(TEXT(DATE(Calendar_Year,ROW($A4),1),"ddd")=LEFT(G$5,3),DATE(Calendar_Year,ROW($A4),1),IF(F9>=1,F9+1,"")),"") -> 46114 | H9: =IFERROR(IF(TEXT(DATE(Calendar_Year,ROW($A4),1),"ddd")=LEFT(H$5,3),DATE(Calendar_Year,ROW($A4),1),IF(G9>=1,G9+1,"")),"") -> 46115 | I9: =IFERROR(IF(TEXT(DATE(Calendar_Year,ROW($A4),1),"ddd")=LEFT(I$5,3),DATE(Calendar_Year,ROW($A4),1),IF(H9>=1,H9+1,"")),"") -> 46116 | J9: =IFERROR(IF(I9>=1,I9+1,""),"") -> 46117 | K9: =IFERROR(IF(J9>=1,J9+1,""),"") -> 46118 | L9: =IFERROR(IF(K9>=1,K9+1,""),"") -> 46119 | M9: =IFERROR(IF(L9>=1,L9+1,""),"") -> 46120 | N9: =IFERROR(IF(M9>=1,M9+1,""),"") -> 46121 | O9: =IFERROR(IF(N9>=1,N9+1,""),"") -> 46122 | P9: =IFERROR(IF(O9>=1,O9+1,""),"") -> 46123 | Q9: =IFERROR(IF(P9>=1,P9+1,""),"") -> 46124 | ... AK9: =IFERROR(IF(AJ9>=1,AJ9+1,""),"") -> 46144 | AL9: =IFERROR(IF(AND(AK9>=1,AK9+1<=DATE(Calendar_Year,ROW($A4)+1,0)),AK9+1,""),"") | AM9: =IFERROR(IF(AND(AL9>=1,AL9+1<=DATE(Calendar_Year,ROW($A4)+1,0)),AL9+1,""),"") | AN9: =IFERROR(IF(AND(AM9>=1,AM9+1<=DATE(Calendar_Year,ROW($A4)+1,0)),AM9+1,""),"") | AO9: =IFERROR(IF(AND(AN9>=1,AN9+1<=DATE(Calendar_Year,ROW($A4)+1,0)),AN9+1,""),"") | AP9: =IFERROR(IF(AND(AO9>=1,AO9+1<=DATE(Calendar_Year,ROW($A4)+1,0)),AO9+1,""),"") | AQ9: =IFERROR(IF(AND(AP9>=1,AP9+1<=DATE(Calendar_Year,ROW($A4)+1,0)),AP9+1,""),"") | AR9: =IFERROR(IF(AND(AQ9>=1,AQ9+1<=DATE(Calendar_Year,ROW($A4)+1,0)),AQ9+1,""),"")
B10: May | C10: =IFERROR(IF(TEXT(DATE(Calendar_Year,ROW($A5),1),"ddd")=LEFT(C$5,3),DATE(Calendar_Year,ROW($A5),1),""),"") | D10: =IFERROR(IF(TEXT(DATE(Calendar_Year,ROW($A5),1),"ddd")=LEFT(D$5,3),DATE(Calendar_Year,ROW($A5),1),IF(C10>=1,C10+1,"")),"") | E10: =IFERROR(IF(TEXT(DATE(Calendar_Year,ROW($A5),1),"ddd")=LEFT(E$5,3),DATE(Calendar_Year,ROW($A5),1),IF(D10>=1,D10+1,"")),"") | F10: =IFERROR(IF(TEXT(DATE(Calendar_Year,ROW($A5),1),"ddd")=LEFT(F$5,3),DATE(Calendar_Year,ROW($A5),1),IF(E10>=1,E10+1,"")),"") | G10: =IFERROR(IF(TEXT(DATE(Calendar_Year,ROW($A5),1),"ddd")=LEFT(G$5,3),DATE(Calendar_Year,ROW($A5),1),IF(F10>=1,F10+1,"")),"") | H10: =IFERROR(IF(TEXT(DATE(Calendar_Year,ROW($A5),1),"ddd")=LEFT(H$5,3),DATE(Calendar_Year,ROW($A5),1),IF(G10>=1,G10+1,"")),"") -> 46143 | I10: =IFERROR(IF(TEXT(DATE(Calendar_Year,ROW($A5),1),"ddd")=LEFT(I$5,3),DATE(Calendar_Year,ROW($A5),1),IF(H10>=1,H10+1,"")),"") -> 46144 | J10: =IFERROR(IF(I10>=1,I10+1,""),"") -> 46145 | K10: =IFERROR(IF(J10>=1,J10+1,""),"") -> 46146 | L10: =IFERROR(IF(K10>=1,K10+1,""),"") -> 46147 | M10: =IFERROR(IF(L10>=1,L10+1,""),"") -> 46148 | N10: =IFERROR(IF(M10>=1,M10+1,""),"") -> 46149 | O10: =IFERROR(IF(N10>=1,N10+1,""),"") -> 46150 | P10: =IFERROR(IF(O10>=1,O10+1,""),"") -> 46151 | Q10: =IFERROR(IF(P10>=1,P10+1,""),"") -> 46152 | ... AK10: =IFERROR(IF(AJ10>=1,AJ10+1,""),"") -> 46172 | AL10: =IFERROR(IF(AND(AK10>=1,AK10+1<=DATE(Calendar_Year,ROW($A5)+1,0)),AK10+1,""),"") -> 46173 | AM10: =IFERROR(IF(AND(AL10>=1,AL10+1<=DATE(Calendar_Year,ROW($A5)+1,0)),AL10+1,""),"") | AN10: =IFERROR(IF(AND(AM10>=1,AM10+1<=DATE(Calendar_Year,ROW($A5)+1,0)),AM10+1,""),"") | AO10: =IFERROR(IF(AND(AN10>=1,AN10+1<=DATE(Calendar_Year,ROW($A5)+1,0)),AN10+1,""),"") | AP10: =IFERROR(IF(AND(AO10>=1,AO10+1<=DATE(Calendar_Year,ROW($A5)+1,0)),AO10+1,""),"") | AQ10: =IFERROR(IF(AND(AP10>=1,AP10+1<=DATE(Calendar_Year,ROW($A5)+1,0)),AP10+1,""),"") | AR10: =IFERROR(IF(AND(AQ10>=1,AQ10+1<=DATE(Calendar_Year,ROW($A5)+1,0)),AQ10+1,""),"")
B11: June | C11: =IFERROR(IF(TEXT(DATE(Calendar_Year,ROW($A6),1),"ddd")=LEFT(C$5,3),DATE(Calendar_Year,ROW($A6),1),""),"") | D11: =IFERROR(IF(TEXT(DATE(Calendar_Year,ROW($A6),1),"ddd")=LEFT(D$5,3),DATE(Calendar_Year,ROW($A6),1),IF(C11>=1,C11+1,"")),"") -> 46174 | E11: =IFERROR(IF(TEXT(DATE(Calendar_Year,ROW($A6),1),"ddd")=LEFT(E$5,3),DATE(Calendar_Year,ROW($A6),1),IF(D11>=1,D11+1,"")),"") -> 46175 | F11: =IFERROR(IF(TEXT(DATE(Calendar_Year,ROW($A6),1),"ddd")=LEFT(F$5,3),DATE(Calendar_Year,ROW($A6),1),IF(E11>=1,E11+1,"")),"") -> 46176 | G11: =IFERROR(IF(TEXT(DATE(Calendar_Year,ROW($A6),1),"ddd")=LEFT(G$5,3),DATE(Calendar_Year,ROW($A6),1),IF(F11>=1,F11+1,"")),"") -> 46177 | H11: =IFERROR(IF(TEXT(DATE(Calendar_Year,ROW($A6),1),"ddd")=LEFT(H$5,3),DATE(Calendar_Year,ROW($A6),1),IF(G11>=1,G11+1,"")),"") -> 46178 | I11: =IFERROR(IF(TEXT(DATE(Calendar_Year,ROW($A6),1),"ddd")=LEFT(I$5,3),DATE(Calendar_Year,ROW($A6),1),IF(H11>=1,H11+1,"")),"") -> 46179 | J11: =IFERROR(IF(I11>=1,I11+1,""),"") -> 46180 | K11: =IFERROR(IF(J11>=1,J11+1,""),"") -> 46181 | L11: =IFERROR(IF(K11>=1,K11+1,""),"") -> 46182 | M11: =IFERROR(IF(L11>=1,L11+1,""),"") -> 46183 | N11: =IFERROR(IF(M11>=1,M11+1,""),"") -> 46184 | O11: =IFERROR(IF(N11>=1,N11+1,""),"") -> 46185 | P11: =IFERROR(IF(O11>=1,O11+1,""),"") -> 46186 | Q11: =IFERROR(IF(P11>=1,P11+1,""),"") -> 46187 | ... AK11: =IFERROR(IF(AJ11>=1,AJ11+1,""),"") -> 46207 | AL11: =IFERROR(IF(AND(AK11>=1,AK11+1<=DATE(Calendar_Year,ROW($A6)+1,0)),AK11+1,""),"") | AM11: =IFERROR(IF(AND(AL11>=1,AL11+1<=DATE(Calendar_Year,ROW($A6)+1,0)),AL11+1,""),"") | AN11: =IFERROR(IF(AND(AM11>=1,AM11+1<=DATE(Calendar_Year,ROW($A6)+1,0)),AM11+1,""),"") | AO11: =IFERROR(IF(AND(AN11>=1,AN11+1<=DATE(Calendar_Year,ROW($A6)+1,0)),AN11+1,""),"") | AP11: =IFERROR(IF(AND(AO11>=1,AO11+1<=DATE(Calendar_Year,ROW($A6)+1,0)),AO11+1,""),"") | AQ11: =IFERROR(IF(AND(AP11>=1,AP11+1<=DATE(Calendar_Year,ROW($A6)+1,0)),AP11+1,""),"") | AR11: =IFERROR(IF(AND(AQ11>=1,AQ11+1<=DATE(Calendar_Year,ROW($A6)+1,0)),AQ11+1,""),"")
B12: July | C12: =IFERROR(IF(TEXT(DATE(Calendar_Year,ROW($A7),1),"ddd")=LEFT(C$5,3),DATE(Calendar_Year,ROW($A7),1),""),"") | D12: =IFERROR(IF(TEXT(DATE(Calendar_Year,ROW($A7),1),"ddd")=LEFT(D$5,3),DATE(Calendar_Year,ROW($A7),1),IF(C12>=1,C12+1,"")),"") | E12: =IFERROR(IF(TEXT(DATE(Calendar_Year,ROW($A7),1),"ddd")=LEFT(E$5,3),DATE(Calendar_Year,ROW($A7),1),IF(D12>=1,D12+1,"")),"") | F12: =IFERROR(IF(TEXT(DATE(Calendar_Year,ROW($A7),1),"ddd")=LEFT(F$5,3),DATE(Calendar_Year,ROW($A7),1),IF(E12>=1,E12+1,"")),"") -> 46204 | G12: =IFERROR(IF(TEXT(DATE(Calendar_Year,ROW($A7),1),"ddd")=LEFT(G$5,3),DATE(Calendar_Year,ROW($A7),1),IF(F12>=1,F12+1,"")),"") -> 46205 | H12: =IFERROR(IF(TEXT(DATE(Calendar_Year,ROW($A7),1),"ddd")=LEFT(H$5,3),DATE(Calendar_Year,ROW($A7),1),IF(G12>=1,G12+1,"")),"") -> 46206 | I12: =IFERROR(IF(TEXT(DATE(Calendar_Year,ROW($A7),1),"ddd")=LEFT(I$5,3),DATE(Calendar_Year,ROW($A7),1),IF(H12>=1,H12+1,"")),"") -> 46207 | J12: =IFERROR(IF(I12>=1,I12+1,""),"") -> 46208 | K12: =IFERROR(IF(J12>=1,J12+1,""),"") -> 46209 | L12: =IFERROR(IF(K12>=1,K12+1,""),"") -> 46210 | M12: =IFERROR(IF(L12>=1,L12+1,""),"") -> 46211 | N12: =IFERROR(IF(M12>=1,M12+1,""),"") -> 46212 | O12: =IFERROR(IF(N12>=1,N12+1,""),"") -> 46213 | P12: =IFERROR(IF(O12>=1,O12+1,""),"") -> 46214 | Q12: =IFERROR(IF(P12>=1,P12+1,""),"") -> 46215 | ... AK12: =IFERROR(IF(AJ12>=1,AJ12+1,""),"") -> 46235 | AL12: =IFERROR(IF(AND(AK12>=1,AK12+1<=DATE(Calendar_Year,ROW($A7)+1,0)),AK12+1,""),"") | AM12: =IFERROR(IF(AND(AL12>=1,AL12+1<=DATE(Calendar_Year,ROW($A7)+1,0)),AL12+1,""),"") | AN12: =IFERROR(IF(AND(AM12>=1,AM12+1<=DATE(Calendar_Year,ROW($A7)+1,0)),AM12+1,""),"") | AO12: =IFERROR(IF(AND(AN12>=1,AN12+1<=DATE(Calendar_Year,ROW($A7)+1,0)),AN12+1,""),"") | AP12: =IFERROR(IF(AND(AO12>=1,AO12+1<=DATE(Calendar_Year,ROW($A7)+1,0)),AO12+1,""),"") | AQ12: =IFERROR(IF(AND(AP12>=1,AP12+1<=DATE(Calendar_Year,ROW($A7)+1,0)),AP12+1,""),"") | AR12: =IFERROR(IF(AND(AQ12>=1,AQ12+1<=DATE(Calendar_Year,ROW($A7)+1,0)),AQ12+1,""),"")
B13: August | C13: =IFERROR(IF(TEXT(DATE(Calendar_Year,ROW($A8),1),"ddd")=LEFT(C$5,3),DATE(Calendar_Year,ROW($A8),1),""),"") | D13: =IFERROR(IF(TEXT(DATE(Calendar_Year,ROW($A8),1),"ddd")=LEFT(D$5,3),DATE(Calendar_Year,ROW($A8),1),IF(C13>=1,C13+1,"")),"") | E13: =IFERROR(IF(TEXT(DATE(Calendar_Year,ROW($A8),1),"ddd")=LEFT(E$5,3),DATE(Calendar_Year,ROW($A8),1),IF(D13>=1,D13+1,"")),"") | F13: =IFERROR(IF(TEXT(DATE(Calendar_Year,ROW($A8),1),"ddd")=LEFT(F$5,3),DATE(Calendar_Year,ROW($A8),1),IF(E13>=1,E13+1,"")),"") | G13: =IFERROR(IF(TEXT(DATE(Calendar_Year,ROW($A8),1),"ddd")=LEFT(G$5,3),DATE(Calendar_Year,ROW($A8),1),IF(F13>=1,F13+1,"")),"") | H13: =IFERROR(IF(TEXT(DATE(Calendar_Year,ROW($A8),1),"ddd")=LEFT(H$5,3),DATE(Calendar_Year,ROW($A8),1),IF(G13>=1,G13+1,"")),"") | I13: =IFERROR(IF(TEXT(DATE(Calendar_Year,ROW($A8),1),"ddd")=LEFT(I$5,3),DATE(Calendar_Year,ROW($A8),1),IF(H13>=1,H13+1,"")),"") -> 46235 | J13: =IFERROR(IF(I13>=1,I13+1,""),"") -> 46236 | K13: =IFERROR(IF(J13>=1,J13+1,""),"") -> 46237 | L13: =IFERROR(IF(K13>=1,K13+1,""),"") -> 46238 | M13: =IFERROR(IF(L13>=1,L13+1,""),"") -> 46239 | N13: =IFERROR(IF(M13>=1,M13+1,""),"") -> 46240 | O13: =IFERROR(IF(N13>=1,N13+1,""),"") -> 46241 | P13: =IFERROR(IF(O13>=1,O13+1,""),"") -> 46242 | Q13: =IFERROR(IF(P13>=1,P13+1,""),"") -> 46243 | ... AK13: =IFERROR(IF(AJ13>=1,AJ13+1,""),"") -> 46263 | AL13: =IFERROR(IF(AND(AK13>=1,AK13+1<=DATE(Calendar_Year,ROW($A8)+1,0)),AK13+1,""),"") -> 46264 | AM13: =IFERROR(IF(AND(AL13>=1,AL13+1<=DATE(Calendar_Year,ROW($A8)+1,0)),AL13+1,""),"") -> 46265 | AN13: =IFERROR(IF(AND(AM13>=1,AM13+1<=DATE(Calendar_Year,ROW($A8)+1,0)),AM13+1,""),"") | AO13: =IFERROR(IF(AND(AN13>=1,AN13+1<=DATE(Calendar_Year,ROW($A8)+1,0)),AN13+1,""),"") | AP13: =IFERROR(IF(AND(AO13>=1,AO13+1<=DATE(Calendar_Year,ROW($A8)+1,0)),AO13+1,""),"") | AQ13: =IFERROR(IF(AND(AP13>=1,AP13+1<=DATE(Calendar_Year,ROW($A8)+1,0)),AP13+1,""),"") | AR13: =IFERROR(IF(AND(AQ13>=1,AQ13+1<=DATE(Calendar_Year,ROW($A8)+1,0)),AQ13+1,""),"")
B14: September | C14: =IFERROR(IF(TEXT(DATE(Calendar_Year,ROW($A9),1),"ddd")=LEFT(C$5,3),DATE(Calendar_Year,ROW($A9),1),""),"") | D14: =IFERROR(IF(TEXT(DATE(Calendar_Year,ROW($A9),1),"ddd")=LEFT(D$5,3),DATE(Calendar_Year,ROW($A9),1),IF(C14>=1,C14+1,"")),"") | E14: =IFERROR(IF(TEXT(DATE(Calendar_Year,ROW($A9),1),"ddd")=LEFT(E$5,3),DATE(Calendar_Year,ROW($A9),1),IF(D14>=1,D14+1,"")),"") -> 46266 | F14: =IFERROR(IF(TEXT(DATE(Calendar_Year,ROW($A9),1),"ddd")=LEFT(F$5,3),DATE(Calendar_Year,ROW($A9),1),IF(E14>=1,E14+1,"")),"") -> 46267 | G14: =IFERROR(IF(TEXT(DATE(Calendar_Year,ROW($A9),1),"ddd")=LEFT(G$5,3),DATE(Calendar_Year,ROW($A9),1),IF(F14>=1,F14+1,"")),"") -> 46268 | H14: =IFERROR(IF(TEXT(DATE(Calendar_Year,ROW($A9),1),"ddd")=LEFT(H$5,3),DATE(Calendar_Year,ROW($A9),1),IF(G14>=1,G14+1,"")),"") -> 46269 | I14: =IFERROR(IF(TEXT(DATE(Calendar_Year,ROW($A9),1),"ddd")=LEFT(I$5,3),DATE(Calendar_Year,ROW($A9),1),IF(H14>=1,H14+1,"")),"") -> 46270 | J14: =IFERROR(IF(I14>=1,I14+1,""),"") -> 46271 | K14: =IFERROR(IF(J14>=1,J14+1,""),"") -> 46272 | L14: =IFERROR(IF(K14>=1,K14+1,""),"") -> 46273 | M14: =IFERROR(IF(L14>=1,L14+1,""),"") -> 46274 | N14: =IFERROR(IF(M14>=1,M14+1,""),"") -> 46275 | O14: =IFERROR(IF(N14>=1,N14+1,""),"") -> 46276 | P14: =IFERROR(IF(O14>=1,O14+1,""),"") -> 46277 | Q14: =IFERROR(IF(P14>=1,P14+1,""),"") -> 46278 | ... AK14: =IFERROR(IF(AJ14>=1,AJ14+1,""),"") -> 46298 | AL14: =IFERROR(IF(AND(AK14>=1,AK14+1<=DATE(Calendar_Year,ROW($A9)+1,0)),AK14+1,""),"") | AM14: =IFERROR(IF(AND(AL14>=1,AL14+1<=DATE(Calendar_Year,ROW($A9)+1,0)),AL14+1,""),"") | AN14: =IFERROR(IF(AND(AM14>=1,AM14+1<=DATE(Calendar_Year,ROW($A9)+1,0)),AM14+1,""),"") | AO14: =IFERROR(IF(AND(AN14>=1,AN14+1<=DATE(Calendar_Year,ROW($A9)+1,0)),AN14+1,""),"") | AP14: =IFERROR(IF(AND(AO14>=1,AO14+1<=DATE(Calendar_Year,ROW($A9)+1,0)),AO14+1,""),"") | AQ14: =IFERROR(IF(AND(AP14>=1,AP14+1<=DATE(Calendar_Year,ROW($A9)+1,0)),AP14+1,""),"") | AR14: =IFERROR(IF(AND(AQ14>=1,AQ14+1<=DATE(Calendar_Year,ROW($A9)+1,0)),AQ14+1,""),"")
B15: October | C15: =IFERROR(IF(TEXT(DATE(Calendar_Year,ROW($A10),1),"ddd")=LEFT(C$5,3),DATE(Calendar_Year,ROW($A10),1),""),"") | D15: =IFERROR(IF(TEXT(DATE(Calendar_Year,ROW($A10),1),"ddd")=LEFT(D$5,3),DATE(Calendar_Year,ROW($A10),1),IF(C15>=1,C15+1,"")),"") | E15: =IFERROR(IF(TEXT(DATE(Calendar_Year,ROW($A10),1),"ddd")=LEFT(E$5,3),DATE(Calendar_Year,ROW($A10),1),IF(D15>=1,D15+1,"")),"") | F15: =IFERROR(IF(TEXT(DATE(Calendar_Year,ROW($A10),1),"ddd")=LEFT(F$5,3),DATE(Calendar_Year,ROW($A10),1),IF(E15>=1,E15+1,"")),"") | G15: =IFERROR(IF(TEXT(DATE(Calendar_Year,ROW($A10),1),"ddd")=LEFT(G$5,3),DATE(Calendar_Year,ROW($A10),1),IF(F15>=1,F15+1,"")),"") -> 46296 | H15: =IFERROR(IF(TEXT(DATE(Calendar_Year,ROW($A10),1),"ddd")=LEFT(H$5,3),DATE(Calendar_Year,ROW($A10),1),IF(G15>=1,G15+1,"")),"") -> 46297 | I15: =IFERROR(IF(TEXT(DATE(Calendar_Year,ROW($A10),1),"ddd")=LEFT(I$5,3),DATE(Calendar_Year,ROW($A10),1),IF(H15>=1,H15+1,"")),"") -> 46298 | J15: =IFERROR(IF(I15>=1,I15+1,""),"") -> 46299 | K15: =IFERROR(IF(J15>=1,J15+1,""),"") -> 46300 | L15: =IFERROR(IF(K15>=1,K15+1,""),"") -> 46301 | M15: =IFERROR(IF(L15>=1,L15+1,""),"") -> 46302 | N15: =IFERROR(IF(M15>=1,M15+1,""),"") -> 46303 | O15: =IFERROR(IF(N15>=1,N15+1,""),"") -> 46304 | P15: =IFERROR(IF(O15>=1,O15+1,""),"") -> 46305 | Q15: =IFERROR(IF(P15>=1,P15+1,""),"") -> 46306 | ... AK15: =IFERROR(IF(AJ15>=1,AJ15+1,""),"") -> 46326 | AL15: =IFERROR(IF(AND(AK15>=1,AK15+1<=DATE(Calendar_Year,ROW($A10)+1,0)),AK15+1,""),"") | AM15: =IFERROR(IF(AND(AL15>=1,AL15+1<=DATE(Calendar_Year,ROW($A10)+1,0)),AL15+1,""),"") | AN15: =IFERROR(IF(AND(AM15>=1,AM15+1<=DATE(Calendar_Year,ROW($A10)+1,0)),AM15+1,""),"") | AO15: =IFERROR(IF(AND(AN15>=1,AN15+1<=DATE(Calendar_Year,ROW($A10)+1,0)),AN15+1,""),"") | AP15: =IFERROR(IF(AND(AO15>=1,AO15+1<=DATE(Calendar_Year,ROW($A10)+1,0)),AO15+1,""),"") | AQ15: =IFERROR(IF(AND(AP15>=1,AP15+1<=DATE(Calendar_Year,ROW($A10)+1,0)),AP15+1,""),"") | AR15: =IFERROR(IF(AND(AQ15>=1,AQ15+1<=DATE(Calendar_Year,ROW($A10)+1,0)),AQ15+1,""),"")
B16: November | C16: =IFERROR(IF(TEXT(DATE(Calendar_Year,ROW($A11),1),"ddd")=LEFT(C$5,3),DATE(Calendar_Year,ROW($A11),1),""),"") -> 46327 | D16: =IFERROR(IF(TEXT(DATE(Calendar_Year,ROW($A11),1),"ddd")=LEFT(D$5,3),DATE(Calendar_Year,ROW($A11),1),IF(C16>=1,C16+1,"")),"") -> 46328 | E16: =IFERROR(IF(TEXT(DATE(Calendar_Year,ROW($A11),1),"ddd")=LEFT(E$5,3),DATE(Calendar_Year,ROW($A11),1),IF(D16>=1,D16+1,"")),"") -> 46329 | F16: =IFERROR(IF(TEXT(DATE(Calendar_Year,ROW($A11),1),"ddd")=LEFT(F$5,3),DATE(Calendar_Year,ROW($A11),1),IF(E16>=1,E16+1,"")),"") -> 46330 | G16: =IFERROR(IF(TEXT(DATE(Calendar_Year,ROW($A11),1),"ddd")=LEFT(G$5,3),DATE(Calendar_Year,ROW($A11),1),IF(F16>=1,F16+1,"")),"") -> 46331 | H16: =IFERROR(IF(TEXT(DATE(Calendar_Year,ROW($A11),1),"ddd")=LEFT(H$5,3),DATE(Calendar_Year,ROW($A11),1),IF(G16>=1,G16+1,"")),"") -> 46332 | I16: =IFERROR(IF(TEXT(DATE(Calendar_Year,ROW($A11),1),"ddd")=LEFT(I$5,3),DATE(Calendar_Year,ROW($A11),1),IF(H16>=1,H16+1,"")),"") -> 46333 | J16: =IFERROR(IF(I16>=1,I16+1,""),"") -> 46334 | K16: =IFERROR(IF(J16>=1,J16+1,""),"") -> 46335 | L16: =IFERROR(IF(K16>=1,K16+1,""),"") -> 46336 | M16: =IFERROR(IF(L16>=1,L16+1,""),"") -> 46337 | N16: =IFERROR(IF(M16>=1,M16+1,""),"") -> 46338 | O16: =IFERROR(IF(N16>=1,N16+1,""),"") -> 46339 | P16: =IFERROR(IF(O16>=1,O16+1,""),"") -> 46340 | Q16: =IFERROR(IF(P16>=1,P16+1,""),"") -> 46341 | ... AK16: =IFERROR(IF(AJ16>=1,AJ16+1,""),"") -> 46361 | AL16: =IFERROR(IF(AND(AK16>=1,AK16+1<=DATE(Calendar_Year,ROW($A11)+1,0)),AK16+1,""),"") | AM16: =IFERROR(IF(AND(AL16>=1,AL16+1<=DATE(Calendar_Year,ROW($A11)+1,0)),AL16+1,""),"") | AN16: =IFERROR(IF(AND(AM16>=1,AM16+1<=DATE(Calendar_Year,ROW($A11)+1,0)),AM16+1,""),"") | AO16: =IFERROR(IF(AND(AN16>=1,AN16+1<=DATE(Calendar_Year,ROW($A11)+1,0)),AN16+1,""),"") | AP16: =IFERROR(IF(AND(AO16>=1,AO16+1<=DATE(Calendar_Year,ROW($A11)+1,0)),AO16+1,""),"") | AQ16: =IFERROR(IF(AND(AP16>=1,AP16+1<=DATE(Calendar_Year,ROW($A11)+1,0)),AP16+1,""),"") | AR16: =IFERROR(IF(AND(AQ16>=1,AQ16+1<=DATE(Calendar_Year,ROW($A11)+1,0)),AQ16+1,""),"")
B17: December | C17: =IFERROR(IF(TEXT(DATE(Calendar_Year,ROW($A12),1),"ddd")=LEFT(C$5,3),DATE(Calendar_Year,ROW($A12),1),""),"") | D17: =IFERROR(IF(TEXT(DATE(Calendar_Year,ROW($A12),1),"ddd")=LEFT(D$5,3),DATE(Calendar_Year,ROW($A12),1),IF(C17>=1,C17+1,"")),"") | E17: =IFERROR(IF(TEXT(DATE(Calendar_Year,ROW($A12),1),"ddd")=LEFT(E$5,3),DATE(Calendar_Year,ROW($A12),1),IF(D17>=1,D17+1,"")),"") -> 46357 | F17: =IFERROR(IF(TEXT(DATE(Calendar_Year,ROW($A12),1),"ddd")=LEFT(F$5,3),DATE(Calendar_Year,ROW($A12),1),IF(E17>=1,E17+1,"")),"") -> 46358 | G17: =IFERROR(IF(TEXT(DATE(Calendar_Year,ROW($A12),1),"ddd")=LEFT(G$5,3),DATE(Calendar_Year,ROW($A12),1),IF(F17>=1,F17+1,"")),"") -> 46359 | H17: =IFERROR(IF(TEXT(DATE(Calendar_Year,ROW($A12),1),"ddd")=LEFT(H$5,3),DATE(Calendar_Year,ROW($A12),1),IF(G17>=1,G17+1,"")),"") -> 46360 | I17: =IFERROR(IF(TEXT(DATE(Calendar_Year,ROW($A12),1),"ddd")=LEFT(I$5,3),DATE(Calendar_Year,ROW($A12),1),IF(H17>=1,H17+1,"")),"") -> 46361 | J17: =IFERROR(IF(I17>=1,I17+1,""),"") -> 46362 | K17: =IFERROR(IF(J17>=1,J17+1,""),"") -> 46363 | L17: =IFERROR(IF(K17>=1,K17+1,""),"") -> 46364 | M17: =IFERROR(IF(L17>=1,L17+1,""),"") -> 46365 | N17: =IFERROR(IF(M17>=1,M17+1,""),"") -> 46366 | O17: =IFERROR(IF(N17>=1,N17+1,""),"") -> 46367 | P17: =IFERROR(IF(O17>=1,O17+1,""),"") -> 46368 | Q17: =IFERROR(IF(P17>=1,P17+1,""),"") -> 46369 | ... AK17: =IFERROR(IF(AJ17>=1,AJ17+1,""),"") -> 46389 | AL17: =IFERROR(IF(AND(AK17>=1,AK17+1<=DATE(Calendar_Year,ROW($A12)+1,0)),AK17+1,""),"") | AM17: =IFERROR(IF(AND(AL17>=1,AL17+1<=DATE(Calendar_Year,ROW($A12)+1,0)),AL17+1,""),"") | AN17: =IFERROR(IF(AND(AM17>=1,AM17+1<=DATE(Calendar_Year,ROW($A12)+1,0)),AM17+1,""),"") | AO17: =IFERROR(IF(AND(AN17>=1,AN17+1<=DATE(Calendar_Year,ROW($A12)+1,0)),AN17+1,""),"") | AP17: =IFERROR(IF(AND(AO17>=1,AO17+1<=DATE(Calendar_Year,ROW($A12)+1,0)),AO17+1,""),"") | AQ17: =IFERROR(IF(AND(AP17>=1,AP17+1<=DATE(Calendar_Year,ROW($A12)+1,0)),AP17+1,""),"") | AR17: =IFERROR(IF(AND(AQ17>=1,AQ17+1<=DATE(Calendar_Year,ROW($A12)+1,0)),AQ17+1,""),"")
B18: KEY STATISTICS
C19: Days on leave | H19: Working days | N19: # Sick days | S19: Vacation | X19: Carry over Vaction | AC19: Breavement | AH19: Solo Parent Leave | AM19: Lieu
C20: =SUMIFS(LeaveTracker[Days],LeaveTracker[Employee name],valSelEmployee,LeaveTracker[Start date],">="&DATE(Calendar_Year,1,1),LeaveTracker[End date],"<"&DATE(Calendar_Year+1,1,1),LeaveTracker[Type of leave],"<>WFH",LeaveTracker[Type of leave],"<>late",LeaveTracker[Type of leave],"<>leave early",LeaveTracker[Type of leave],"<>Flex") -> 0 | H20: =NETWORKDAYS(DATE(Calendar_Year,1,1),EDATE(DATE(Calendar_Year,1,1),12)-1) -> 261 | N20: =SUMIFS(LeaveTracker[Days],LeaveTracker[Employee name],valSelEmployee,LeaveTracker[Start date],">="&DATE(Calendar_Year,1,1),LeaveTracker[End date],"<"&DATE(Calendar_Year+1,1,1),LeaveTracker[Type of leave],'Leave Types'!B4) -> 0 | S20: =SUMIFS(LeaveTracker[Days],LeaveTracker[Employee name],valSelEmployee,LeaveTracker[Start date],">="&DATE(Calendar_Year,1,1),LeaveTracker[End date],"<"&DATE(Calendar_Year+1,1,1),LeaveTracker[Type of leave],'Leave Types'!B5) -> 0 | X20: =SUMIFS(LeaveTracker[Days],LeaveTracker[Employee name],valSelEmployee,LeaveTracker[Start date],">="&DATE(Calendar_Year,1,1),LeaveTracker[End date],"<"&DATE(Calendar_Year+1,1,1),LeaveTracker[Type of leave],'Leave Types'!B6) -> 0 | AC20: =SUMIFS(LeaveTracker[Days],LeaveTracker[Employee name],valSelEmployee,LeaveTracker[Start date],">="&DATE(Calendar_Year,1,1),LeaveTracker[End date],"<"&DATE(Calendar_Year+1,1,1),LeaveTracker[Type of leave],'Leave Types'!B7) -> 0 | AH20: =SUMIFS(LeaveTracker[Days],LeaveTracker[Employee name],valSelEmployee,LeaveTracker[Start date],">="&DATE(Calendar_Year,1,1),LeaveTracker[End date],"<"&DATE(Calendar_Year+1,1,1),LeaveTracker[Type of leave],'Leave Types'!B8) -> 0 | AM20: =SUMIFS(LeaveTracker[Days],LeaveTracker[Employee name],valSelEmployee,LeaveTracker[Start date],">="&DATE(Calendar_Year,1,1),LeaveTracker[End date],"<"&DATE(Calendar_Year+1,1,1),LeaveTracker[Type of leave],'Leave Types'!B9) -> 0
C21: =SUMIFS(LeaveTracker[Days],LeaveTracker[Employee name],valSelEmployee,LeaveTracker[Start date],">="&DATE(Calendar_Year-1,1,1),LeaveTracker[End date],"<"&DATE(Calendar_Year,1,1)) -> 1 | H21: =NETWORKDAYS(DATE(Calendar_Year-1,1,1),EDATE(DATE(Calendar_Year-1,1,1),12)-1) -> 261 | N21: =SUMIFS(LeaveTracker[Days],LeaveTracker[Employee name],valSelEmployee,LeaveTracker[Start date],">="&DATE(Calendar_Year-1,1,1),LeaveTracker[End date],"<"&DATE(Calendar_Year,1,1),LeaveTracker[Type of leave],'Leave Types'!B4) -> 1 | S21: =SUMIFS(LeaveTracker[Days],LeaveTracker[Employee name],valSelEmployee,LeaveTracker[Start date],">="&DATE(Calendar_Year-1,1,1),LeaveTracker[End date],"<"&DATE(Calendar_Year,1,1),LeaveTracker[Type of leave],'Leave Types'!B5) -> 0 | X21: =SUMIFS(LeaveTracker[Days],LeaveTracker[Employee name],valSelEmployee,LeaveTracker[Start date],">="&DATE(Calendar_Year-1,1,1),LeaveTracker[End date],"<"&DATE(Calendar_Year,1,1),LeaveTracker[Type of leave],'Leave Types'!B7) -> 0 | AC21: =SUMIFS(LeaveTracker[Days],LeaveTracker[Employee name],valSelEmployee,LeaveTracker[Start date],">="&DATE(Calendar_Year-1,1,1),LeaveTracker[End date],"<"&DATE(Calendar_Year,1,1),LeaveTracker[Type of leave],'Leave Types'!B10) -> 0 | AH21: =SUMIFS(LeaveTracker[Days],LeaveTracker[Employee name],valSelEmployee,LeaveTracker[Start date],">="&DATE(Calendar_Year-1,1,1),LeaveTracker[End date],"<"&DATE(Calendar_Year,1,1),LeaveTracker[Type of leave],'Leave Types'!G10) -> 0 | AM21: =SUMIFS(LeaveTracker[Days],LeaveTracker[Employee name],valSelEmployee,LeaveTracker[Start date],">="&DATE(Calendar_Year-1,1,1),LeaveTracker[End date],"<"&DATE(Calendar_Year,1,1),LeaveTracker[Type of leave],'Leave Types'!L10) -> 0
C22: =IFERROR(IF(C21<>0,IF(C20>=C21,"UP ", "DOWN ")&TEXT(C20/C21-1,"0%;0%"),"UP 100%"),"") -> DOWN 100% | H22: =IFERROR(IF(H21<>0,IF(H20>=H21,"UP ", "DOWN ")&TEXT(H20/H21-1,"0%;0%"),"UP 100%"),"") -> UP 0% | N22: =IFERROR(IF(N21<>0,IF(N20>=N21,"UP ", "DOWN ")&TEXT(N20/N21-1,"0%;0%"),"UP 100%"),"") -> DOWN 100% | S22: =IFERROR(IF(S21<>0,IF(S20>=S21,"UP ", "DOWN ")&TEXT(S20/S21-1,"0%;0%"),"UP 100%"),"") -> UP 100% | X22: =IFERROR(IF(X21<>0,IF(X20>=X21,"UP ", "DOWN ")&TEXT(X20/X21-1,"0%;0%"),"UP 100%"),"") -> UP 100% | AC22: =IFERROR(IF(AC21<>0,IF(AC20>=AC21,"UP ", "DOWN ")&TEXT(AC20/AC21-1,"0%;0%"),"UP 100%"),"") -> UP 100% | AH22: =IFERROR(IF(AH21<>0,IF(AH20>=AH21,"UP ", "DOWN ")&TEXT(AH20/AH21-1,"0%;0%"),"UP 100%"),"") -> UP 100% | AM22: =IFERROR(IF(AM21<>0,IF(AM20>=AM21,"UP ", "DOWN ")&TEXT(AM20/AM21-1,"0%;0%"),"UP 100%"),"") -> UP 100%
N26: WFH | S26: Late | X26: Leave Early | AC26: Flex
N27: =SUMIFS(LeaveTracker[Days],LeaveTracker[Employee name],valSelEmployee,LeaveTracker[Start date],">="&DATE(Calendar_Year,1,1),LeaveTracker[End date],"<"&DATE(Calendar_Year+1,1,1),LeaveTracker[Type of leave],'Leave Types'!B10) -> 0 | S27: =SUMIFS(LeaveTracker[Days],LeaveTracker[Employee name],valSelEmployee,LeaveTracker[Start date],">="&DATE(Calendar_Year,1,1),LeaveTracker[End date],"<"&DATE(Calendar_Year+1,1,1),LeaveTracker[Type of leave],'Leave Types'!B11) -> 0 | X27: =SUMIFS(LeaveTracker[Days],LeaveTracker[Employee name],valSelEmployee,LeaveTracker[Start date],">="&DATE(Calendar_Year,1,1),LeaveTracker[End date],"<"&DATE(Calendar_Year+1,1,1),LeaveTracker[Type of leave],'Leave Types'!B12) -> 0 | AC27: =SUMIFS(LeaveTracker[Days],LeaveTracker[Employee name],valSelEmployee,LeaveTracker[Start date],">="&DATE(Calendar_Year,1,1),LeaveTracker[End date],"<"&DATE(Calendar_Year+1,1,1),LeaveTracker[Type of leave],'Leave Types'!B15) -> 0
N28: =SUMIFS(LeaveTracker[Days],LeaveTracker[Employee name],valSelEmployee,LeaveTracker[Start date],">="&DATE(Calendar_Year-1,1,1),LeaveTracker[End date],"<"&DATE(Calendar_Year,1,1),LeaveTracker[Type of leave],'Leave Types'!#REF!) -> 0 | S28: =SUMIFS(LeaveTracker[Days],LeaveTracker[Employee name],valSelEmployee,LeaveTracker[Start date],">="&DATE(Calendar_Year-1,1,1),LeaveTracker[End date],"<"&DATE(Calendar_Year,1,1),LeaveTracker[Type of leave],'Leave Types'!#REF!) -> 0 | X28: =SUMIFS(LeaveTracker[Days],LeaveTracker[Employee name],valSelEmployee,LeaveTracker[Start date],">="&DATE(Calendar_Year-1,1,1),LeaveTracker[End date],"<"&DATE(Calendar_Year,1,1),LeaveTracker[Type of leave],'Leave Types'!#REF!) -> 0 | AC28: =SUMIFS(LeaveTracker[Days],LeaveTracker[Employee name],valSelEmployee,LeaveTracker[Start date],">="&DATE(Calendar_Year-1,1,1),LeaveTracker[End date],"<"&DATE(Calendar_Year,1,1),LeaveTracker[Type of leave],'Leave Types'!#REF!) -> 0
N29: =IFERROR(IF(N28<>0,IF(N27>=N28,"UP ", "DOWN ")&TEXT(N27/N28-1,"0%;0%"),"UP 100%"),"") -> UP 100% | S29: =IFERROR(IF(S28<>0,IF(S27>=S28,"UP ", "DOWN ")&TEXT(S27/S28-1,"0%;0%"),"UP 100%"),"") -> UP 100% | X29: =IFERROR(IF(X28<>0,IF(X27>=X28,"UP ", "DOWN ")&TEXT(X27/X28-1,"0%;0%"),"UP 100%"),"") -> UP 100% | AC29: =IFERROR(IF(AC28<>0,IF(AC27>=AC28,"UP ", "DOWN ")&TEXT(AC27/AC28-1,"0%;0%"),"UP 100%"),"") -> UP 100%

Sheet Employee Leave Tracker
B1: Employee leave tracker
B3: Employee name | C3: Start date | D3: End date | E3: Type of leave | F3: Days
B4: Maida Musse | C4: =DATE(YEAR(TODAY()),1,3) -> 46025 | D4: =DATE(YEAR(TODAY()),1,3) -> 46025 | E4: Carryover Vacation | F4: =NETWORKDAYS(LeaveTracker[[#This Row],[Start date]],LeaveTracker[[#This Row],[End date]],lstHolidays) -> 0
B5: Anita Bliss-Dias | C5: =DATE(YEAR(TODAY()),1,2) -> 46024 | D5: =DATE(YEAR(TODAY()),1,10) -> 46032 | E5: Vacation | F5: =NETWORKDAYS(LeaveTracker[[#This Row],[Start date]],LeaveTracker[[#This Row],[End date]],lstHolidays) -> 6
B6: Gilisa Williams | C6: =DATE(YEAR(TODAY()),1,2 ) -> 46024 | D6: =DATE(YEAR(TODAY()),1,7) -> 46029 | E6: Carryover Vacation | F6: =NETWORKDAYS(LeaveTracker[[#This Row],[Start date]],LeaveTracker[[#This Row],[End date]],lstHolidays) -> 4
B7: Gilisa Williams | C7: =DATE(YEAR(TODAY()),1,8 ) -> 46030 | D7: =DATE(YEAR(TODAY()),1,10) -> 46032 | E7: Vacation | F7: =NETWORKDAYS(LeaveTracker[[#This Row],[Start date]],LeaveTracker[[#This Row],[End date]],lstHolidays) -> 2
B8: Kristi Stead | C8: =DATE(YEAR(TODAY()),1,2 ) -> 46024 | D8: =DATE(YEAR(TODAY()),1,3) -> 46025 | E8: Carryover Vacation | F8: =NETWORKDAYS(LeaveTracker[[#This Row],[Start date]],LeaveTracker[[#This Row],[End date]],lstHolidays) -> 1
B9: Viena Lacena | C9: =DATE(YEAR(TODAY()),1,2 ) -> 46024 | D9: =DATE(YEAR(TODAY()),1,3) -> 46025 | E9: Vacation | F9: =NETWORKDAYS(LeaveTracker[[#This Row],[Start date]],LeaveTracker[[#This Row],[End date]],lstHolidays) -> 1
B10: Kate Saigo | C10: =DATE(YEAR(TODAY()),1,2 ) -> 46024 | D10: =DATE(YEAR(TODAY()),1,2) -> 46024 | E10: Vacation | F10: =NETWORKDAYS(LeaveTracker[[#This Row],[Start date]],LeaveTracker[[#This Row],[End date]],lstHolidays) -> 1
B11: Donna Calilong | C11: =DATE(YEAR(TODAY()),1,2 ) -> 46024 | D11: =DATE(YEAR(TODAY()),1,3) -> 46025 | E11: Vacation | F11: =NETWORKDAYS(LeaveTracker[[#This Row],[Start date]],LeaveTracker[[#This Row],[End date]],lstHolidays) -> 1
B12: Hazel Vhea De Fiesta | C12: =DATE(YEAR(TODAY()),1,3) -> 46025 | D12: =DATE(YEAR(TODAY()),1,3) -> 46025 | E12: Vacation | F12: =NETWORKDAYS(LeaveTracker[[#This Row],[Start date]],LeaveTracker[[#This Row],[End date]],lstHolidays) -> 0
B13: Kate Saigo | C13: =DATE(YEAR(TODAY()),1,16) -> 46038 | D13: =DATE(YEAR(TODAY()),1,16) -> 46038 | E13: Lieu | F13: =NETWORKDAYS(LeaveTracker[[#This Row],[Start date]],LeaveTracker[[#This Row],[End date]],lstHolidays) -> 1
B14: Charisse (Chase) Argamosa | C14: =DATE(YEAR(TODAY()),1,13 ) -> 46035 | D14: =DATE(YEAR(TODAY()),1,14) -> 46036 | E14: Vacation | F14: =NETWORKDAYS(LeaveTracker[[#This Row],[Start date]],LeaveTracker[[#This Row],[End date]],lstHolidays) -> 2
B15: Donna Calilong | C15: =DATE(YEAR(TODAY()),1,23 ) -> 46045 | D15: =DATE(YEAR(TODAY()),1,23) -> 46045 | E15: Sick leave | F15: =NETWORKDAYS(LeaveTracker[[#This Row],[Start date]],LeaveTracker[[#This Row],[End date]],lstHolidays) -> 1
B16: Kate Saigo | C16: =DATE(YEAR(TODAY()),1,16 ) -> 46038 | D16: =DATE(YEAR(TODAY()),1,24) -> 46046 | E16: WFH | F16: =NETWORKDAYS(LeaveTracker[[#This Row],[Start date]],LeaveTracker[[#This Row],[End date]],lstHolidays) -> 6
B17: Stephany Chavez | C17: =DATE(YEAR(TODAY()),1,22 ) -> 46044 | D17: =DATE(YEAR(TODAY()),1,29) -> 46051 | E17: Vacation | F17: =NETWORKDAYS(LeaveTracker[[#This Row],[Start date]],LeaveTracker[[#This Row],[End date]],lstHolidays) -> 6
B18: Charisse (Chase) Argamosa | C18: =DATE(YEAR(TODAY()),1,30 ) -> 46052 | D18: =DATE(YEAR(TODAY()),1,30) -> 46052 | E18: Late | F18: =NETWORKDAYS(LeaveTracker[[#This Row],[Start date]],LeaveTracker[[#This Row],[End date]],lstHolidays) -> 1
B19: Viena Lacena | C19: =DATE(YEAR(TODAY()),1,30 ) -> 46052 | D19: =DATE(YEAR(TODAY()),1,30) -> 46052 | E19: Sick leave | F19: =NETWORKDAYS(LeaveTracker[[#This Row],[Start date]],LeaveTracker[[#This Row],[End date]],lstHolidays) -> 1
B20: Kristi Stead | C20: =DATE(YEAR(TODAY()),1,28 ) -> 46050 | D20: =DATE(YEAR(TODAY()),1,30) -> 46052 | E20: Vacation | F20: =NETWORKDAYS(LeaveTracker[[#This Row],[Start date]],LeaveTracker[[#This Row],[End date]],lstHolidays) -> 3
B21: Kristi Stead | C21: =DATE(YEAR(TODAY()),2,5 ) -> 46058 | D21: =DATE(YEAR(TODAY()),2,5) -> 46058 | E21: Flex | F21: =NETWORKDAYS(LeaveTracker[[#This Row],[Start date]],LeaveTracker[[#This Row],[End date]],lstHolidays) -> 1
B22: Anabelle (Belle) Pizon | C22: =DATE(YEAR(TODAY()),2,4 ) -> 46057 | D22: =DATE(YEAR(TODAY()),2,4) -> 46057 | E22: Leave Early | F22: =NETWORKDAYS(LeaveTracker[[#This Row],[Start date]],LeaveTracker[[#This Row],[End date]],lstHolidays) -> 1
B23: Stephany Chavez | C23: =DATE(YEAR(TODAY()),2,3) -> 46056 | D23: =DATE(YEAR(TODAY()),2,3) -> 46056 | E23: Sick leave | F23: =NETWORKDAYS(LeaveTracker[[#This Row],[Start date]],LeaveTracker[[#This Row],[End date]],lstHolidays) -> 1
B24: Charisse (Chase) Argamosa | C24: =DATE(YEAR(TODAY()),2,7) -> 46060 | D24: =DATE(YEAR(TODAY()),2,7) -> 46060 | E24: Late | F24: =NETWORKDAYS(LeaveTracker[[#This Row],[Start date]],LeaveTracker[[#This Row],[End date]],lstHolidays) -> 0
B25: Charisse (Chase) Argamosa | C25: =DATE(YEAR(TODAY()),2,10) -> 46063 | D25: =DATE(YEAR(TODAY()),2,11) -> 46064 | E25: Vacation | F25: =NETWORKDAYS(LeaveTracker[[#This Row],[Start date]],LeaveTracker[[#This Row],[End date]],lstHolidays) -> 2
B26: Anita Bliss-Dias | C26: =DATE(YEAR(TODAY()),2,10) -> 46063 | D26: =DATE(YEAR(TODAY()),2,10) -> 46063 | E26: Flex | F26: =NETWORKDAYS(LeaveTracker[[#This Row],[Start date]],LeaveTracker[[#This Row],[End date]],lstHolidays) -> 1
B27: Charisse (Chase) Argamosa | C27: =DATE(YEAR(TODAY()),2,14) -> 46067 | D27: =DATE(YEAR(TODAY()),2,14) -> 46067 | E27: Vacation | F27: =NETWORKDAYS(LeaveTracker[[#This Row],[Start date]],LeaveTracker[[#This Row],[End date]],lstHolidays) -> 0
B28: Charisse (Chase) Argamosa | C28: =DATE(YEAR(TODAY()),2,17) -> 46070 | D28: =DATE(YEAR(TODAY()),2,17) -> 46070 | E28: Vacation | F28: =NETWORKDAYS(LeaveTracker[[#This Row],[Start date]],LeaveTracker[[#This Row],[End date]],lstHolidays) -> 0
B29: Stephany Chavez | C29: =DATE(YEAR(TODAY()),2,17) -> 46070 | D29: =DATE(YEAR(TODAY()),2,19) -> 46072 | E29: Sick leave | F29: =NETWORKDAYS(LeaveTracker[[#This Row],[Start date]],LeaveTracker[[#This Row],[End date]],lstHolidays) -> 2
B30: Kenneth Vera Hibaya | C30: =DATE(YEAR(TODAY()),2,14) -> 46067 | D30: =DATE(YEAR(TODAY()),2,14) -> 46067 | E30: Sick leave | F30: =NETWORKDAYS(LeaveTracker[[#This Row],[Start date]],LeaveTracker[[#This Row],[End date]],lstHolidays) -> 0
B31: Mary Jean Pauline Luzada | C31: =DATE(YEAR(TODAY()),2,20) -> 46073 | D31: =DATE(YEAR(TODAY()),2,20) -> 46073 | E31: WFH | F31: =NETWORKDAYS(LeaveTracker[[#This Row],[Start date]],LeaveTracker[[#This Row],[End date]],lstHolidays) -> 1
B32: Donna Calilong | C32: =DATE(YEAR(TODAY()),2,24) -> 46077 | D32: =DATE(YEAR(TODAY()),2,24) -> 46077 | E32: Sick leave | F32: =NETWORKDAYS(LeaveTracker[[#This Row],[Start date]],LeaveTracker[[#This Row],[End date]],lstHolidays) -> 1
B33: Anabelle (Belle) Pizon | C33: =DATE(YEAR(TODAY()),2,26) -> 46079 | D33: =DATE(YEAR(TODAY()),2,26) -> 46079 | E33: Sick leave | F33: =NETWORKDAYS(LeaveTracker[[#This Row],[Start date]],LeaveTracker[[#This Row],[End date]],lstHolidays) -> 1
B34: Charisse (Chase) Argamosa | C34: =DATE(YEAR(TODAY()),3,10) -> 46091 | D34: =DATE(YEAR(TODAY()),3,10) -> 46091 | E34: Vacation | F34: =NETWORKDAYS(LeaveTracker[[#This Row],[Start date]],LeaveTracker[[#This Row],[End date]],lstHolidays) -> 1
B35: Charisse (Chase) Argamosa | C35: =DATE(YEAR(TODAY()),3,14) -> 46095 | D35: =DATE(YEAR(TODAY()),3,14) -> 46095 | E35: Vacation | F35: =NETWORKDAYS(LeaveTracker[[#This Row],[Start date]],LeaveTracker[[#This Row],[End date]],lstHolidays) -> 0
B36: Gilisa Williams | C36: =DATE(YEAR(TODAY()),3,26) -> 46107 | D36: =DATE(YEAR(TODAY()),3,26) -> 46107 | E36: Sick leave | F36: =NETWORKDAYS(LeaveTracker[[#This Row],[Start date]],LeaveTracker[[#This Row],[End date]],lstHolidays) -> 1
B37: Charisse (Chase) Argamosa | C37: =DATE(YEAR(TODAY()),5,12) -> 46154 | D37: =DATE(YEAR(TODAY()),5,12) -> 46154 | E37: Vacation | F37: =NETWORKDAYS(LeaveTracker[[#This Row],[Start date]],LeaveTracker[[#This Row],[End date]],lstHolidays) -> 1
B38: Charisse (Chase) Argamosa | C38: =DATE(YEAR(TODAY()),5,15) -> 46157 | D38: =DATE(YEAR(TODAY()),5,16) -> 46158 | E38: Vacation | F38: =NETWORKDAYS(LeaveTracker[[#This Row],[Start date]],LeaveTracker[[#This Row],[End date]],lstHolidays) -> 1
B39: Charisse (Chase) Argamosa | C39: =DATE(YEAR(TODAY()),5,19) -> 46161 | D39: =DATE(YEAR(TODAY()),5,19) -> 46161 | E39: Vacation | F39: =NETWORKDAYS(LeaveTracker[[#This Row],[Start date]],LeaveTracker[[#This Row],[End date]],lstHolidays) -> 1
B40: Charisse (Chase) Argamosa | C40: =DATE(YEAR(TODAY()),5,30) -> 46172 | D40: =DATE(YEAR(TODAY()),5,30) -> 46172 | E40: Unpaid | F40: =NETWORKDAYS(LeaveTracker[[#This Row],[Start date]],LeaveTracker[[#This Row],[End date]],lstHolidays) -> 0
B41: Charisse (Chase) Argamosa | C41: =DATE(YEAR(TODAY()),6,2) -> 46175 | D41: =DATE(YEAR(TODAY()),6,2) -> 46175 | E41: Unpaid | F41: =NETWORKDAYS(LeaveTracker[[#This Row],[Start date]],LeaveTracker[[#This Row],[End date]],lstHolidays) -> 1
...

Sheet List of Employees
B1: List of employees
B3: Employee names
B4: Aakansha Panchal
B5: Alka Kumari
B6: Amit Kushwaha
B7: Anabelle (Belle) Pizon
B8: Angelica Jessa (AJ) Regalado
B9: Anita Bliss-Dias
B10: Anjali Sharma
B11: Anshuman Srivastava
B12: Anthony (Maleka) Legodi
B13: Catherine (Kate) Saigo
... B55: Viena Lacena

Sheet Leave Types
B1: Leave types
B3: List of leave types
B4: Sick leave
B5: Vacation
B6: Carryover Vacation
B7: Bereavement
B8: Solo Parent
B9: Lieu
B10: WFH
B11: Late
B12: Leave Early
B13: LOA
... B15: Unpaid

Sheet Company Holidays
B1: Company holidays
B3: Company holidays | C3: Description
B4: =DATE(YEAR(TODAY()),1,1) -> 46023 | C4: New Year's Day
B5: =DATE(YEAR(TODAY()),2,17) -> 46070 | C5: Family Day (Canada Only)
B6: =DATE(YEAR(TODAY()),4,17) -> 46129 | C6: Maundy Thursday (Philippines Only)
B7: =DATE(YEAR(TODAY()),4,18) -> 46130 | C7: Good Friday
B8: =DATE(YEAR(TODAY()),5,1) -> 46143 | C8: Labor Day (Philippeans Only)
B9: =DATE(YEAR(TODAY()),6,12) -> 46185 | C9: Independence Day (Philippines Only)
B10: =DATE(YEAR(TODAY()),7,1) -> 46204 | C10: Canada Day (Canada Only)
B11: =DATE(YEAR(TODAY()),9,1) -> 46266 | C11: Labour Day (Canada Only
B12: =DATE(YEAR(TODAY()),10,13) -> 46308 | C12: Thanksgiving (Canada Only)
B13: =DATE(YEAR(TODAY()),11,1) -> 46327 | C13: All Saint's Day (Philippines Only)
B14: =DATE(YEAR(TODAY()),12,24) -> 46380 | C14: Christmas Eve (Philippines Only)
B15: =DATE(YEAR(TODAY()),12,25) -> 46381 | C15: Christmas
B16: =DATE(YEAR(TODAY()),12,31) -> 46387 | C16: Last Day of the Year (Pilippeans only)
